[2025-02-24T17:20:29.197+0000] {taskinstance.py:1159} INFO - Dependencies all met for dep_context=non-requeueable deps ti=<TaskInstance: coingecko_ingestion_dag.store_raw_data_in_hdfs scheduled__2025-01-26T00:00:00+00:00 [queued]>
[2025-02-24T17:20:29.210+0000] {taskinstance.py:1159} INFO - Dependencies all met for dep_context=requeueable deps ti=<TaskInstance: coingecko_ingestion_dag.store_raw_data_in_hdfs scheduled__2025-01-26T00:00:00+00:00 [queued]>
[2025-02-24T17:20:29.211+0000] {taskinstance.py:1361} INFO - Starting attempt 1 of 2
[2025-02-24T17:20:29.285+0000] {taskinstance.py:1382} INFO - Executing <Task(PythonOperator): store_raw_data_in_hdfs> on 2025-01-26 00:00:00+00:00
[2025-02-24T17:20:29.297+0000] {standard_task_runner.py:57} INFO - Started process 706 to run task
[2025-02-24T17:20:29.311+0000] {standard_task_runner.py:84} INFO - Running: ['***', 'tasks', 'run', 'coingecko_ingestion_dag', 'store_raw_data_in_hdfs', 'scheduled__2025-01-26T00:00:00+00:00', '--job-id', '75', '--raw', '--subdir', 'DAGS_FOLDER/test.py', '--cfg-path', '/tmp/tmpwa87_l3l']
[2025-02-24T17:20:29.317+0000] {standard_task_runner.py:85} INFO - Job 75: Subtask store_raw_data_in_hdfs
[2025-02-24T17:20:29.420+0000] {task_command.py:415} INFO - Running <TaskInstance: coingecko_ingestion_dag.store_raw_data_in_hdfs scheduled__2025-01-26T00:00:00+00:00 [running]> on host 85b967fd3989
[2025-02-24T17:20:29.543+0000] {taskinstance.py:1660} INFO - Exporting env vars: AIRFLOW_CTX_DAG_OWNER='etudiant' AIRFLOW_CTX_DAG_ID='coingecko_ingestion_dag' AIRFLOW_CTX_TASK_ID='store_raw_data_in_hdfs' AIRFLOW_CTX_EXECUTION_DATE='2025-01-26T00:00:00+00:00' AIRFLOW_CTX_TRY_NUMBER='1' AIRFLOW_CTX_DAG_RUN_ID='scheduled__2025-01-26T00:00:00+00:00'
[2025-02-24T17:20:29.573+0000] {taskinstance.py:1943} ERROR - Task failed with exception
Traceback (most recent call last):
  File "/home/airflow/.local/lib/python3.8/site-packages/airflow/operators/python.py", line 192, in execute
    return_value = self.execute_callable()
  File "/home/airflow/.local/lib/python3.8/site-packages/airflow/operators/python.py", line 209, in execute_callable
    return self.python_callable(*self.op_args, **self.op_kwargs)
  File "/opt/airflow/dags/test.py", line 38, in store_raw_data_in_hdfs
    with open(local_file, 'w') as f:
PermissionError: [Errno 13] Permission denied: '/mnt/hadoop_data/coingecko_raw.json'
[2025-02-24T17:20:29.591+0000] {taskinstance.py:1400} INFO - Marking task as UP_FOR_RETRY. dag_id=coingecko_ingestion_dag, task_id=store_raw_data_in_hdfs, execution_date=20250126T000000, start_date=20250224T172029, end_date=20250224T172029
[2025-02-24T17:20:29.619+0000] {standard_task_runner.py:104} ERROR - Failed to execute job 75 for task store_raw_data_in_hdfs ([Errno 13] Permission denied: '/mnt/hadoop_data/coingecko_raw.json'; 706)
[2025-02-24T17:20:29.660+0000] {local_task_job_runner.py:228} INFO - Task exited with return code 1
[2025-02-24T17:20:29.680+0000] {taskinstance.py:2784} INFO - 0 downstream tasks scheduled from follow-on schedule check
[2025-02-25T15:53:49.738+0000] {taskinstance.py:1159} INFO - Dependencies all met for dep_context=non-requeueable deps ti=<TaskInstance: coingecko_ingestion_dag.store_raw_data_in_hdfs scheduled__2025-01-26T00:00:00+00:00 [queued]>
[2025-02-25T15:53:49.786+0000] {taskinstance.py:1159} INFO - Dependencies all met for dep_context=requeueable deps ti=<TaskInstance: coingecko_ingestion_dag.store_raw_data_in_hdfs scheduled__2025-01-26T00:00:00+00:00 [queued]>
[2025-02-25T15:53:49.787+0000] {taskinstance.py:1361} INFO - Starting attempt 1 of 2
[2025-02-25T15:53:49.837+0000] {taskinstance.py:1382} INFO - Executing <Task(PythonOperator): store_raw_data_in_hdfs> on 2025-01-26 00:00:00+00:00
[2025-02-25T15:53:49.854+0000] {standard_task_runner.py:57} INFO - Started process 397 to run task
[2025-02-25T15:53:49.861+0000] {standard_task_runner.py:84} INFO - Running: ['***', 'tasks', 'run', 'coingecko_ingestion_dag', 'store_raw_data_in_hdfs', 'scheduled__2025-01-26T00:00:00+00:00', '--job-id', '76', '--raw', '--subdir', 'DAGS_FOLDER/pipeline.py', '--cfg-path', '/tmp/tmp52otw1f4']
[2025-02-25T15:53:49.870+0000] {standard_task_runner.py:85} INFO - Job 76: Subtask store_raw_data_in_hdfs
[2025-02-25T15:53:50.040+0000] {task_command.py:415} INFO - Running <TaskInstance: coingecko_ingestion_dag.store_raw_data_in_hdfs scheduled__2025-01-26T00:00:00+00:00 [running]> on host af9744bbb9eb
[2025-02-25T15:53:50.338+0000] {taskinstance.py:1660} INFO - Exporting env vars: AIRFLOW_CTX_DAG_OWNER='etudiant' AIRFLOW_CTX_DAG_ID='coingecko_ingestion_dag' AIRFLOW_CTX_TASK_ID='store_raw_data_in_hdfs' AIRFLOW_CTX_EXECUTION_DATE='2025-01-26T00:00:00+00:00' AIRFLOW_CTX_TRY_NUMBER='1' AIRFLOW_CTX_DAG_RUN_ID='scheduled__2025-01-26T00:00:00+00:00'
[2025-02-25T15:53:50.368+0000] {taskinstance.py:1943} ERROR - Task failed with exception
Traceback (most recent call last):
  File "/home/airflow/.local/lib/python3.8/site-packages/airflow/operators/python.py", line 192, in execute
    return_value = self.execute_callable()
  File "/home/airflow/.local/lib/python3.8/site-packages/airflow/operators/python.py", line 209, in execute_callable
    return self.python_callable(*self.op_args, **self.op_kwargs)
  File "/opt/airflow/dags/pipeline.py", line 39, in store_raw_data_in_hdfs
    with open(local_file, 'w') as f:
PermissionError: [Errno 13] Permission denied: '/mnt/hadoop_data/coingecko_raw.json'
[2025-02-25T15:53:50.388+0000] {taskinstance.py:1400} INFO - Marking task as UP_FOR_RETRY. dag_id=coingecko_ingestion_dag, task_id=store_raw_data_in_hdfs, execution_date=20250126T000000, start_date=20250225T155349, end_date=20250225T155350
[2025-02-25T15:53:50.426+0000] {standard_task_runner.py:104} ERROR - Failed to execute job 76 for task store_raw_data_in_hdfs ([Errno 13] Permission denied: '/mnt/hadoop_data/coingecko_raw.json'; 397)
[2025-02-25T15:53:50.468+0000] {local_task_job_runner.py:228} INFO - Task exited with return code 1
[2025-02-25T15:53:50.507+0000] {taskinstance.py:2784} INFO - 0 downstream tasks scheduled from follow-on schedule check
