[2025-02-24T17:30:42.639+0000] {taskinstance.py:1159} INFO - Dependencies all met for dep_context=non-requeueable deps ti=<TaskInstance: coingecko_ingestion_dag.store_raw_data_in_hdfs scheduled__2025-02-11T00:00:00+00:00 [queued]>
[2025-02-24T17:30:42.667+0000] {taskinstance.py:1159} INFO - Dependencies all met for dep_context=requeueable deps ti=<TaskInstance: coingecko_ingestion_dag.store_raw_data_in_hdfs scheduled__2025-02-11T00:00:00+00:00 [queued]>
[2025-02-24T17:30:42.671+0000] {taskinstance.py:1361} INFO - Starting attempt 2 of 2
[2025-02-24T17:30:42.698+0000] {taskinstance.py:1382} INFO - Executing <Task(PythonOperator): store_raw_data_in_hdfs> on 2025-02-11 00:00:00+00:00
[2025-02-24T17:30:42.715+0000] {standard_task_runner.py:57} INFO - Started process 1038 to run task
[2025-02-24T17:30:42.719+0000] {standard_task_runner.py:84} INFO - Running: ['***', 'tasks', 'run', 'coingecko_ingestion_dag', 'store_raw_data_in_hdfs', 'scheduled__2025-02-11T00:00:00+00:00', '--job-id', '141', '--raw', '--subdir', 'DAGS_FOLDER/test.py', '--cfg-path', '/tmp/tmpixk8afja']
[2025-02-24T17:30:42.728+0000] {standard_task_runner.py:85} INFO - Job 141: Subtask store_raw_data_in_hdfs
[2025-02-24T17:30:42.845+0000] {task_command.py:415} INFO - Running <TaskInstance: coingecko_ingestion_dag.store_raw_data_in_hdfs scheduled__2025-02-11T00:00:00+00:00 [running]> on host 85b967fd3989
[2025-02-24T17:30:43.006+0000] {taskinstance.py:1660} INFO - Exporting env vars: AIRFLOW_CTX_DAG_OWNER='etudiant' AIRFLOW_CTX_DAG_ID='coingecko_ingestion_dag' AIRFLOW_CTX_TASK_ID='store_raw_data_in_hdfs' AIRFLOW_CTX_EXECUTION_DATE='2025-02-11T00:00:00+00:00' AIRFLOW_CTX_TRY_NUMBER='2' AIRFLOW_CTX_DAG_RUN_ID='scheduled__2025-02-11T00:00:00+00:00'
[2025-02-24T17:30:43.032+0000] {taskinstance.py:1943} ERROR - Task failed with exception
Traceback (most recent call last):
  File "/home/airflow/.local/lib/python3.8/site-packages/airflow/operators/python.py", line 192, in execute
    return_value = self.execute_callable()
  File "/home/airflow/.local/lib/python3.8/site-packages/airflow/operators/python.py", line 209, in execute_callable
    return self.python_callable(*self.op_args, **self.op_kwargs)
  File "/opt/airflow/dags/test.py", line 38, in store_raw_data_in_hdfs
    with open(local_file, 'w') as f:
PermissionError: [Errno 13] Permission denied: '/mnt/hadoop_data/coingecko_raw.json'
[2025-02-24T17:30:43.053+0000] {taskinstance.py:1400} INFO - Marking task as FAILED. dag_id=coingecko_ingestion_dag, task_id=store_raw_data_in_hdfs, execution_date=20250211T000000, start_date=20250224T173042, end_date=20250224T173043
[2025-02-24T17:30:43.081+0000] {standard_task_runner.py:104} ERROR - Failed to execute job 141 for task store_raw_data_in_hdfs ([Errno 13] Permission denied: '/mnt/hadoop_data/coingecko_raw.json'; 1038)
[2025-02-24T17:30:43.111+0000] {local_task_job_runner.py:228} INFO - Task exited with return code 1
[2025-02-24T17:30:43.133+0000] {taskinstance.py:2784} INFO - 0 downstream tasks scheduled from follow-on schedule check
[2025-02-25T16:04:28.202+0000] {taskinstance.py:1159} INFO - Dependencies all met for dep_context=non-requeueable deps ti=<TaskInstance: coingecko_ingestion_dag.store_raw_data_in_hdfs scheduled__2025-02-11T00:00:00+00:00 [queued]>
[2025-02-25T16:04:28.219+0000] {taskinstance.py:1159} INFO - Dependencies all met for dep_context=requeueable deps ti=<TaskInstance: coingecko_ingestion_dag.store_raw_data_in_hdfs scheduled__2025-02-11T00:00:00+00:00 [queued]>
[2025-02-25T16:04:28.220+0000] {taskinstance.py:1361} INFO - Starting attempt 2 of 2
[2025-02-25T16:04:28.242+0000] {taskinstance.py:1382} INFO - Executing <Task(PythonOperator): store_raw_data_in_hdfs> on 2025-02-11 00:00:00+00:00
[2025-02-25T16:04:28.251+0000] {standard_task_runner.py:57} INFO - Started process 635 to run task
[2025-02-25T16:04:28.259+0000] {standard_task_runner.py:84} INFO - Running: ['***', 'tasks', 'run', 'coingecko_ingestion_dag', 'store_raw_data_in_hdfs', 'scheduled__2025-02-11T00:00:00+00:00', '--job-id', '144', '--raw', '--subdir', 'DAGS_FOLDER/pipeline.py', '--cfg-path', '/tmp/tmpy708hiiw']
[2025-02-25T16:04:28.268+0000] {standard_task_runner.py:85} INFO - Job 144: Subtask store_raw_data_in_hdfs
[2025-02-25T16:04:28.348+0000] {task_command.py:415} INFO - Running <TaskInstance: coingecko_ingestion_dag.store_raw_data_in_hdfs scheduled__2025-02-11T00:00:00+00:00 [running]> on host af9744bbb9eb
[2025-02-25T16:04:28.469+0000] {taskinstance.py:1660} INFO - Exporting env vars: AIRFLOW_CTX_DAG_OWNER='etudiant' AIRFLOW_CTX_DAG_ID='coingecko_ingestion_dag' AIRFLOW_CTX_TASK_ID='store_raw_data_in_hdfs' AIRFLOW_CTX_EXECUTION_DATE='2025-02-11T00:00:00+00:00' AIRFLOW_CTX_TRY_NUMBER='2' AIRFLOW_CTX_DAG_RUN_ID='scheduled__2025-02-11T00:00:00+00:00'
[2025-02-25T16:04:28.489+0000] {taskinstance.py:1943} ERROR - Task failed with exception
Traceback (most recent call last):
  File "/home/airflow/.local/lib/python3.8/site-packages/airflow/operators/python.py", line 192, in execute
    return_value = self.execute_callable()
  File "/home/airflow/.local/lib/python3.8/site-packages/airflow/operators/python.py", line 209, in execute_callable
    return self.python_callable(*self.op_args, **self.op_kwargs)
  File "/opt/airflow/dags/pipeline.py", line 39, in store_raw_data_in_hdfs
    with open(local_file, 'w') as f:
PermissionError: [Errno 13] Permission denied: '/mnt/hadoop_data/coingecko_raw.json'
[2025-02-25T16:04:28.504+0000] {taskinstance.py:1400} INFO - Marking task as FAILED. dag_id=coingecko_ingestion_dag, task_id=store_raw_data_in_hdfs, execution_date=20250211T000000, start_date=20250225T160428, end_date=20250225T160428
[2025-02-25T16:04:28.522+0000] {standard_task_runner.py:104} ERROR - Failed to execute job 144 for task store_raw_data_in_hdfs ([Errno 13] Permission denied: '/mnt/hadoop_data/coingecko_raw.json'; 635)
[2025-02-25T16:04:28.564+0000] {local_task_job_runner.py:228} INFO - Task exited with return code 1
[2025-02-25T16:04:28.584+0000] {taskinstance.py:2784} INFO - 0 downstream tasks scheduled from follow-on schedule check
