[2025-02-24T17:20:31.125+0000] {taskinstance.py:1159} INFO - Dependencies all met for dep_context=non-requeueable deps ti=<TaskInstance: coingecko_ingestion_dag.store_raw_data_in_hdfs scheduled__2025-02-01T00:00:00+00:00 [queued]>
[2025-02-24T17:20:31.134+0000] {taskinstance.py:1159} INFO - Dependencies all met for dep_context=requeueable deps ti=<TaskInstance: coingecko_ingestion_dag.store_raw_data_in_hdfs scheduled__2025-02-01T00:00:00+00:00 [queued]>
[2025-02-24T17:20:31.135+0000] {taskinstance.py:1361} INFO - Starting attempt 1 of 2
[2025-02-24T17:20:31.149+0000] {taskinstance.py:1382} INFO - Executing <Task(PythonOperator): store_raw_data_in_hdfs> on 2025-02-01 00:00:00+00:00
[2025-02-24T17:20:31.154+0000] {standard_task_runner.py:57} INFO - Started process 716 to run task
[2025-02-24T17:20:31.158+0000] {standard_task_runner.py:84} INFO - Running: ['***', 'tasks', 'run', 'coingecko_ingestion_dag', 'store_raw_data_in_hdfs', 'scheduled__2025-02-01T00:00:00+00:00', '--job-id', '81', '--raw', '--subdir', 'DAGS_FOLDER/test.py', '--cfg-path', '/tmp/tmp60nnluch']
[2025-02-24T17:20:31.162+0000] {standard_task_runner.py:85} INFO - Job 81: Subtask store_raw_data_in_hdfs
[2025-02-24T17:20:31.213+0000] {task_command.py:415} INFO - Running <TaskInstance: coingecko_ingestion_dag.store_raw_data_in_hdfs scheduled__2025-02-01T00:00:00+00:00 [running]> on host 85b967fd3989
[2025-02-24T17:20:31.285+0000] {taskinstance.py:1660} INFO - Exporting env vars: AIRFLOW_CTX_DAG_OWNER='etudiant' AIRFLOW_CTX_DAG_ID='coingecko_ingestion_dag' AIRFLOW_CTX_TASK_ID='store_raw_data_in_hdfs' AIRFLOW_CTX_EXECUTION_DATE='2025-02-01T00:00:00+00:00' AIRFLOW_CTX_TRY_NUMBER='1' AIRFLOW_CTX_DAG_RUN_ID='scheduled__2025-02-01T00:00:00+00:00'
[2025-02-24T17:20:31.298+0000] {taskinstance.py:1943} ERROR - Task failed with exception
Traceback (most recent call last):
  File "/home/airflow/.local/lib/python3.8/site-packages/airflow/operators/python.py", line 192, in execute
    return_value = self.execute_callable()
  File "/home/airflow/.local/lib/python3.8/site-packages/airflow/operators/python.py", line 209, in execute_callable
    return self.python_callable(*self.op_args, **self.op_kwargs)
  File "/opt/airflow/dags/test.py", line 38, in store_raw_data_in_hdfs
    with open(local_file, 'w') as f:
PermissionError: [Errno 13] Permission denied: '/mnt/hadoop_data/coingecko_raw.json'
[2025-02-24T17:20:31.306+0000] {taskinstance.py:1400} INFO - Marking task as UP_FOR_RETRY. dag_id=coingecko_ingestion_dag, task_id=store_raw_data_in_hdfs, execution_date=20250201T000000, start_date=20250224T172031, end_date=20250224T172031
[2025-02-24T17:20:31.316+0000] {standard_task_runner.py:104} ERROR - Failed to execute job 81 for task store_raw_data_in_hdfs ([Errno 13] Permission denied: '/mnt/hadoop_data/coingecko_raw.json'; 716)
[2025-02-24T17:20:31.338+0000] {local_task_job_runner.py:228} INFO - Task exited with return code 1
[2025-02-24T17:20:31.352+0000] {taskinstance.py:2784} INFO - 0 downstream tasks scheduled from follow-on schedule check
[2025-02-25T15:58:51.498+0000] {taskinstance.py:1159} INFO - Dependencies all met for dep_context=non-requeueable deps ti=<TaskInstance: coingecko_ingestion_dag.store_raw_data_in_hdfs scheduled__2025-02-01T00:00:00+00:00 [queued]>
[2025-02-25T15:58:51.512+0000] {taskinstance.py:1159} INFO - Dependencies all met for dep_context=requeueable deps ti=<TaskInstance: coingecko_ingestion_dag.store_raw_data_in_hdfs scheduled__2025-02-01T00:00:00+00:00 [queued]>
[2025-02-25T15:58:51.513+0000] {taskinstance.py:1361} INFO - Starting attempt 1 of 2
[2025-02-25T15:58:51.533+0000] {taskinstance.py:1382} INFO - Executing <Task(PythonOperator): store_raw_data_in_hdfs> on 2025-02-01 00:00:00+00:00
[2025-02-25T15:58:51.541+0000] {standard_task_runner.py:57} INFO - Started process 487 to run task
[2025-02-25T15:58:51.547+0000] {standard_task_runner.py:84} INFO - Running: ['***', 'tasks', 'run', 'coingecko_ingestion_dag', 'store_raw_data_in_hdfs', 'scheduled__2025-02-01T00:00:00+00:00', '--job-id', '96', '--raw', '--subdir', 'DAGS_FOLDER/pipeline.py', '--cfg-path', '/tmp/tmpr6oq_b1y']
[2025-02-25T15:58:51.553+0000] {standard_task_runner.py:85} INFO - Job 96: Subtask store_raw_data_in_hdfs
[2025-02-25T15:58:51.638+0000] {task_command.py:415} INFO - Running <TaskInstance: coingecko_ingestion_dag.store_raw_data_in_hdfs scheduled__2025-02-01T00:00:00+00:00 [running]> on host af9744bbb9eb
[2025-02-25T15:58:51.749+0000] {taskinstance.py:1660} INFO - Exporting env vars: AIRFLOW_CTX_DAG_OWNER='etudiant' AIRFLOW_CTX_DAG_ID='coingecko_ingestion_dag' AIRFLOW_CTX_TASK_ID='store_raw_data_in_hdfs' AIRFLOW_CTX_EXECUTION_DATE='2025-02-01T00:00:00+00:00' AIRFLOW_CTX_TRY_NUMBER='1' AIRFLOW_CTX_DAG_RUN_ID='scheduled__2025-02-01T00:00:00+00:00'
[2025-02-25T15:58:51.773+0000] {taskinstance.py:1943} ERROR - Task failed with exception
Traceback (most recent call last):
  File "/home/airflow/.local/lib/python3.8/site-packages/airflow/operators/python.py", line 192, in execute
    return_value = self.execute_callable()
  File "/home/airflow/.local/lib/python3.8/site-packages/airflow/operators/python.py", line 209, in execute_callable
    return self.python_callable(*self.op_args, **self.op_kwargs)
  File "/opt/airflow/dags/pipeline.py", line 39, in store_raw_data_in_hdfs
    with open(local_file, 'w') as f:
PermissionError: [Errno 13] Permission denied: '/mnt/hadoop_data/coingecko_raw.json'
[2025-02-25T15:58:51.787+0000] {taskinstance.py:1400} INFO - Marking task as UP_FOR_RETRY. dag_id=coingecko_ingestion_dag, task_id=store_raw_data_in_hdfs, execution_date=20250201T000000, start_date=20250225T155851, end_date=20250225T155851
[2025-02-25T15:58:51.807+0000] {standard_task_runner.py:104} ERROR - Failed to execute job 96 for task store_raw_data_in_hdfs ([Errno 13] Permission denied: '/mnt/hadoop_data/coingecko_raw.json'; 487)
[2025-02-25T15:58:51.852+0000] {local_task_job_runner.py:228} INFO - Task exited with return code 1
[2025-02-25T15:58:51.872+0000] {taskinstance.py:2784} INFO - 0 downstream tasks scheduled from follow-on schedule check
