[2025-02-28T10:21:17.016+0000] {taskinstance.py:1159} INFO - Dependencies all met for dep_context=non-requeueable deps ti=<TaskInstance: coingecko_ingestion_dag.load_to_hbase manual__2025-02-27T21:09:57.462541+00:00 [queued]>
[2025-02-28T10:21:17.024+0000] {taskinstance.py:1159} INFO - Dependencies all met for dep_context=requeueable deps ti=<TaskInstance: coingecko_ingestion_dag.load_to_hbase manual__2025-02-27T21:09:57.462541+00:00 [queued]>
[2025-02-28T10:21:17.025+0000] {taskinstance.py:1361} INFO - Starting attempt 3 of 4
[2025-02-28T10:21:17.036+0000] {taskinstance.py:1382} INFO - Executing <Task(PythonOperator): load_to_hbase> on 2025-02-27 21:09:57.462541+00:00
[2025-02-28T10:21:17.039+0000] {standard_task_runner.py:57} INFO - Started process 551 to run task
[2025-02-28T10:21:17.042+0000] {standard_task_runner.py:84} INFO - Running: ['***', 'tasks', 'run', 'coingecko_ingestion_dag', 'load_to_hbase', 'manual__2025-02-27T21:09:57.462541+00:00', '--job-id', '554', '--raw', '--subdir', 'DAGS_FOLDER/pipeline.py', '--cfg-path', '/tmp/tmp8wxb7dej']
[2025-02-28T10:21:17.044+0000] {standard_task_runner.py:85} INFO - Job 554: Subtask load_to_hbase
[2025-02-28T10:21:17.077+0000] {task_command.py:415} INFO - Running <TaskInstance: coingecko_ingestion_dag.load_to_hbase manual__2025-02-27T21:09:57.462541+00:00 [running]> on host b86b19d2f863
[2025-02-28T10:21:17.139+0000] {taskinstance.py:1660} INFO - Exporting env vars: AIRFLOW_CTX_DAG_OWNER='etudiant' AIRFLOW_CTX_DAG_ID='coingecko_ingestion_dag' AIRFLOW_CTX_TASK_ID='load_to_hbase' AIRFLOW_CTX_EXECUTION_DATE='2025-02-27T21:09:57.462541+00:00' AIRFLOW_CTX_TRY_NUMBER='3' AIRFLOW_CTX_DAG_RUN_ID='manual__2025-02-27T21:09:57.462541+00:00'
[2025-02-28T10:21:18.877+0000] {taskinstance.py:1943} ERROR - Task failed with exception
Traceback (most recent call last):
  File "/home/airflow/.local/lib/python3.8/site-packages/airflow/operators/python.py", line 192, in execute
    return_value = self.execute_callable()
  File "/home/airflow/.local/lib/python3.8/site-packages/airflow/operators/python.py", line 209, in execute_callable
    return self.python_callable(*self.op_args, **self.op_kwargs)
  File "/opt/airflow/dags/pipeline.py", line 68, in load_to_hbase
    with open(local_file, 'r') as f:
FileNotFoundError: [Errno 2] No such file or directory: '/tmp/crypto_agg.csv'
[2025-02-28T10:21:18.887+0000] {taskinstance.py:1400} INFO - Marking task as UP_FOR_RETRY. dag_id=coingecko_ingestion_dag, task_id=load_to_hbase, execution_date=20250227T210957, start_date=20250228T102117, end_date=20250228T102118
[2025-02-28T10:21:18.901+0000] {standard_task_runner.py:104} ERROR - Failed to execute job 554 for task load_to_hbase ([Errno 2] No such file or directory: '/tmp/crypto_agg.csv'; 551)
[2025-02-28T10:21:18.947+0000] {local_task_job_runner.py:228} INFO - Task exited with return code 1
[2025-02-28T10:21:18.962+0000] {taskinstance.py:2784} INFO - 0 downstream tasks scheduled from follow-on schedule check
