[2025-02-25T16:34:07.496+0000] {taskinstance.py:1159} INFO - Dependencies all met for dep_context=non-requeueable deps ti=<TaskInstance: coingecko_ingestion_dag.store_raw_data_in_hdfs manual__2025-02-25T16:34:03.737068+00:00 [queued]>
[2025-02-25T16:34:07.516+0000] {taskinstance.py:1159} INFO - Dependencies all met for dep_context=requeueable deps ti=<TaskInstance: coingecko_ingestion_dag.store_raw_data_in_hdfs manual__2025-02-25T16:34:03.737068+00:00 [queued]>
[2025-02-25T16:34:07.517+0000] {taskinstance.py:1361} INFO - Starting attempt 1 of 2
[2025-02-25T16:34:07.551+0000] {taskinstance.py:1382} INFO - Executing <Task(PythonOperator): store_raw_data_in_hdfs> on 2025-02-25 16:34:03.737068+00:00
[2025-02-25T16:34:07.557+0000] {standard_task_runner.py:57} INFO - Started process 198 to run task
[2025-02-25T16:34:07.564+0000] {standard_task_runner.py:84} INFO - Running: ['***', 'tasks', 'run', 'coingecko_ingestion_dag', 'store_raw_data_in_hdfs', 'manual__2025-02-25T16:34:03.737068+00:00', '--job-id', '175', '--raw', '--subdir', 'DAGS_FOLDER/pipeline.py', '--cfg-path', '/tmp/tmp1j9ui3ql']
[2025-02-25T16:34:07.573+0000] {standard_task_runner.py:85} INFO - Job 175: Subtask store_raw_data_in_hdfs
[2025-02-25T16:34:07.673+0000] {task_command.py:415} INFO - Running <TaskInstance: coingecko_ingestion_dag.store_raw_data_in_hdfs manual__2025-02-25T16:34:03.737068+00:00 [running]> on host af9744bbb9eb
[2025-02-25T16:34:07.793+0000] {taskinstance.py:1660} INFO - Exporting env vars: AIRFLOW_CTX_DAG_OWNER='etudiant' AIRFLOW_CTX_DAG_ID='coingecko_ingestion_dag' AIRFLOW_CTX_TASK_ID='store_raw_data_in_hdfs' AIRFLOW_CTX_EXECUTION_DATE='2025-02-25T16:34:03.737068+00:00' AIRFLOW_CTX_TRY_NUMBER='1' AIRFLOW_CTX_DAG_RUN_ID='manual__2025-02-25T16:34:03.737068+00:00'
[2025-02-25T16:34:13.380+0000] {taskinstance.py:1943} ERROR - Task failed with exception
Traceback (most recent call last):
  File "/home/airflow/.local/lib/python3.8/site-packages/airflow/operators/python.py", line 192, in execute
    return_value = self.execute_callable()
  File "/home/airflow/.local/lib/python3.8/site-packages/airflow/operators/python.py", line 209, in execute_callable
    return self.python_callable(*self.op_args, **self.op_kwargs)
  File "/opt/airflow/dags/pipeline.py", line 52, in store_raw_data_in_hdfs
    subprocess.run(["docker", "exec", "-i", "-u", "root", "namenode", "hdfs", "dfs", "-put", "-f", local_file, hdfs_file_path], check=True)
  File "/usr/local/lib/python3.8/subprocess.py", line 516, in run
    raise CalledProcessError(retcode, process.args,
subprocess.CalledProcessError: Command '['docker', 'exec', '-i', '-u', 'root', 'namenode', 'hdfs', 'dfs', '-put', '-f', '/tmp/tmp7sba5hpv.json', '/user/etudiant/crypto/raw/YYYY=2025/MM=02/DD=25/coingecko_raw.json']' returned non-zero exit status 1.
[2025-02-25T16:34:13.399+0000] {taskinstance.py:1400} INFO - Marking task as UP_FOR_RETRY. dag_id=coingecko_ingestion_dag, task_id=store_raw_data_in_hdfs, execution_date=20250225T163403, start_date=20250225T163407, end_date=20250225T163413
[2025-02-25T16:34:13.446+0000] {standard_task_runner.py:104} ERROR - Failed to execute job 175 for task store_raw_data_in_hdfs (Command '['docker', 'exec', '-i', '-u', 'root', 'namenode', 'hdfs', 'dfs', '-put', '-f', '/tmp/tmp7sba5hpv.json', '/user/etudiant/crypto/raw/YYYY=2025/MM=02/DD=25/coingecko_raw.json']' returned non-zero exit status 1.; 198)
[2025-02-25T16:34:13.478+0000] {local_task_job_runner.py:228} INFO - Task exited with return code 1
[2025-02-25T16:34:13.497+0000] {taskinstance.py:2784} INFO - 0 downstream tasks scheduled from follow-on schedule check
