[2025-02-24T17:15:09.893+0000] {taskinstance.py:1159} INFO - Dependencies all met for dep_context=non-requeueable deps ti=<TaskInstance: coingecko_ingestion_dag.store_raw_data_in_hdfs scheduled__2025-01-05T00:00:00+00:00 [queued]>
[2025-02-24T17:15:09.930+0000] {taskinstance.py:1159} INFO - Dependencies all met for dep_context=requeueable deps ti=<TaskInstance: coingecko_ingestion_dag.store_raw_data_in_hdfs scheduled__2025-01-05T00:00:00+00:00 [queued]>
[2025-02-24T17:15:09.935+0000] {taskinstance.py:1361} INFO - Starting attempt 1 of 2
[2025-02-24T17:15:10.007+0000] {taskinstance.py:1382} INFO - Executing <Task(PythonOperator): store_raw_data_in_hdfs> on 2025-01-05 00:00:00+00:00
[2025-02-24T17:15:10.033+0000] {standard_task_runner.py:57} INFO - Started process 519 to run task
[2025-02-24T17:15:10.051+0000] {standard_task_runner.py:84} INFO - Running: ['***', 'tasks', 'run', 'coingecko_ingestion_dag', 'store_raw_data_in_hdfs', 'scheduled__2025-01-05T00:00:00+00:00', '--job-id', '31', '--raw', '--subdir', 'DAGS_FOLDER/pipeline.py', '--cfg-path', '/tmp/tmpwpyie7r9']
[2025-02-24T17:15:10.066+0000] {standard_task_runner.py:85} INFO - Job 31: Subtask store_raw_data_in_hdfs
[2025-02-24T17:15:10.435+0000] {task_command.py:415} INFO - Running <TaskInstance: coingecko_ingestion_dag.store_raw_data_in_hdfs scheduled__2025-01-05T00:00:00+00:00 [running]> on host 85b967fd3989
[2025-02-24T17:15:10.891+0000] {taskinstance.py:1660} INFO - Exporting env vars: AIRFLOW_CTX_DAG_OWNER='etudiant' AIRFLOW_CTX_DAG_ID='coingecko_ingestion_dag' AIRFLOW_CTX_TASK_ID='store_raw_data_in_hdfs' AIRFLOW_CTX_EXECUTION_DATE='2025-01-05T00:00:00+00:00' AIRFLOW_CTX_TRY_NUMBER='1' AIRFLOW_CTX_DAG_RUN_ID='scheduled__2025-01-05T00:00:00+00:00'
[2025-02-24T17:15:10.920+0000] {taskinstance.py:1943} ERROR - Task failed with exception
Traceback (most recent call last):
  File "/home/airflow/.local/lib/python3.8/site-packages/airflow/operators/python.py", line 192, in execute
    return_value = self.execute_callable()
  File "/home/airflow/.local/lib/python3.8/site-packages/airflow/operators/python.py", line 209, in execute_callable
    return self.python_callable(*self.op_args, **self.op_kwargs)
  File "/opt/airflow/dags/pipeline.py", line 38, in store_raw_data_in_hdfs
    with open(local_file, 'w') as f:
PermissionError: [Errno 13] Permission denied: '/mnt/hadoop_data/coingecko_raw.json'
[2025-02-24T17:15:10.935+0000] {taskinstance.py:1400} INFO - Marking task as UP_FOR_RETRY. dag_id=coingecko_ingestion_dag, task_id=store_raw_data_in_hdfs, execution_date=20250105T000000, start_date=20250224T171509, end_date=20250224T171510
[2025-02-24T17:15:10.953+0000] {standard_task_runner.py:104} ERROR - Failed to execute job 31 for task store_raw_data_in_hdfs ([Errno 13] Permission denied: '/mnt/hadoop_data/coingecko_raw.json'; 519)
[2025-02-24T17:15:10.980+0000] {local_task_job_runner.py:228} INFO - Task exited with return code 1
[2025-02-24T17:15:10.999+0000] {taskinstance.py:2784} INFO - 0 downstream tasks scheduled from follow-on schedule check
[2025-02-25T15:52:44.430+0000] {taskinstance.py:1159} INFO - Dependencies all met for dep_context=non-requeueable deps ti=<TaskInstance: coingecko_ingestion_dag.store_raw_data_in_hdfs scheduled__2025-01-05T00:00:00+00:00 [queued]>
[2025-02-25T15:52:44.447+0000] {taskinstance.py:1159} INFO - Dependencies all met for dep_context=requeueable deps ti=<TaskInstance: coingecko_ingestion_dag.store_raw_data_in_hdfs scheduled__2025-01-05T00:00:00+00:00 [queued]>
[2025-02-25T15:52:44.448+0000] {taskinstance.py:1361} INFO - Starting attempt 1 of 2
[2025-02-25T15:52:44.470+0000] {taskinstance.py:1382} INFO - Executing <Task(PythonOperator): store_raw_data_in_hdfs> on 2025-01-05 00:00:00+00:00
[2025-02-25T15:52:44.481+0000] {standard_task_runner.py:57} INFO - Started process 301 to run task
[2025-02-25T15:52:44.485+0000] {standard_task_runner.py:84} INFO - Running: ['***', 'tasks', 'run', 'coingecko_ingestion_dag', 'store_raw_data_in_hdfs', 'scheduled__2025-01-05T00:00:00+00:00', '--job-id', '34', '--raw', '--subdir', 'DAGS_FOLDER/pipeline.py', '--cfg-path', '/tmp/tmpzm05lc76']
[2025-02-25T15:52:44.492+0000] {standard_task_runner.py:85} INFO - Job 34: Subtask store_raw_data_in_hdfs
[2025-02-25T15:52:44.568+0000] {task_command.py:415} INFO - Running <TaskInstance: coingecko_ingestion_dag.store_raw_data_in_hdfs scheduled__2025-01-05T00:00:00+00:00 [running]> on host af9744bbb9eb
[2025-02-25T15:52:44.685+0000] {taskinstance.py:1660} INFO - Exporting env vars: AIRFLOW_CTX_DAG_OWNER='etudiant' AIRFLOW_CTX_DAG_ID='coingecko_ingestion_dag' AIRFLOW_CTX_TASK_ID='store_raw_data_in_hdfs' AIRFLOW_CTX_EXECUTION_DATE='2025-01-05T00:00:00+00:00' AIRFLOW_CTX_TRY_NUMBER='1' AIRFLOW_CTX_DAG_RUN_ID='scheduled__2025-01-05T00:00:00+00:00'
[2025-02-25T15:52:44.711+0000] {taskinstance.py:1943} ERROR - Task failed with exception
Traceback (most recent call last):
  File "/home/airflow/.local/lib/python3.8/site-packages/airflow/operators/python.py", line 192, in execute
    return_value = self.execute_callable()
  File "/home/airflow/.local/lib/python3.8/site-packages/airflow/operators/python.py", line 209, in execute_callable
    return self.python_callable(*self.op_args, **self.op_kwargs)
  File "/opt/airflow/dags/pipeline.py", line 39, in store_raw_data_in_hdfs
    with open(local_file, 'w') as f:
PermissionError: [Errno 13] Permission denied: '/mnt/hadoop_data/coingecko_raw.json'
[2025-02-25T15:52:44.722+0000] {taskinstance.py:1400} INFO - Marking task as UP_FOR_RETRY. dag_id=coingecko_ingestion_dag, task_id=store_raw_data_in_hdfs, execution_date=20250105T000000, start_date=20250225T155244, end_date=20250225T155244
[2025-02-25T15:52:44.748+0000] {standard_task_runner.py:104} ERROR - Failed to execute job 34 for task store_raw_data_in_hdfs ([Errno 13] Permission denied: '/mnt/hadoop_data/coingecko_raw.json'; 301)
[2025-02-25T15:52:44.788+0000] {local_task_job_runner.py:228} INFO - Task exited with return code 1
[2025-02-25T15:52:44.816+0000] {taskinstance.py:2784} INFO - 0 downstream tasks scheduled from follow-on schedule check
