[2025-02-27T20:24:20.998+0000] {taskinstance.py:1159} INFO - Dependencies all met for dep_context=non-requeueable deps ti=<TaskInstance: coingecko_ingestion_dag.load_to_hbase manual__2025-02-27T20:18:46.392295+00:00 [queued]>
[2025-02-27T20:24:21.009+0000] {taskinstance.py:1159} INFO - Dependencies all met for dep_context=requeueable deps ti=<TaskInstance: coingecko_ingestion_dag.load_to_hbase manual__2025-02-27T20:18:46.392295+00:00 [queued]>
[2025-02-27T20:24:21.009+0000] {taskinstance.py:1361} INFO - Starting attempt 2 of 4
[2025-02-27T20:24:21.024+0000] {taskinstance.py:1382} INFO - Executing <Task(PythonOperator): load_to_hbase> on 2025-02-27 20:18:46.392295+00:00
[2025-02-27T20:24:21.029+0000] {standard_task_runner.py:57} INFO - Started process 989 to run task
[2025-02-27T20:24:21.033+0000] {standard_task_runner.py:84} INFO - Running: ['***', 'tasks', 'run', 'coingecko_ingestion_dag', 'load_to_hbase', 'manual__2025-02-27T20:18:46.392295+00:00', '--job-id', '401', '--raw', '--subdir', 'DAGS_FOLDER/pipeline.py', '--cfg-path', '/tmp/tmpns6ocnq5']
[2025-02-27T20:24:21.036+0000] {standard_task_runner.py:85} INFO - Job 401: Subtask load_to_hbase
[2025-02-27T20:24:21.088+0000] {task_command.py:415} INFO - Running <TaskInstance: coingecko_ingestion_dag.load_to_hbase manual__2025-02-27T20:18:46.392295+00:00 [running]> on host 04b500935d21
[2025-02-27T20:24:21.167+0000] {taskinstance.py:1660} INFO - Exporting env vars: AIRFLOW_CTX_DAG_OWNER='etudiant' AIRFLOW_CTX_DAG_ID='coingecko_ingestion_dag' AIRFLOW_CTX_TASK_ID='load_to_hbase' AIRFLOW_CTX_EXECUTION_DATE='2025-02-27T20:18:46.392295+00:00' AIRFLOW_CTX_TRY_NUMBER='2' AIRFLOW_CTX_DAG_RUN_ID='manual__2025-02-27T20:18:46.392295+00:00'
[2025-02-27T20:24:23.048+0000] {taskinstance.py:1943} ERROR - Task failed with exception
Traceback (most recent call last):
  File "/home/airflow/.local/lib/python3.8/site-packages/airflow/operators/python.py", line 192, in execute
    return_value = self.execute_callable()
  File "/home/airflow/.local/lib/python3.8/site-packages/airflow/operators/python.py", line 209, in execute_callable
    return self.python_callable(*self.op_args, **self.op_kwargs)
  File "/opt/airflow/dags/pipeline.py", line 59, in load_to_hbase
    raise Exception(f"Failed to get file from HDFS: {result.stderr}")
Exception: Failed to get file from HDFS: get: `/tmp/crypto_agg.csv': File exists

[2025-02-27T20:24:23.068+0000] {taskinstance.py:1400} INFO - Marking task as UP_FOR_RETRY. dag_id=coingecko_ingestion_dag, task_id=load_to_hbase, execution_date=20250227T201846, start_date=20250227T202420, end_date=20250227T202423
[2025-02-27T20:24:23.083+0000] {standard_task_runner.py:104} ERROR - Failed to execute job 401 for task load_to_hbase (Failed to get file from HDFS: get: `/tmp/crypto_agg.csv': File exists
; 989)
[2025-02-27T20:24:23.097+0000] {local_task_job_runner.py:228} INFO - Task exited with return code 1
[2025-02-27T20:24:23.144+0000] {taskinstance.py:2784} INFO - 0 downstream tasks scheduled from follow-on schedule check
