[2025-02-24T17:30:42.440+0000] {taskinstance.py:1159} INFO - Dependencies all met for dep_context=non-requeueable deps ti=<TaskInstance: coingecko_ingestion_dag.store_raw_data_in_hdfs scheduled__2025-02-10T00:00:00+00:00 [queued]>
[2025-02-24T17:30:42.463+0000] {taskinstance.py:1159} INFO - Dependencies all met for dep_context=requeueable deps ti=<TaskInstance: coingecko_ingestion_dag.store_raw_data_in_hdfs scheduled__2025-02-10T00:00:00+00:00 [queued]>
[2025-02-24T17:30:42.464+0000] {taskinstance.py:1361} INFO - Starting attempt 2 of 2
[2025-02-24T17:30:42.499+0000] {taskinstance.py:1382} INFO - Executing <Task(PythonOperator): store_raw_data_in_hdfs> on 2025-02-10 00:00:00+00:00
[2025-02-24T17:30:42.513+0000] {standard_task_runner.py:57} INFO - Started process 1035 to run task
[2025-02-24T17:30:42.524+0000] {standard_task_runner.py:84} INFO - Running: ['***', 'tasks', 'run', 'coingecko_ingestion_dag', 'store_raw_data_in_hdfs', 'scheduled__2025-02-10T00:00:00+00:00', '--job-id', '138', '--raw', '--subdir', 'DAGS_FOLDER/test.py', '--cfg-path', '/tmp/tmpnlpy_m2y']
[2025-02-24T17:30:42.534+0000] {standard_task_runner.py:85} INFO - Job 138: Subtask store_raw_data_in_hdfs
[2025-02-24T17:30:42.644+0000] {task_command.py:415} INFO - Running <TaskInstance: coingecko_ingestion_dag.store_raw_data_in_hdfs scheduled__2025-02-10T00:00:00+00:00 [running]> on host 85b967fd3989
[2025-02-24T17:30:42.800+0000] {taskinstance.py:1660} INFO - Exporting env vars: AIRFLOW_CTX_DAG_OWNER='etudiant' AIRFLOW_CTX_DAG_ID='coingecko_ingestion_dag' AIRFLOW_CTX_TASK_ID='store_raw_data_in_hdfs' AIRFLOW_CTX_EXECUTION_DATE='2025-02-10T00:00:00+00:00' AIRFLOW_CTX_TRY_NUMBER='2' AIRFLOW_CTX_DAG_RUN_ID='scheduled__2025-02-10T00:00:00+00:00'
[2025-02-24T17:30:42.830+0000] {taskinstance.py:1943} ERROR - Task failed with exception
Traceback (most recent call last):
  File "/home/airflow/.local/lib/python3.8/site-packages/airflow/operators/python.py", line 192, in execute
    return_value = self.execute_callable()
  File "/home/airflow/.local/lib/python3.8/site-packages/airflow/operators/python.py", line 209, in execute_callable
    return self.python_callable(*self.op_args, **self.op_kwargs)
  File "/opt/airflow/dags/test.py", line 38, in store_raw_data_in_hdfs
    with open(local_file, 'w') as f:
PermissionError: [Errno 13] Permission denied: '/mnt/hadoop_data/coingecko_raw.json'
[2025-02-24T17:30:42.854+0000] {taskinstance.py:1400} INFO - Marking task as FAILED. dag_id=coingecko_ingestion_dag, task_id=store_raw_data_in_hdfs, execution_date=20250210T000000, start_date=20250224T173042, end_date=20250224T173042
[2025-02-24T17:30:42.874+0000] {standard_task_runner.py:104} ERROR - Failed to execute job 138 for task store_raw_data_in_hdfs ([Errno 13] Permission denied: '/mnt/hadoop_data/coingecko_raw.json'; 1035)
[2025-02-24T17:30:42.920+0000] {local_task_job_runner.py:228} INFO - Task exited with return code 1
[2025-02-24T17:30:42.950+0000] {taskinstance.py:2784} INFO - 0 downstream tasks scheduled from follow-on schedule check
[2025-02-25T16:04:28.234+0000] {taskinstance.py:1159} INFO - Dependencies all met for dep_context=non-requeueable deps ti=<TaskInstance: coingecko_ingestion_dag.store_raw_data_in_hdfs scheduled__2025-02-10T00:00:00+00:00 [queued]>
[2025-02-25T16:04:28.253+0000] {taskinstance.py:1159} INFO - Dependencies all met for dep_context=requeueable deps ti=<TaskInstance: coingecko_ingestion_dag.store_raw_data_in_hdfs scheduled__2025-02-10T00:00:00+00:00 [queued]>
[2025-02-25T16:04:28.256+0000] {taskinstance.py:1361} INFO - Starting attempt 2 of 2
[2025-02-25T16:04:28.282+0000] {taskinstance.py:1382} INFO - Executing <Task(PythonOperator): store_raw_data_in_hdfs> on 2025-02-10 00:00:00+00:00
[2025-02-25T16:04:28.289+0000] {standard_task_runner.py:57} INFO - Started process 638 to run task
[2025-02-25T16:04:28.294+0000] {standard_task_runner.py:84} INFO - Running: ['***', 'tasks', 'run', 'coingecko_ingestion_dag', 'store_raw_data_in_hdfs', 'scheduled__2025-02-10T00:00:00+00:00', '--job-id', '145', '--raw', '--subdir', 'DAGS_FOLDER/pipeline.py', '--cfg-path', '/tmp/tmp6oufe2i9']
[2025-02-25T16:04:28.299+0000] {standard_task_runner.py:85} INFO - Job 145: Subtask store_raw_data_in_hdfs
[2025-02-25T16:04:28.376+0000] {task_command.py:415} INFO - Running <TaskInstance: coingecko_ingestion_dag.store_raw_data_in_hdfs scheduled__2025-02-10T00:00:00+00:00 [running]> on host af9744bbb9eb
[2025-02-25T16:04:28.504+0000] {taskinstance.py:1660} INFO - Exporting env vars: AIRFLOW_CTX_DAG_OWNER='etudiant' AIRFLOW_CTX_DAG_ID='coingecko_ingestion_dag' AIRFLOW_CTX_TASK_ID='store_raw_data_in_hdfs' AIRFLOW_CTX_EXECUTION_DATE='2025-02-10T00:00:00+00:00' AIRFLOW_CTX_TRY_NUMBER='2' AIRFLOW_CTX_DAG_RUN_ID='scheduled__2025-02-10T00:00:00+00:00'
[2025-02-25T16:04:28.522+0000] {taskinstance.py:1943} ERROR - Task failed with exception
Traceback (most recent call last):
  File "/home/airflow/.local/lib/python3.8/site-packages/airflow/operators/python.py", line 192, in execute
    return_value = self.execute_callable()
  File "/home/airflow/.local/lib/python3.8/site-packages/airflow/operators/python.py", line 209, in execute_callable
    return self.python_callable(*self.op_args, **self.op_kwargs)
  File "/opt/airflow/dags/pipeline.py", line 39, in store_raw_data_in_hdfs
    with open(local_file, 'w') as f:
PermissionError: [Errno 13] Permission denied: '/mnt/hadoop_data/coingecko_raw.json'
[2025-02-25T16:04:28.538+0000] {taskinstance.py:1400} INFO - Marking task as FAILED. dag_id=coingecko_ingestion_dag, task_id=store_raw_data_in_hdfs, execution_date=20250210T000000, start_date=20250225T160428, end_date=20250225T160428
[2025-02-25T16:04:28.555+0000] {standard_task_runner.py:104} ERROR - Failed to execute job 145 for task store_raw_data_in_hdfs ([Errno 13] Permission denied: '/mnt/hadoop_data/coingecko_raw.json'; 638)
[2025-02-25T16:04:28.595+0000] {local_task_job_runner.py:228} INFO - Task exited with return code 1
[2025-02-25T16:04:28.619+0000] {taskinstance.py:2784} INFO - 0 downstream tasks scheduled from follow-on schedule check
