[2025-02-24T17:25:30.781+0000] {taskinstance.py:1159} INFO - Dependencies all met for dep_context=non-requeueable deps ti=<TaskInstance: coingecko_ingestion_dag.store_raw_data_in_hdfs scheduled__2025-01-17T00:00:00+00:00 [queued]>
[2025-02-24T17:25:30.845+0000] {taskinstance.py:1159} INFO - Dependencies all met for dep_context=requeueable deps ti=<TaskInstance: coingecko_ingestion_dag.store_raw_data_in_hdfs scheduled__2025-01-17T00:00:00+00:00 [queued]>
[2025-02-24T17:25:30.847+0000] {taskinstance.py:1361} INFO - Starting attempt 2 of 2
[2025-02-24T17:25:30.907+0000] {taskinstance.py:1382} INFO - Executing <Task(PythonOperator): store_raw_data_in_hdfs> on 2025-01-17 00:00:00+00:00
[2025-02-24T17:25:30.937+0000] {standard_task_runner.py:57} INFO - Started process 837 to run task
[2025-02-24T17:25:30.966+0000] {standard_task_runner.py:84} INFO - Running: ['***', 'tasks', 'run', 'coingecko_ingestion_dag', 'store_raw_data_in_hdfs', 'scheduled__2025-01-17T00:00:00+00:00', '--job-id', '87', '--raw', '--subdir', 'DAGS_FOLDER/test.py', '--cfg-path', '/tmp/tmpnjam744h']
[2025-02-24T17:25:30.986+0000] {standard_task_runner.py:85} INFO - Job 87: Subtask store_raw_data_in_hdfs
[2025-02-24T17:25:31.199+0000] {task_command.py:415} INFO - Running <TaskInstance: coingecko_ingestion_dag.store_raw_data_in_hdfs scheduled__2025-01-17T00:00:00+00:00 [running]> on host 85b967fd3989
[2025-02-24T17:25:31.477+0000] {taskinstance.py:1660} INFO - Exporting env vars: AIRFLOW_CTX_DAG_OWNER='etudiant' AIRFLOW_CTX_DAG_ID='coingecko_ingestion_dag' AIRFLOW_CTX_TASK_ID='store_raw_data_in_hdfs' AIRFLOW_CTX_EXECUTION_DATE='2025-01-17T00:00:00+00:00' AIRFLOW_CTX_TRY_NUMBER='2' AIRFLOW_CTX_DAG_RUN_ID='scheduled__2025-01-17T00:00:00+00:00'
[2025-02-24T17:25:31.543+0000] {taskinstance.py:1943} ERROR - Task failed with exception
Traceback (most recent call last):
  File "/home/airflow/.local/lib/python3.8/site-packages/airflow/operators/python.py", line 192, in execute
    return_value = self.execute_callable()
  File "/home/airflow/.local/lib/python3.8/site-packages/airflow/operators/python.py", line 209, in execute_callable
    return self.python_callable(*self.op_args, **self.op_kwargs)
  File "/opt/airflow/dags/test.py", line 38, in store_raw_data_in_hdfs
    with open(local_file, 'w') as f:
PermissionError: [Errno 13] Permission denied: '/mnt/hadoop_data/coingecko_raw.json'
[2025-02-24T17:25:31.588+0000] {taskinstance.py:1400} INFO - Marking task as FAILED. dag_id=coingecko_ingestion_dag, task_id=store_raw_data_in_hdfs, execution_date=20250117T000000, start_date=20250224T172530, end_date=20250224T172531
[2025-02-24T17:25:31.633+0000] {standard_task_runner.py:104} ERROR - Failed to execute job 87 for task store_raw_data_in_hdfs ([Errno 13] Permission denied: '/mnt/hadoop_data/coingecko_raw.json'; 837)
[2025-02-24T17:25:31.713+0000] {local_task_job_runner.py:228} INFO - Task exited with return code 1
[2025-02-24T17:25:31.789+0000] {taskinstance.py:2784} INFO - 0 downstream tasks scheduled from follow-on schedule check
[2025-02-25T15:58:45.843+0000] {taskinstance.py:1159} INFO - Dependencies all met for dep_context=non-requeueable deps ti=<TaskInstance: coingecko_ingestion_dag.store_raw_data_in_hdfs scheduled__2025-01-17T00:00:00+00:00 [queued]>
[2025-02-25T15:58:45.851+0000] {taskinstance.py:1159} INFO - Dependencies all met for dep_context=requeueable deps ti=<TaskInstance: coingecko_ingestion_dag.store_raw_data_in_hdfs scheduled__2025-01-17T00:00:00+00:00 [queued]>
[2025-02-25T15:58:45.852+0000] {taskinstance.py:1361} INFO - Starting attempt 2 of 2
[2025-02-25T15:58:45.866+0000] {taskinstance.py:1382} INFO - Executing <Task(PythonOperator): store_raw_data_in_hdfs> on 2025-01-17 00:00:00+00:00
[2025-02-25T15:58:45.870+0000] {standard_task_runner.py:57} INFO - Started process 456 to run task
[2025-02-25T15:58:45.874+0000] {standard_task_runner.py:84} INFO - Running: ['***', 'tasks', 'run', 'coingecko_ingestion_dag', 'store_raw_data_in_hdfs', 'scheduled__2025-01-17T00:00:00+00:00', '--job-id', '84', '--raw', '--subdir', 'DAGS_FOLDER/pipeline.py', '--cfg-path', '/tmp/tmpn91ecng9']
[2025-02-25T15:58:45.877+0000] {standard_task_runner.py:85} INFO - Job 84: Subtask store_raw_data_in_hdfs
[2025-02-25T15:58:45.918+0000] {task_command.py:415} INFO - Running <TaskInstance: coingecko_ingestion_dag.store_raw_data_in_hdfs scheduled__2025-01-17T00:00:00+00:00 [running]> on host af9744bbb9eb
[2025-02-25T15:58:45.990+0000] {taskinstance.py:1660} INFO - Exporting env vars: AIRFLOW_CTX_DAG_OWNER='etudiant' AIRFLOW_CTX_DAG_ID='coingecko_ingestion_dag' AIRFLOW_CTX_TASK_ID='store_raw_data_in_hdfs' AIRFLOW_CTX_EXECUTION_DATE='2025-01-17T00:00:00+00:00' AIRFLOW_CTX_TRY_NUMBER='2' AIRFLOW_CTX_DAG_RUN_ID='scheduled__2025-01-17T00:00:00+00:00'
[2025-02-25T15:58:46.006+0000] {taskinstance.py:1943} ERROR - Task failed with exception
Traceback (most recent call last):
  File "/home/airflow/.local/lib/python3.8/site-packages/airflow/operators/python.py", line 192, in execute
    return_value = self.execute_callable()
  File "/home/airflow/.local/lib/python3.8/site-packages/airflow/operators/python.py", line 209, in execute_callable
    return self.python_callable(*self.op_args, **self.op_kwargs)
  File "/opt/airflow/dags/pipeline.py", line 39, in store_raw_data_in_hdfs
    with open(local_file, 'w') as f:
PermissionError: [Errno 13] Permission denied: '/mnt/hadoop_data/coingecko_raw.json'
[2025-02-25T15:58:46.013+0000] {taskinstance.py:1400} INFO - Marking task as FAILED. dag_id=coingecko_ingestion_dag, task_id=store_raw_data_in_hdfs, execution_date=20250117T000000, start_date=20250225T155845, end_date=20250225T155846
[2025-02-25T15:58:46.022+0000] {standard_task_runner.py:104} ERROR - Failed to execute job 84 for task store_raw_data_in_hdfs ([Errno 13] Permission denied: '/mnt/hadoop_data/coingecko_raw.json'; 456)
[2025-02-25T15:58:46.055+0000] {local_task_job_runner.py:228} INFO - Task exited with return code 1
[2025-02-25T15:58:46.074+0000] {taskinstance.py:2784} INFO - 0 downstream tasks scheduled from follow-on schedule check
