[2025-02-24T17:25:41.156+0000] {taskinstance.py:1159} INFO - Dependencies all met for dep_context=non-requeueable deps ti=<TaskInstance: coingecko_ingestion_dag.store_raw_data_in_hdfs scheduled__2025-02-13T00:00:00+00:00 [queued]>
[2025-02-24T17:25:41.177+0000] {taskinstance.py:1159} INFO - Dependencies all met for dep_context=requeueable deps ti=<TaskInstance: coingecko_ingestion_dag.store_raw_data_in_hdfs scheduled__2025-02-13T00:00:00+00:00 [queued]>
[2025-02-24T17:25:41.178+0000] {taskinstance.py:1361} INFO - Starting attempt 1 of 2
[2025-02-24T17:25:41.206+0000] {taskinstance.py:1382} INFO - Executing <Task(PythonOperator): store_raw_data_in_hdfs> on 2025-02-13 00:00:00+00:00
[2025-02-24T17:25:41.219+0000] {standard_task_runner.py:57} INFO - Started process 906 to run task
[2025-02-24T17:25:41.229+0000] {standard_task_runner.py:84} INFO - Running: ['***', 'tasks', 'run', 'coingecko_ingestion_dag', 'store_raw_data_in_hdfs', 'scheduled__2025-02-13T00:00:00+00:00', '--job-id', '125', '--raw', '--subdir', 'DAGS_FOLDER/test.py', '--cfg-path', '/tmp/tmpmzzhzevc']
[2025-02-24T17:25:41.234+0000] {standard_task_runner.py:85} INFO - Job 125: Subtask store_raw_data_in_hdfs
[2025-02-24T17:25:41.326+0000] {task_command.py:415} INFO - Running <TaskInstance: coingecko_ingestion_dag.store_raw_data_in_hdfs scheduled__2025-02-13T00:00:00+00:00 [running]> on host 85b967fd3989
[2025-02-24T17:25:41.444+0000] {taskinstance.py:1660} INFO - Exporting env vars: AIRFLOW_CTX_DAG_OWNER='etudiant' AIRFLOW_CTX_DAG_ID='coingecko_ingestion_dag' AIRFLOW_CTX_TASK_ID='store_raw_data_in_hdfs' AIRFLOW_CTX_EXECUTION_DATE='2025-02-13T00:00:00+00:00' AIRFLOW_CTX_TRY_NUMBER='1' AIRFLOW_CTX_DAG_RUN_ID='scheduled__2025-02-13T00:00:00+00:00'
[2025-02-24T17:25:41.459+0000] {taskinstance.py:1943} ERROR - Task failed with exception
Traceback (most recent call last):
  File "/home/airflow/.local/lib/python3.8/site-packages/airflow/operators/python.py", line 192, in execute
    return_value = self.execute_callable()
  File "/home/airflow/.local/lib/python3.8/site-packages/airflow/operators/python.py", line 209, in execute_callable
    return self.python_callable(*self.op_args, **self.op_kwargs)
  File "/opt/airflow/dags/test.py", line 38, in store_raw_data_in_hdfs
    with open(local_file, 'w') as f:
PermissionError: [Errno 13] Permission denied: '/mnt/hadoop_data/coingecko_raw.json'
[2025-02-24T17:25:41.474+0000] {taskinstance.py:1400} INFO - Marking task as UP_FOR_RETRY. dag_id=coingecko_ingestion_dag, task_id=store_raw_data_in_hdfs, execution_date=20250213T000000, start_date=20250224T172541, end_date=20250224T172541
[2025-02-24T17:25:41.488+0000] {standard_task_runner.py:104} ERROR - Failed to execute job 125 for task store_raw_data_in_hdfs ([Errno 13] Permission denied: '/mnt/hadoop_data/coingecko_raw.json'; 906)
[2025-02-24T17:25:41.531+0000] {local_task_job_runner.py:228} INFO - Task exited with return code 1
[2025-02-24T17:25:41.547+0000] {taskinstance.py:2784} INFO - 0 downstream tasks scheduled from follow-on schedule check
[2025-02-25T15:59:28.279+0000] {taskinstance.py:1159} INFO - Dependencies all met for dep_context=non-requeueable deps ti=<TaskInstance: coingecko_ingestion_dag.store_raw_data_in_hdfs scheduled__2025-02-13T00:00:00+00:00 [queued]>
[2025-02-25T15:59:28.291+0000] {taskinstance.py:1159} INFO - Dependencies all met for dep_context=requeueable deps ti=<TaskInstance: coingecko_ingestion_dag.store_raw_data_in_hdfs scheduled__2025-02-13T00:00:00+00:00 [queued]>
[2025-02-25T15:59:28.292+0000] {taskinstance.py:1361} INFO - Starting attempt 1 of 2
[2025-02-25T15:59:28.305+0000] {taskinstance.py:1382} INFO - Executing <Task(PythonOperator): store_raw_data_in_hdfs> on 2025-02-13 00:00:00+00:00
[2025-02-25T15:59:28.312+0000] {standard_task_runner.py:57} INFO - Started process 551 to run task
[2025-02-25T15:59:28.316+0000] {standard_task_runner.py:84} INFO - Running: ['***', 'tasks', 'run', 'coingecko_ingestion_dag', 'store_raw_data_in_hdfs', 'scheduled__2025-02-13T00:00:00+00:00', '--job-id', '126', '--raw', '--subdir', 'DAGS_FOLDER/pipeline.py', '--cfg-path', '/tmp/tmpnbb7yox1']
[2025-02-25T15:59:28.320+0000] {standard_task_runner.py:85} INFO - Job 126: Subtask store_raw_data_in_hdfs
[2025-02-25T15:59:28.382+0000] {task_command.py:415} INFO - Running <TaskInstance: coingecko_ingestion_dag.store_raw_data_in_hdfs scheduled__2025-02-13T00:00:00+00:00 [running]> on host af9744bbb9eb
[2025-02-25T15:59:28.479+0000] {taskinstance.py:1660} INFO - Exporting env vars: AIRFLOW_CTX_DAG_OWNER='etudiant' AIRFLOW_CTX_DAG_ID='coingecko_ingestion_dag' AIRFLOW_CTX_TASK_ID='store_raw_data_in_hdfs' AIRFLOW_CTX_EXECUTION_DATE='2025-02-13T00:00:00+00:00' AIRFLOW_CTX_TRY_NUMBER='1' AIRFLOW_CTX_DAG_RUN_ID='scheduled__2025-02-13T00:00:00+00:00'
[2025-02-25T15:59:28.497+0000] {taskinstance.py:1943} ERROR - Task failed with exception
Traceback (most recent call last):
  File "/home/airflow/.local/lib/python3.8/site-packages/airflow/operators/python.py", line 192, in execute
    return_value = self.execute_callable()
  File "/home/airflow/.local/lib/python3.8/site-packages/airflow/operators/python.py", line 209, in execute_callable
    return self.python_callable(*self.op_args, **self.op_kwargs)
  File "/opt/airflow/dags/pipeline.py", line 39, in store_raw_data_in_hdfs
    with open(local_file, 'w') as f:
PermissionError: [Errno 13] Permission denied: '/mnt/hadoop_data/coingecko_raw.json'
[2025-02-25T15:59:28.508+0000] {taskinstance.py:1400} INFO - Marking task as UP_FOR_RETRY. dag_id=coingecko_ingestion_dag, task_id=store_raw_data_in_hdfs, execution_date=20250213T000000, start_date=20250225T155928, end_date=20250225T155928
[2025-02-25T15:59:28.551+0000] {standard_task_runner.py:104} ERROR - Failed to execute job 126 for task store_raw_data_in_hdfs ([Errno 13] Permission denied: '/mnt/hadoop_data/coingecko_raw.json'; 551)
[2025-02-25T15:59:28.577+0000] {local_task_job_runner.py:228} INFO - Task exited with return code 1
[2025-02-25T15:59:28.598+0000] {taskinstance.py:2784} INFO - 0 downstream tasks scheduled from follow-on schedule check
