[2025-02-24T17:30:44.328+0000] {taskinstance.py:1159} INFO - Dependencies all met for dep_context=non-requeueable deps ti=<TaskInstance: coingecko_ingestion_dag.store_raw_data_in_hdfs scheduled__2025-02-16T00:00:00+00:00 [queued]>
[2025-02-24T17:30:44.343+0000] {taskinstance.py:1159} INFO - Dependencies all met for dep_context=requeueable deps ti=<TaskInstance: coingecko_ingestion_dag.store_raw_data_in_hdfs scheduled__2025-02-16T00:00:00+00:00 [queued]>
[2025-02-24T17:30:44.344+0000] {taskinstance.py:1361} INFO - Starting attempt 2 of 2
[2025-02-24T17:30:44.360+0000] {taskinstance.py:1382} INFO - Executing <Task(PythonOperator): store_raw_data_in_hdfs> on 2025-02-16 00:00:00+00:00
[2025-02-24T17:30:44.364+0000] {standard_task_runner.py:57} INFO - Started process 1044 to run task
[2025-02-24T17:30:44.369+0000] {standard_task_runner.py:84} INFO - Running: ['***', 'tasks', 'run', 'coingecko_ingestion_dag', 'store_raw_data_in_hdfs', 'scheduled__2025-02-16T00:00:00+00:00', '--job-id', '145', '--raw', '--subdir', 'DAGS_FOLDER/test.py', '--cfg-path', '/tmp/tmp99d0g53s']
[2025-02-24T17:30:44.374+0000] {standard_task_runner.py:85} INFO - Job 145: Subtask store_raw_data_in_hdfs
[2025-02-24T17:30:44.426+0000] {task_command.py:415} INFO - Running <TaskInstance: coingecko_ingestion_dag.store_raw_data_in_hdfs scheduled__2025-02-16T00:00:00+00:00 [running]> on host 85b967fd3989
[2025-02-24T17:30:44.503+0000] {taskinstance.py:1660} INFO - Exporting env vars: AIRFLOW_CTX_DAG_OWNER='etudiant' AIRFLOW_CTX_DAG_ID='coingecko_ingestion_dag' AIRFLOW_CTX_TASK_ID='store_raw_data_in_hdfs' AIRFLOW_CTX_EXECUTION_DATE='2025-02-16T00:00:00+00:00' AIRFLOW_CTX_TRY_NUMBER='2' AIRFLOW_CTX_DAG_RUN_ID='scheduled__2025-02-16T00:00:00+00:00'
[2025-02-24T17:30:44.514+0000] {taskinstance.py:1943} ERROR - Task failed with exception
Traceback (most recent call last):
  File "/home/airflow/.local/lib/python3.8/site-packages/airflow/operators/python.py", line 192, in execute
    return_value = self.execute_callable()
  File "/home/airflow/.local/lib/python3.8/site-packages/airflow/operators/python.py", line 209, in execute_callable
    return self.python_callable(*self.op_args, **self.op_kwargs)
  File "/opt/airflow/dags/test.py", line 38, in store_raw_data_in_hdfs
    with open(local_file, 'w') as f:
PermissionError: [Errno 13] Permission denied: '/mnt/hadoop_data/coingecko_raw.json'
[2025-02-24T17:30:44.524+0000] {taskinstance.py:1400} INFO - Marking task as FAILED. dag_id=coingecko_ingestion_dag, task_id=store_raw_data_in_hdfs, execution_date=20250216T000000, start_date=20250224T173044, end_date=20250224T173044
[2025-02-24T17:30:44.535+0000] {standard_task_runner.py:104} ERROR - Failed to execute job 145 for task store_raw_data_in_hdfs ([Errno 13] Permission denied: '/mnt/hadoop_data/coingecko_raw.json'; 1044)
[2025-02-24T17:30:44.549+0000] {local_task_job_runner.py:228} INFO - Task exited with return code 1
[2025-02-24T17:30:44.564+0000] {taskinstance.py:2784} INFO - 0 downstream tasks scheduled from follow-on schedule check
[2025-02-25T16:08:00.228+0000] {taskinstance.py:1159} INFO - Dependencies all met for dep_context=non-requeueable deps ti=<TaskInstance: coingecko_ingestion_dag.store_raw_data_in_hdfs scheduled__2025-02-16T00:00:00+00:00 [queued]>
[2025-02-25T16:08:00.237+0000] {taskinstance.py:1159} INFO - Dependencies all met for dep_context=requeueable deps ti=<TaskInstance: coingecko_ingestion_dag.store_raw_data_in_hdfs scheduled__2025-02-16T00:00:00+00:00 [queued]>
[2025-02-25T16:08:00.238+0000] {taskinstance.py:1361} INFO - Starting attempt 2 of 2
[2025-02-25T16:08:00.251+0000] {taskinstance.py:1382} INFO - Executing <Task(PythonOperator): store_raw_data_in_hdfs> on 2025-02-16 00:00:00+00:00
[2025-02-25T16:08:00.255+0000] {standard_task_runner.py:57} INFO - Started process 707 to run task
[2025-02-25T16:08:00.258+0000] {standard_task_runner.py:84} INFO - Running: ['***', 'tasks', 'run', 'coingecko_ingestion_dag', 'store_raw_data_in_hdfs', 'scheduled__2025-02-16T00:00:00+00:00', '--job-id', '162', '--raw', '--subdir', 'DAGS_FOLDER/pipeline.py', '--cfg-path', '/tmp/tmp4qt75i9q']
[2025-02-25T16:08:00.260+0000] {standard_task_runner.py:85} INFO - Job 162: Subtask store_raw_data_in_hdfs
[2025-02-25T16:08:00.297+0000] {task_command.py:415} INFO - Running <TaskInstance: coingecko_ingestion_dag.store_raw_data_in_hdfs scheduled__2025-02-16T00:00:00+00:00 [running]> on host af9744bbb9eb
[2025-02-25T16:08:00.358+0000] {taskinstance.py:1660} INFO - Exporting env vars: AIRFLOW_CTX_DAG_OWNER='etudiant' AIRFLOW_CTX_DAG_ID='coingecko_ingestion_dag' AIRFLOW_CTX_TASK_ID='store_raw_data_in_hdfs' AIRFLOW_CTX_EXECUTION_DATE='2025-02-16T00:00:00+00:00' AIRFLOW_CTX_TRY_NUMBER='2' AIRFLOW_CTX_DAG_RUN_ID='scheduled__2025-02-16T00:00:00+00:00'
[2025-02-25T16:08:00.376+0000] {taskinstance.py:1943} ERROR - Task failed with exception
Traceback (most recent call last):
  File "/home/airflow/.local/lib/python3.8/site-packages/airflow/operators/python.py", line 192, in execute
    return_value = self.execute_callable()
  File "/home/airflow/.local/lib/python3.8/site-packages/airflow/operators/python.py", line 209, in execute_callable
    return self.python_callable(*self.op_args, **self.op_kwargs)
  File "/opt/airflow/dags/pipeline.py", line 39, in store_raw_data_in_hdfs
    with open(local_file, 'w') as f:
PermissionError: [Errno 13] Permission denied: '/mnt/hadoop_data/coingecko_raw.json'
[2025-02-25T16:08:00.383+0000] {taskinstance.py:1400} INFO - Marking task as FAILED. dag_id=coingecko_ingestion_dag, task_id=store_raw_data_in_hdfs, execution_date=20250216T000000, start_date=20250225T160800, end_date=20250225T160800
[2025-02-25T16:08:00.392+0000] {standard_task_runner.py:104} ERROR - Failed to execute job 162 for task store_raw_data_in_hdfs ([Errno 13] Permission denied: '/mnt/hadoop_data/coingecko_raw.json'; 707)
[2025-02-25T16:08:00.436+0000] {local_task_job_runner.py:228} INFO - Task exited with return code 1
[2025-02-25T16:08:00.452+0000] {taskinstance.py:2784} INFO - 0 downstream tasks scheduled from follow-on schedule check
