[2025-02-24T17:20:11.346+0000] {taskinstance.py:1159} INFO - Dependencies all met for dep_context=non-requeueable deps ti=<TaskInstance: coingecko_ingestion_dag.store_raw_data_in_hdfs scheduled__2025-01-06T00:00:00+00:00 [queued]>
[2025-02-24T17:20:11.362+0000] {taskinstance.py:1159} INFO - Dependencies all met for dep_context=requeueable deps ti=<TaskInstance: coingecko_ingestion_dag.store_raw_data_in_hdfs scheduled__2025-01-06T00:00:00+00:00 [queued]>
[2025-02-24T17:20:11.367+0000] {taskinstance.py:1361} INFO - Starting attempt 2 of 2
[2025-02-24T17:20:11.426+0000] {taskinstance.py:1382} INFO - Executing <Task(PythonOperator): store_raw_data_in_hdfs> on 2025-01-06 00:00:00+00:00
[2025-02-24T17:20:11.440+0000] {standard_task_runner.py:57} INFO - Started process 636 to run task
[2025-02-24T17:20:11.443+0000] {standard_task_runner.py:84} INFO - Running: ['***', 'tasks', 'run', 'coingecko_ingestion_dag', 'store_raw_data_in_hdfs', 'scheduled__2025-01-06T00:00:00+00:00', '--job-id', '34', '--raw', '--subdir', 'DAGS_FOLDER/test.py', '--cfg-path', '/tmp/tmp96p3f7ah']
[2025-02-24T17:20:11.448+0000] {standard_task_runner.py:85} INFO - Job 34: Subtask store_raw_data_in_hdfs
[2025-02-24T17:20:11.570+0000] {task_command.py:415} INFO - Running <TaskInstance: coingecko_ingestion_dag.store_raw_data_in_hdfs scheduled__2025-01-06T00:00:00+00:00 [running]> on host 85b967fd3989
[2025-02-24T17:20:11.817+0000] {taskinstance.py:1660} INFO - Exporting env vars: AIRFLOW_CTX_DAG_OWNER='etudiant' AIRFLOW_CTX_DAG_ID='coingecko_ingestion_dag' AIRFLOW_CTX_TASK_ID='store_raw_data_in_hdfs' AIRFLOW_CTX_EXECUTION_DATE='2025-01-06T00:00:00+00:00' AIRFLOW_CTX_TRY_NUMBER='2' AIRFLOW_CTX_DAG_RUN_ID='scheduled__2025-01-06T00:00:00+00:00'
[2025-02-24T17:20:11.899+0000] {taskinstance.py:1943} ERROR - Task failed with exception
Traceback (most recent call last):
  File "/home/airflow/.local/lib/python3.8/site-packages/airflow/operators/python.py", line 192, in execute
    return_value = self.execute_callable()
  File "/home/airflow/.local/lib/python3.8/site-packages/airflow/operators/python.py", line 209, in execute_callable
    return self.python_callable(*self.op_args, **self.op_kwargs)
  File "/opt/airflow/dags/test.py", line 38, in store_raw_data_in_hdfs
    with open(local_file, 'w') as f:
PermissionError: [Errno 13] Permission denied: '/mnt/hadoop_data/coingecko_raw.json'
[2025-02-24T17:20:11.932+0000] {taskinstance.py:1400} INFO - Marking task as FAILED. dag_id=coingecko_ingestion_dag, task_id=store_raw_data_in_hdfs, execution_date=20250106T000000, start_date=20250224T172011, end_date=20250224T172011
[2025-02-24T17:20:12.006+0000] {standard_task_runner.py:104} ERROR - Failed to execute job 34 for task store_raw_data_in_hdfs ([Errno 13] Permission denied: '/mnt/hadoop_data/coingecko_raw.json'; 636)
[2025-02-24T17:20:12.045+0000] {local_task_job_runner.py:228} INFO - Task exited with return code 1
[2025-02-24T17:20:12.090+0000] {taskinstance.py:2784} INFO - 0 downstream tasks scheduled from follow-on schedule check
[2025-02-25T15:52:56.448+0000] {taskinstance.py:1159} INFO - Dependencies all met for dep_context=non-requeueable deps ti=<TaskInstance: coingecko_ingestion_dag.store_raw_data_in_hdfs scheduled__2025-01-06T00:00:00+00:00 [queued]>
[2025-02-25T15:52:56.494+0000] {taskinstance.py:1159} INFO - Dependencies all met for dep_context=requeueable deps ti=<TaskInstance: coingecko_ingestion_dag.store_raw_data_in_hdfs scheduled__2025-01-06T00:00:00+00:00 [queued]>
[2025-02-25T15:52:56.498+0000] {taskinstance.py:1361} INFO - Starting attempt 2 of 2
[2025-02-25T15:52:56.560+0000] {taskinstance.py:1382} INFO - Executing <Task(PythonOperator): store_raw_data_in_hdfs> on 2025-01-06 00:00:00+00:00
[2025-02-25T15:52:56.594+0000] {standard_task_runner.py:57} INFO - Started process 336 to run task
[2025-02-25T15:52:56.606+0000] {standard_task_runner.py:84} INFO - Running: ['***', 'tasks', 'run', 'coingecko_ingestion_dag', 'store_raw_data_in_hdfs', 'scheduled__2025-01-06T00:00:00+00:00', '--job-id', '49', '--raw', '--subdir', 'DAGS_FOLDER/pipeline.py', '--cfg-path', '/tmp/tmpvev1u_i0']
[2025-02-25T15:52:56.624+0000] {standard_task_runner.py:85} INFO - Job 49: Subtask store_raw_data_in_hdfs
[2025-02-25T15:52:56.970+0000] {task_command.py:415} INFO - Running <TaskInstance: coingecko_ingestion_dag.store_raw_data_in_hdfs scheduled__2025-01-06T00:00:00+00:00 [running]> on host af9744bbb9eb
[2025-02-25T15:52:57.334+0000] {taskinstance.py:1660} INFO - Exporting env vars: AIRFLOW_CTX_DAG_OWNER='etudiant' AIRFLOW_CTX_DAG_ID='coingecko_ingestion_dag' AIRFLOW_CTX_TASK_ID='store_raw_data_in_hdfs' AIRFLOW_CTX_EXECUTION_DATE='2025-01-06T00:00:00+00:00' AIRFLOW_CTX_TRY_NUMBER='2' AIRFLOW_CTX_DAG_RUN_ID='scheduled__2025-01-06T00:00:00+00:00'
[2025-02-25T15:52:57.411+0000] {taskinstance.py:1943} ERROR - Task failed with exception
Traceback (most recent call last):
  File "/home/airflow/.local/lib/python3.8/site-packages/airflow/operators/python.py", line 192, in execute
    return_value = self.execute_callable()
  File "/home/airflow/.local/lib/python3.8/site-packages/airflow/operators/python.py", line 209, in execute_callable
    return self.python_callable(*self.op_args, **self.op_kwargs)
  File "/opt/airflow/dags/pipeline.py", line 39, in store_raw_data_in_hdfs
    with open(local_file, 'w') as f:
PermissionError: [Errno 13] Permission denied: '/mnt/hadoop_data/coingecko_raw.json'
[2025-02-25T15:52:57.440+0000] {taskinstance.py:1400} INFO - Marking task as FAILED. dag_id=coingecko_ingestion_dag, task_id=store_raw_data_in_hdfs, execution_date=20250106T000000, start_date=20250225T155256, end_date=20250225T155257
[2025-02-25T15:52:57.515+0000] {standard_task_runner.py:104} ERROR - Failed to execute job 49 for task store_raw_data_in_hdfs ([Errno 13] Permission denied: '/mnt/hadoop_data/coingecko_raw.json'; 336)
[2025-02-25T15:52:57.567+0000] {local_task_job_runner.py:228} INFO - Task exited with return code 1
[2025-02-25T15:52:57.604+0000] {taskinstance.py:2784} INFO - 0 downstream tasks scheduled from follow-on schedule check
