[2025-02-24T17:15:09.038+0000] {taskinstance.py:1159} INFO - Dependencies all met for dep_context=non-requeueable deps ti=<TaskInstance: coingecko_ingestion_dag.store_raw_data_in_hdfs scheduled__2025-01-06T00:00:00+00:00 [queued]>
[2025-02-24T17:15:09.195+0000] {taskinstance.py:1159} INFO - Dependencies all met for dep_context=requeueable deps ti=<TaskInstance: coingecko_ingestion_dag.store_raw_data_in_hdfs scheduled__2025-01-06T00:00:00+00:00 [queued]>
[2025-02-24T17:15:09.207+0000] {taskinstance.py:1361} INFO - Starting attempt 1 of 2
[2025-02-24T17:15:09.440+0000] {taskinstance.py:1382} INFO - Executing <Task(PythonOperator): store_raw_data_in_hdfs> on 2025-01-06 00:00:00+00:00
[2025-02-24T17:15:09.462+0000] {standard_task_runner.py:57} INFO - Started process 505 to run task
[2025-02-24T17:15:09.478+0000] {standard_task_runner.py:84} INFO - Running: ['***', 'tasks', 'run', 'coingecko_ingestion_dag', 'store_raw_data_in_hdfs', 'scheduled__2025-01-06T00:00:00+00:00', '--job-id', '19', '--raw', '--subdir', 'DAGS_FOLDER/pipeline.py', '--cfg-path', '/tmp/tmpp1q1cbj0']
[2025-02-24T17:15:09.510+0000] {standard_task_runner.py:85} INFO - Job 19: Subtask store_raw_data_in_hdfs
[2025-02-24T17:15:09.868+0000] {task_command.py:415} INFO - Running <TaskInstance: coingecko_ingestion_dag.store_raw_data_in_hdfs scheduled__2025-01-06T00:00:00+00:00 [running]> on host 85b967fd3989
[2025-02-24T17:15:10.117+0000] {taskinstance.py:1660} INFO - Exporting env vars: AIRFLOW_CTX_DAG_OWNER='etudiant' AIRFLOW_CTX_DAG_ID='coingecko_ingestion_dag' AIRFLOW_CTX_TASK_ID='store_raw_data_in_hdfs' AIRFLOW_CTX_EXECUTION_DATE='2025-01-06T00:00:00+00:00' AIRFLOW_CTX_TRY_NUMBER='1' AIRFLOW_CTX_DAG_RUN_ID='scheduled__2025-01-06T00:00:00+00:00'
[2025-02-24T17:15:10.219+0000] {taskinstance.py:1943} ERROR - Task failed with exception
Traceback (most recent call last):
  File "/home/airflow/.local/lib/python3.8/site-packages/airflow/operators/python.py", line 192, in execute
    return_value = self.execute_callable()
  File "/home/airflow/.local/lib/python3.8/site-packages/airflow/operators/python.py", line 209, in execute_callable
    return self.python_callable(*self.op_args, **self.op_kwargs)
  File "/opt/airflow/dags/pipeline.py", line 38, in store_raw_data_in_hdfs
    with open(local_file, 'w') as f:
PermissionError: [Errno 13] Permission denied: '/mnt/hadoop_data/coingecko_raw.json'
[2025-02-24T17:15:10.264+0000] {taskinstance.py:1400} INFO - Marking task as UP_FOR_RETRY. dag_id=coingecko_ingestion_dag, task_id=store_raw_data_in_hdfs, execution_date=20250106T000000, start_date=20250224T171509, end_date=20250224T171510
[2025-02-24T17:15:10.433+0000] {standard_task_runner.py:104} ERROR - Failed to execute job 19 for task store_raw_data_in_hdfs ([Errno 13] Permission denied: '/mnt/hadoop_data/coingecko_raw.json'; 505)
[2025-02-24T17:15:10.499+0000] {local_task_job_runner.py:228} INFO - Task exited with return code 1
[2025-02-24T17:15:10.549+0000] {taskinstance.py:2784} INFO - 0 downstream tasks scheduled from follow-on schedule check
[2025-02-25T15:47:49.602+0000] {taskinstance.py:1159} INFO - Dependencies all met for dep_context=non-requeueable deps ti=<TaskInstance: coingecko_ingestion_dag.store_raw_data_in_hdfs scheduled__2025-01-06T00:00:00+00:00 [queued]>
[2025-02-25T15:47:49.732+0000] {taskinstance.py:1159} INFO - Dependencies all met for dep_context=requeueable deps ti=<TaskInstance: coingecko_ingestion_dag.store_raw_data_in_hdfs scheduled__2025-01-06T00:00:00+00:00 [queued]>
[2025-02-25T15:47:49.736+0000] {taskinstance.py:1361} INFO - Starting attempt 1 of 2
[2025-02-25T15:47:49.887+0000] {taskinstance.py:1382} INFO - Executing <Task(PythonOperator): store_raw_data_in_hdfs> on 2025-01-06 00:00:00+00:00
[2025-02-25T15:47:49.938+0000] {standard_task_runner.py:57} INFO - Started process 245 to run task
[2025-02-25T15:47:49.984+0000] {standard_task_runner.py:84} INFO - Running: ['***', 'tasks', 'run', 'coingecko_ingestion_dag', 'store_raw_data_in_hdfs', 'scheduled__2025-01-06T00:00:00+00:00', '--job-id', '25', '--raw', '--subdir', 'DAGS_FOLDER/pipeline.py', '--cfg-path', '/tmp/tmpnecv8fay']
[2025-02-25T15:47:50.020+0000] {standard_task_runner.py:85} INFO - Job 25: Subtask store_raw_data_in_hdfs
[2025-02-25T15:47:50.597+0000] {task_command.py:415} INFO - Running <TaskInstance: coingecko_ingestion_dag.store_raw_data_in_hdfs scheduled__2025-01-06T00:00:00+00:00 [running]> on host af9744bbb9eb
[2025-02-25T15:47:51.490+0000] {taskinstance.py:1660} INFO - Exporting env vars: AIRFLOW_CTX_DAG_OWNER='etudiant' AIRFLOW_CTX_DAG_ID='coingecko_ingestion_dag' AIRFLOW_CTX_TASK_ID='store_raw_data_in_hdfs' AIRFLOW_CTX_EXECUTION_DATE='2025-01-06T00:00:00+00:00' AIRFLOW_CTX_TRY_NUMBER='1' AIRFLOW_CTX_DAG_RUN_ID='scheduled__2025-01-06T00:00:00+00:00'
[2025-02-25T15:47:51.587+0000] {taskinstance.py:1943} ERROR - Task failed with exception
Traceback (most recent call last):
  File "/home/airflow/.local/lib/python3.8/site-packages/airflow/operators/python.py", line 192, in execute
    return_value = self.execute_callable()
  File "/home/airflow/.local/lib/python3.8/site-packages/airflow/operators/python.py", line 209, in execute_callable
    return self.python_callable(*self.op_args, **self.op_kwargs)
  File "/opt/airflow/dags/pipeline.py", line 39, in store_raw_data_in_hdfs
    with open(local_file, 'w') as f:
PermissionError: [Errno 13] Permission denied: '/mnt/hadoop_data/coingecko_raw.json'
[2025-02-25T15:47:51.642+0000] {taskinstance.py:1400} INFO - Marking task as UP_FOR_RETRY. dag_id=coingecko_ingestion_dag, task_id=store_raw_data_in_hdfs, execution_date=20250106T000000, start_date=20250225T154749, end_date=20250225T154751
[2025-02-25T15:47:51.729+0000] {standard_task_runner.py:104} ERROR - Failed to execute job 25 for task store_raw_data_in_hdfs ([Errno 13] Permission denied: '/mnt/hadoop_data/coingecko_raw.json'; 245)
[2025-02-25T15:47:51.779+0000] {local_task_job_runner.py:228} INFO - Task exited with return code 1
[2025-02-25T15:47:51.870+0000] {taskinstance.py:2784} INFO - 0 downstream tasks scheduled from follow-on schedule check
