[2025-02-24T17:20:27.373+0000] {taskinstance.py:1159} INFO - Dependencies all met for dep_context=non-requeueable deps ti=<TaskInstance: coingecko_ingestion_dag.store_raw_data_in_hdfs scheduled__2025-01-21T00:00:00+00:00 [queued]>
[2025-02-24T17:20:27.395+0000] {taskinstance.py:1159} INFO - Dependencies all met for dep_context=requeueable deps ti=<TaskInstance: coingecko_ingestion_dag.store_raw_data_in_hdfs scheduled__2025-01-21T00:00:00+00:00 [queued]>
[2025-02-24T17:20:27.398+0000] {taskinstance.py:1361} INFO - Starting attempt 1 of 2
[2025-02-24T17:20:27.434+0000] {taskinstance.py:1382} INFO - Executing <Task(PythonOperator): store_raw_data_in_hdfs> on 2025-01-21 00:00:00+00:00
[2025-02-24T17:20:27.443+0000] {standard_task_runner.py:57} INFO - Started process 685 to run task
[2025-02-24T17:20:27.448+0000] {standard_task_runner.py:84} INFO - Running: ['***', 'tasks', 'run', 'coingecko_ingestion_dag', 'store_raw_data_in_hdfs', 'scheduled__2025-01-21T00:00:00+00:00', '--job-id', '61', '--raw', '--subdir', 'DAGS_FOLDER/test.py', '--cfg-path', '/tmp/tmp4ul_nmrn']
[2025-02-24T17:20:27.461+0000] {standard_task_runner.py:85} INFO - Job 61: Subtask store_raw_data_in_hdfs
[2025-02-24T17:20:27.592+0000] {task_command.py:415} INFO - Running <TaskInstance: coingecko_ingestion_dag.store_raw_data_in_hdfs scheduled__2025-01-21T00:00:00+00:00 [running]> on host 85b967fd3989
[2025-02-24T17:20:27.796+0000] {taskinstance.py:1660} INFO - Exporting env vars: AIRFLOW_CTX_DAG_OWNER='etudiant' AIRFLOW_CTX_DAG_ID='coingecko_ingestion_dag' AIRFLOW_CTX_TASK_ID='store_raw_data_in_hdfs' AIRFLOW_CTX_EXECUTION_DATE='2025-01-21T00:00:00+00:00' AIRFLOW_CTX_TRY_NUMBER='1' AIRFLOW_CTX_DAG_RUN_ID='scheduled__2025-01-21T00:00:00+00:00'
[2025-02-24T17:20:27.846+0000] {taskinstance.py:1943} ERROR - Task failed with exception
Traceback (most recent call last):
  File "/home/airflow/.local/lib/python3.8/site-packages/airflow/operators/python.py", line 192, in execute
    return_value = self.execute_callable()
  File "/home/airflow/.local/lib/python3.8/site-packages/airflow/operators/python.py", line 209, in execute_callable
    return self.python_callable(*self.op_args, **self.op_kwargs)
  File "/opt/airflow/dags/test.py", line 38, in store_raw_data_in_hdfs
    with open(local_file, 'w') as f:
PermissionError: [Errno 13] Permission denied: '/mnt/hadoop_data/coingecko_raw.json'
[2025-02-24T17:20:27.870+0000] {taskinstance.py:1400} INFO - Marking task as UP_FOR_RETRY. dag_id=coingecko_ingestion_dag, task_id=store_raw_data_in_hdfs, execution_date=20250121T000000, start_date=20250224T172027, end_date=20250224T172027
[2025-02-24T17:20:27.913+0000] {standard_task_runner.py:104} ERROR - Failed to execute job 61 for task store_raw_data_in_hdfs ([Errno 13] Permission denied: '/mnt/hadoop_data/coingecko_raw.json'; 685)
[2025-02-24T17:20:27.963+0000] {local_task_job_runner.py:228} INFO - Task exited with return code 1
[2025-02-24T17:20:28.028+0000] {taskinstance.py:2784} INFO - 0 downstream tasks scheduled from follow-on schedule check
[2025-02-25T15:53:46.317+0000] {taskinstance.py:1159} INFO - Dependencies all met for dep_context=non-requeueable deps ti=<TaskInstance: coingecko_ingestion_dag.store_raw_data_in_hdfs scheduled__2025-01-21T00:00:00+00:00 [queued]>
[2025-02-25T15:53:46.397+0000] {taskinstance.py:1159} INFO - Dependencies all met for dep_context=requeueable deps ti=<TaskInstance: coingecko_ingestion_dag.store_raw_data_in_hdfs scheduled__2025-01-21T00:00:00+00:00 [queued]>
[2025-02-25T15:53:46.405+0000] {taskinstance.py:1361} INFO - Starting attempt 1 of 2
[2025-02-25T15:53:46.456+0000] {taskinstance.py:1382} INFO - Executing <Task(PythonOperator): store_raw_data_in_hdfs> on 2025-01-21 00:00:00+00:00
[2025-02-25T15:53:46.482+0000] {standard_task_runner.py:57} INFO - Started process 384 to run task
[2025-02-25T15:53:46.507+0000] {standard_task_runner.py:84} INFO - Running: ['***', 'tasks', 'run', 'coingecko_ingestion_dag', 'store_raw_data_in_hdfs', 'scheduled__2025-01-21T00:00:00+00:00', '--job-id', '66', '--raw', '--subdir', 'DAGS_FOLDER/pipeline.py', '--cfg-path', '/tmp/tmpfn01_gya']
[2025-02-25T15:53:46.522+0000] {standard_task_runner.py:85} INFO - Job 66: Subtask store_raw_data_in_hdfs
[2025-02-25T15:53:46.755+0000] {task_command.py:415} INFO - Running <TaskInstance: coingecko_ingestion_dag.store_raw_data_in_hdfs scheduled__2025-01-21T00:00:00+00:00 [running]> on host af9744bbb9eb
[2025-02-25T15:53:47.103+0000] {taskinstance.py:1660} INFO - Exporting env vars: AIRFLOW_CTX_DAG_OWNER='etudiant' AIRFLOW_CTX_DAG_ID='coingecko_ingestion_dag' AIRFLOW_CTX_TASK_ID='store_raw_data_in_hdfs' AIRFLOW_CTX_EXECUTION_DATE='2025-01-21T00:00:00+00:00' AIRFLOW_CTX_TRY_NUMBER='1' AIRFLOW_CTX_DAG_RUN_ID='scheduled__2025-01-21T00:00:00+00:00'
[2025-02-25T15:53:47.152+0000] {taskinstance.py:1943} ERROR - Task failed with exception
Traceback (most recent call last):
  File "/home/airflow/.local/lib/python3.8/site-packages/airflow/operators/python.py", line 192, in execute
    return_value = self.execute_callable()
  File "/home/airflow/.local/lib/python3.8/site-packages/airflow/operators/python.py", line 209, in execute_callable
    return self.python_callable(*self.op_args, **self.op_kwargs)
  File "/opt/airflow/dags/pipeline.py", line 39, in store_raw_data_in_hdfs
    with open(local_file, 'w') as f:
PermissionError: [Errno 13] Permission denied: '/mnt/hadoop_data/coingecko_raw.json'
[2025-02-25T15:53:47.218+0000] {taskinstance.py:1400} INFO - Marking task as UP_FOR_RETRY. dag_id=coingecko_ingestion_dag, task_id=store_raw_data_in_hdfs, execution_date=20250121T000000, start_date=20250225T155346, end_date=20250225T155347
[2025-02-25T15:53:47.281+0000] {standard_task_runner.py:104} ERROR - Failed to execute job 66 for task store_raw_data_in_hdfs ([Errno 13] Permission denied: '/mnt/hadoop_data/coingecko_raw.json'; 384)
[2025-02-25T15:53:47.324+0000] {local_task_job_runner.py:228} INFO - Task exited with return code 1
[2025-02-25T15:53:47.667+0000] {taskinstance.py:2784} INFO - 0 downstream tasks scheduled from follow-on schedule check
