[2025-02-24T17:20:12.364+0000] {taskinstance.py:1159} INFO - Dependencies all met for dep_context=non-requeueable deps ti=<TaskInstance: coingecko_ingestion_dag.store_raw_data_in_hdfs scheduled__2025-01-09T00:00:00+00:00 [queued]>
[2025-02-24T17:20:12.398+0000] {taskinstance.py:1159} INFO - Dependencies all met for dep_context=requeueable deps ti=<TaskInstance: coingecko_ingestion_dag.store_raw_data_in_hdfs scheduled__2025-01-09T00:00:00+00:00 [queued]>
[2025-02-24T17:20:12.399+0000] {taskinstance.py:1361} INFO - Starting attempt 2 of 2
[2025-02-24T17:20:12.423+0000] {taskinstance.py:1382} INFO - Executing <Task(PythonOperator): store_raw_data_in_hdfs> on 2025-01-09 00:00:00+00:00
[2025-02-24T17:20:12.435+0000] {standard_task_runner.py:57} INFO - Started process 644 to run task
[2025-02-24T17:20:12.444+0000] {standard_task_runner.py:84} INFO - Running: ['***', 'tasks', 'run', 'coingecko_ingestion_dag', 'store_raw_data_in_hdfs', 'scheduled__2025-01-09T00:00:00+00:00', '--job-id', '41', '--raw', '--subdir', 'DAGS_FOLDER/test.py', '--cfg-path', '/tmp/tmpfiw6jd4o']
[2025-02-24T17:20:12.450+0000] {standard_task_runner.py:85} INFO - Job 41: Subtask store_raw_data_in_hdfs
[2025-02-24T17:20:12.586+0000] {task_command.py:415} INFO - Running <TaskInstance: coingecko_ingestion_dag.store_raw_data_in_hdfs scheduled__2025-01-09T00:00:00+00:00 [running]> on host 85b967fd3989
[2025-02-24T17:20:12.805+0000] {taskinstance.py:1660} INFO - Exporting env vars: AIRFLOW_CTX_DAG_OWNER='etudiant' AIRFLOW_CTX_DAG_ID='coingecko_ingestion_dag' AIRFLOW_CTX_TASK_ID='store_raw_data_in_hdfs' AIRFLOW_CTX_EXECUTION_DATE='2025-01-09T00:00:00+00:00' AIRFLOW_CTX_TRY_NUMBER='2' AIRFLOW_CTX_DAG_RUN_ID='scheduled__2025-01-09T00:00:00+00:00'
[2025-02-24T17:20:12.830+0000] {taskinstance.py:1943} ERROR - Task failed with exception
Traceback (most recent call last):
  File "/home/airflow/.local/lib/python3.8/site-packages/airflow/operators/python.py", line 192, in execute
    return_value = self.execute_callable()
  File "/home/airflow/.local/lib/python3.8/site-packages/airflow/operators/python.py", line 209, in execute_callable
    return self.python_callable(*self.op_args, **self.op_kwargs)
  File "/opt/airflow/dags/test.py", line 38, in store_raw_data_in_hdfs
    with open(local_file, 'w') as f:
PermissionError: [Errno 13] Permission denied: '/mnt/hadoop_data/coingecko_raw.json'
[2025-02-24T17:20:12.848+0000] {taskinstance.py:1400} INFO - Marking task as FAILED. dag_id=coingecko_ingestion_dag, task_id=store_raw_data_in_hdfs, execution_date=20250109T000000, start_date=20250224T172012, end_date=20250224T172012
[2025-02-24T17:20:12.885+0000] {standard_task_runner.py:104} ERROR - Failed to execute job 41 for task store_raw_data_in_hdfs ([Errno 13] Permission denied: '/mnt/hadoop_data/coingecko_raw.json'; 644)
[2025-02-24T17:20:12.931+0000] {local_task_job_runner.py:228} INFO - Task exited with return code 1
[2025-02-24T17:20:13.154+0000] {taskinstance.py:2784} INFO - 0 downstream tasks scheduled from follow-on schedule check
[2025-02-25T15:52:55.590+0000] {taskinstance.py:1159} INFO - Dependencies all met for dep_context=non-requeueable deps ti=<TaskInstance: coingecko_ingestion_dag.store_raw_data_in_hdfs scheduled__2025-01-09T00:00:00+00:00 [queued]>
[2025-02-25T15:52:55.657+0000] {taskinstance.py:1159} INFO - Dependencies all met for dep_context=requeueable deps ti=<TaskInstance: coingecko_ingestion_dag.store_raw_data_in_hdfs scheduled__2025-01-09T00:00:00+00:00 [queued]>
[2025-02-25T15:52:55.668+0000] {taskinstance.py:1361} INFO - Starting attempt 2 of 2
[2025-02-25T15:52:55.798+0000] {taskinstance.py:1382} INFO - Executing <Task(PythonOperator): store_raw_data_in_hdfs> on 2025-01-09 00:00:00+00:00
[2025-02-25T15:52:55.854+0000] {standard_task_runner.py:57} INFO - Started process 328 to run task
[2025-02-25T15:52:55.872+0000] {standard_task_runner.py:84} INFO - Running: ['***', 'tasks', 'run', 'coingecko_ingestion_dag', 'store_raw_data_in_hdfs', 'scheduled__2025-01-09T00:00:00+00:00', '--job-id', '40', '--raw', '--subdir', 'DAGS_FOLDER/pipeline.py', '--cfg-path', '/tmp/tmpfqrmosis']
[2025-02-25T15:52:55.895+0000] {standard_task_runner.py:85} INFO - Job 40: Subtask store_raw_data_in_hdfs
[2025-02-25T15:52:56.202+0000] {task_command.py:415} INFO - Running <TaskInstance: coingecko_ingestion_dag.store_raw_data_in_hdfs scheduled__2025-01-09T00:00:00+00:00 [running]> on host af9744bbb9eb
[2025-02-25T15:52:56.602+0000] {taskinstance.py:1660} INFO - Exporting env vars: AIRFLOW_CTX_DAG_OWNER='etudiant' AIRFLOW_CTX_DAG_ID='coingecko_ingestion_dag' AIRFLOW_CTX_TASK_ID='store_raw_data_in_hdfs' AIRFLOW_CTX_EXECUTION_DATE='2025-01-09T00:00:00+00:00' AIRFLOW_CTX_TRY_NUMBER='2' AIRFLOW_CTX_DAG_RUN_ID='scheduled__2025-01-09T00:00:00+00:00'
[2025-02-25T15:52:56.659+0000] {taskinstance.py:1943} ERROR - Task failed with exception
Traceback (most recent call last):
  File "/home/airflow/.local/lib/python3.8/site-packages/airflow/operators/python.py", line 192, in execute
    return_value = self.execute_callable()
  File "/home/airflow/.local/lib/python3.8/site-packages/airflow/operators/python.py", line 209, in execute_callable
    return self.python_callable(*self.op_args, **self.op_kwargs)
  File "/opt/airflow/dags/pipeline.py", line 39, in store_raw_data_in_hdfs
    with open(local_file, 'w') as f:
PermissionError: [Errno 13] Permission denied: '/mnt/hadoop_data/coingecko_raw.json'
[2025-02-25T15:52:56.719+0000] {taskinstance.py:1400} INFO - Marking task as FAILED. dag_id=coingecko_ingestion_dag, task_id=store_raw_data_in_hdfs, execution_date=20250109T000000, start_date=20250225T155255, end_date=20250225T155256
[2025-02-25T15:52:56.774+0000] {standard_task_runner.py:104} ERROR - Failed to execute job 40 for task store_raw_data_in_hdfs ([Errno 13] Permission denied: '/mnt/hadoop_data/coingecko_raw.json'; 328)
[2025-02-25T15:52:56.869+0000] {local_task_job_runner.py:228} INFO - Task exited with return code 1
[2025-02-25T15:52:57.147+0000] {taskinstance.py:2784} INFO - 0 downstream tasks scheduled from follow-on schedule check
