[2025-02-24T17:30:53.252+0000] {taskinstance.py:1159} INFO - Dependencies all met for dep_context=non-requeueable deps ti=<TaskInstance: coingecko_ingestion_dag.store_raw_data_in_hdfs scheduled__2025-02-21T00:00:00+00:00 [queued]>
[2025-02-24T17:30:53.270+0000] {taskinstance.py:1159} INFO - Dependencies all met for dep_context=requeueable deps ti=<TaskInstance: coingecko_ingestion_dag.store_raw_data_in_hdfs scheduled__2025-02-21T00:00:00+00:00 [queued]>
[2025-02-24T17:30:53.272+0000] {taskinstance.py:1361} INFO - Starting attempt 1 of 2
[2025-02-24T17:30:53.304+0000] {taskinstance.py:1382} INFO - Executing <Task(PythonOperator): store_raw_data_in_hdfs> on 2025-02-21 00:00:00+00:00
[2025-02-24T17:30:53.317+0000] {standard_task_runner.py:57} INFO - Started process 1074 to run task
[2025-02-24T17:30:53.322+0000] {standard_task_runner.py:84} INFO - Running: ['***', 'tasks', 'run', 'coingecko_ingestion_dag', 'store_raw_data_in_hdfs', 'scheduled__2025-02-21T00:00:00+00:00', '--job-id', '153', '--raw', '--subdir', 'DAGS_FOLDER/pipeline.py', '--cfg-path', '/tmp/tmp42t6gekk']
[2025-02-24T17:30:53.330+0000] {standard_task_runner.py:85} INFO - Job 153: Subtask store_raw_data_in_hdfs
[2025-02-24T17:30:53.440+0000] {task_command.py:415} INFO - Running <TaskInstance: coingecko_ingestion_dag.store_raw_data_in_hdfs scheduled__2025-02-21T00:00:00+00:00 [running]> on host 85b967fd3989
[2025-02-24T17:30:53.590+0000] {taskinstance.py:1660} INFO - Exporting env vars: AIRFLOW_CTX_DAG_OWNER='etudiant' AIRFLOW_CTX_DAG_ID='coingecko_ingestion_dag' AIRFLOW_CTX_TASK_ID='store_raw_data_in_hdfs' AIRFLOW_CTX_EXECUTION_DATE='2025-02-21T00:00:00+00:00' AIRFLOW_CTX_TRY_NUMBER='1' AIRFLOW_CTX_DAG_RUN_ID='scheduled__2025-02-21T00:00:00+00:00'
[2025-02-24T17:30:53.623+0000] {taskinstance.py:1943} ERROR - Task failed with exception
Traceback (most recent call last):
  File "/home/airflow/.local/lib/python3.8/site-packages/airflow/operators/python.py", line 192, in execute
    return_value = self.execute_callable()
  File "/home/airflow/.local/lib/python3.8/site-packages/airflow/operators/python.py", line 209, in execute_callable
    return self.python_callable(*self.op_args, **self.op_kwargs)
  File "/opt/airflow/dags/pipeline.py", line 38, in store_raw_data_in_hdfs
    with open(local_file, 'w') as f:
PermissionError: [Errno 13] Permission denied: '/mnt/hadoop_data/coingecko_raw.json'
[2025-02-24T17:30:53.642+0000] {taskinstance.py:1400} INFO - Marking task as UP_FOR_RETRY. dag_id=coingecko_ingestion_dag, task_id=store_raw_data_in_hdfs, execution_date=20250221T000000, start_date=20250224T173053, end_date=20250224T173053
[2025-02-24T17:30:53.661+0000] {standard_task_runner.py:104} ERROR - Failed to execute job 153 for task store_raw_data_in_hdfs ([Errno 13] Permission denied: '/mnt/hadoop_data/coingecko_raw.json'; 1074)
[2025-02-24T17:30:53.674+0000] {local_task_job_runner.py:228} INFO - Task exited with return code 1
[2025-02-24T17:30:53.700+0000] {taskinstance.py:2784} INFO - 0 downstream tasks scheduled from follow-on schedule check
[2025-02-25T16:04:37.631+0000] {taskinstance.py:1159} INFO - Dependencies all met for dep_context=non-requeueable deps ti=<TaskInstance: coingecko_ingestion_dag.store_raw_data_in_hdfs scheduled__2025-02-21T00:00:00+00:00 [queued]>
[2025-02-25T16:04:37.644+0000] {taskinstance.py:1159} INFO - Dependencies all met for dep_context=requeueable deps ti=<TaskInstance: coingecko_ingestion_dag.store_raw_data_in_hdfs scheduled__2025-02-21T00:00:00+00:00 [queued]>
[2025-02-25T16:04:37.644+0000] {taskinstance.py:1361} INFO - Starting attempt 1 of 2
[2025-02-25T16:04:37.663+0000] {taskinstance.py:1382} INFO - Executing <Task(PythonOperator): store_raw_data_in_hdfs> on 2025-02-21 00:00:00+00:00
[2025-02-25T16:04:37.672+0000] {standard_task_runner.py:57} INFO - Started process 668 to run task
[2025-02-25T16:04:37.678+0000] {standard_task_runner.py:84} INFO - Running: ['***', 'tasks', 'run', 'coingecko_ingestion_dag', 'store_raw_data_in_hdfs', 'scheduled__2025-02-21T00:00:00+00:00', '--job-id', '159', '--raw', '--subdir', 'DAGS_FOLDER/pipeline.py', '--cfg-path', '/tmp/tmp79o8zymd']
[2025-02-25T16:04:37.685+0000] {standard_task_runner.py:85} INFO - Job 159: Subtask store_raw_data_in_hdfs
[2025-02-25T16:04:37.769+0000] {task_command.py:415} INFO - Running <TaskInstance: coingecko_ingestion_dag.store_raw_data_in_hdfs scheduled__2025-02-21T00:00:00+00:00 [running]> on host af9744bbb9eb
[2025-02-25T16:04:37.893+0000] {taskinstance.py:1660} INFO - Exporting env vars: AIRFLOW_CTX_DAG_OWNER='etudiant' AIRFLOW_CTX_DAG_ID='coingecko_ingestion_dag' AIRFLOW_CTX_TASK_ID='store_raw_data_in_hdfs' AIRFLOW_CTX_EXECUTION_DATE='2025-02-21T00:00:00+00:00' AIRFLOW_CTX_TRY_NUMBER='1' AIRFLOW_CTX_DAG_RUN_ID='scheduled__2025-02-21T00:00:00+00:00'
[2025-02-25T16:04:37.921+0000] {taskinstance.py:1943} ERROR - Task failed with exception
Traceback (most recent call last):
  File "/home/airflow/.local/lib/python3.8/site-packages/airflow/operators/python.py", line 192, in execute
    return_value = self.execute_callable()
  File "/home/airflow/.local/lib/python3.8/site-packages/airflow/operators/python.py", line 209, in execute_callable
    return self.python_callable(*self.op_args, **self.op_kwargs)
  File "/opt/airflow/dags/pipeline.py", line 39, in store_raw_data_in_hdfs
    with open(local_file, 'w') as f:
PermissionError: [Errno 13] Permission denied: '/mnt/hadoop_data/coingecko_raw.json'
[2025-02-25T16:04:37.934+0000] {taskinstance.py:1400} INFO - Marking task as UP_FOR_RETRY. dag_id=coingecko_ingestion_dag, task_id=store_raw_data_in_hdfs, execution_date=20250221T000000, start_date=20250225T160437, end_date=20250225T160437
[2025-02-25T16:04:37.950+0000] {standard_task_runner.py:104} ERROR - Failed to execute job 159 for task store_raw_data_in_hdfs ([Errno 13] Permission denied: '/mnt/hadoop_data/coingecko_raw.json'; 668)
[2025-02-25T16:04:37.980+0000] {local_task_job_runner.py:228} INFO - Task exited with return code 1
[2025-02-25T16:04:38.004+0000] {taskinstance.py:2784} INFO - 0 downstream tasks scheduled from follow-on schedule check
