[2025-02-24T17:25:42.873+0000] {taskinstance.py:1159} INFO - Dependencies all met for dep_context=non-requeueable deps ti=<TaskInstance: coingecko_ingestion_dag.store_raw_data_in_hdfs scheduled__2025-02-17T00:00:00+00:00 [queued]>
[2025-02-24T17:25:42.888+0000] {taskinstance.py:1159} INFO - Dependencies all met for dep_context=requeueable deps ti=<TaskInstance: coingecko_ingestion_dag.store_raw_data_in_hdfs scheduled__2025-02-17T00:00:00+00:00 [queued]>
[2025-02-24T17:25:42.890+0000] {taskinstance.py:1361} INFO - Starting attempt 1 of 2
[2025-02-24T17:25:42.915+0000] {taskinstance.py:1382} INFO - Executing <Task(PythonOperator): store_raw_data_in_hdfs> on 2025-02-17 00:00:00+00:00
[2025-02-24T17:25:42.924+0000] {standard_task_runner.py:57} INFO - Started process 921 to run task
[2025-02-24T17:25:42.929+0000] {standard_task_runner.py:84} INFO - Running: ['***', 'tasks', 'run', 'coingecko_ingestion_dag', 'store_raw_data_in_hdfs', 'scheduled__2025-02-17T00:00:00+00:00', '--job-id', '128', '--raw', '--subdir', 'DAGS_FOLDER/pipeline.py', '--cfg-path', '/tmp/tmpwcbv92o9']
[2025-02-24T17:25:42.932+0000] {standard_task_runner.py:85} INFO - Job 128: Subtask store_raw_data_in_hdfs
[2025-02-24T17:25:42.994+0000] {task_command.py:415} INFO - Running <TaskInstance: coingecko_ingestion_dag.store_raw_data_in_hdfs scheduled__2025-02-17T00:00:00+00:00 [running]> on host 85b967fd3989
[2025-02-24T17:25:43.095+0000] {taskinstance.py:1660} INFO - Exporting env vars: AIRFLOW_CTX_DAG_OWNER='etudiant' AIRFLOW_CTX_DAG_ID='coingecko_ingestion_dag' AIRFLOW_CTX_TASK_ID='store_raw_data_in_hdfs' AIRFLOW_CTX_EXECUTION_DATE='2025-02-17T00:00:00+00:00' AIRFLOW_CTX_TRY_NUMBER='1' AIRFLOW_CTX_DAG_RUN_ID='scheduled__2025-02-17T00:00:00+00:00'
[2025-02-24T17:25:43.116+0000] {taskinstance.py:1943} ERROR - Task failed with exception
Traceback (most recent call last):
  File "/home/airflow/.local/lib/python3.8/site-packages/airflow/operators/python.py", line 192, in execute
    return_value = self.execute_callable()
  File "/home/airflow/.local/lib/python3.8/site-packages/airflow/operators/python.py", line 209, in execute_callable
    return self.python_callable(*self.op_args, **self.op_kwargs)
  File "/opt/airflow/dags/pipeline.py", line 38, in store_raw_data_in_hdfs
    with open(local_file, 'w') as f:
PermissionError: [Errno 13] Permission denied: '/mnt/hadoop_data/coingecko_raw.json'
[2025-02-24T17:25:43.134+0000] {taskinstance.py:1400} INFO - Marking task as UP_FOR_RETRY. dag_id=coingecko_ingestion_dag, task_id=store_raw_data_in_hdfs, execution_date=20250217T000000, start_date=20250224T172542, end_date=20250224T172543
[2025-02-24T17:25:43.155+0000] {standard_task_runner.py:104} ERROR - Failed to execute job 128 for task store_raw_data_in_hdfs ([Errno 13] Permission denied: '/mnt/hadoop_data/coingecko_raw.json'; 921)
[2025-02-24T17:25:43.193+0000] {local_task_job_runner.py:228} INFO - Task exited with return code 1
[2025-02-24T17:25:43.219+0000] {taskinstance.py:2784} INFO - 0 downstream tasks scheduled from follow-on schedule check
[2025-02-25T16:04:06.170+0000] {taskinstance.py:1159} INFO - Dependencies all met for dep_context=non-requeueable deps ti=<TaskInstance: coingecko_ingestion_dag.store_raw_data_in_hdfs scheduled__2025-02-17T00:00:00+00:00 [queued]>
[2025-02-25T16:04:06.178+0000] {taskinstance.py:1159} INFO - Dependencies all met for dep_context=requeueable deps ti=<TaskInstance: coingecko_ingestion_dag.store_raw_data_in_hdfs scheduled__2025-02-17T00:00:00+00:00 [queued]>
[2025-02-25T16:04:06.179+0000] {taskinstance.py:1361} INFO - Starting attempt 1 of 2
[2025-02-25T16:04:06.190+0000] {taskinstance.py:1382} INFO - Executing <Task(PythonOperator): store_raw_data_in_hdfs> on 2025-02-17 00:00:00+00:00
[2025-02-25T16:04:06.194+0000] {standard_task_runner.py:57} INFO - Started process 611 to run task
[2025-02-25T16:04:06.198+0000] {standard_task_runner.py:84} INFO - Running: ['***', 'tasks', 'run', 'coingecko_ingestion_dag', 'store_raw_data_in_hdfs', 'scheduled__2025-02-17T00:00:00+00:00', '--job-id', '134', '--raw', '--subdir', 'DAGS_FOLDER/pipeline.py', '--cfg-path', '/tmp/tmpf491uo12']
[2025-02-25T16:04:06.201+0000] {standard_task_runner.py:85} INFO - Job 134: Subtask store_raw_data_in_hdfs
[2025-02-25T16:04:06.245+0000] {task_command.py:415} INFO - Running <TaskInstance: coingecko_ingestion_dag.store_raw_data_in_hdfs scheduled__2025-02-17T00:00:00+00:00 [running]> on host af9744bbb9eb
[2025-02-25T16:04:06.313+0000] {taskinstance.py:1660} INFO - Exporting env vars: AIRFLOW_CTX_DAG_OWNER='etudiant' AIRFLOW_CTX_DAG_ID='coingecko_ingestion_dag' AIRFLOW_CTX_TASK_ID='store_raw_data_in_hdfs' AIRFLOW_CTX_EXECUTION_DATE='2025-02-17T00:00:00+00:00' AIRFLOW_CTX_TRY_NUMBER='1' AIRFLOW_CTX_DAG_RUN_ID='scheduled__2025-02-17T00:00:00+00:00'
[2025-02-25T16:04:06.329+0000] {taskinstance.py:1943} ERROR - Task failed with exception
Traceback (most recent call last):
  File "/home/airflow/.local/lib/python3.8/site-packages/airflow/operators/python.py", line 192, in execute
    return_value = self.execute_callable()
  File "/home/airflow/.local/lib/python3.8/site-packages/airflow/operators/python.py", line 209, in execute_callable
    return self.python_callable(*self.op_args, **self.op_kwargs)
  File "/opt/airflow/dags/pipeline.py", line 39, in store_raw_data_in_hdfs
    with open(local_file, 'w') as f:
PermissionError: [Errno 13] Permission denied: '/mnt/hadoop_data/coingecko_raw.json'
[2025-02-25T16:04:06.337+0000] {taskinstance.py:1400} INFO - Marking task as UP_FOR_RETRY. dag_id=coingecko_ingestion_dag, task_id=store_raw_data_in_hdfs, execution_date=20250217T000000, start_date=20250225T160406, end_date=20250225T160406
[2025-02-25T16:04:06.347+0000] {standard_task_runner.py:104} ERROR - Failed to execute job 134 for task store_raw_data_in_hdfs ([Errno 13] Permission denied: '/mnt/hadoop_data/coingecko_raw.json'; 611)
[2025-02-25T16:04:06.376+0000] {local_task_job_runner.py:228} INFO - Task exited with return code 1
[2025-02-25T16:04:06.391+0000] {taskinstance.py:2784} INFO - 0 downstream tasks scheduled from follow-on schedule check
