[2025-02-24T17:20:12.610+0000] {taskinstance.py:1159} INFO - Dependencies all met for dep_context=non-requeueable deps ti=<TaskInstance: coingecko_ingestion_dag.store_raw_data_in_hdfs scheduled__2025-01-04T00:00:00+00:00 [queued]>
[2025-02-24T17:20:12.635+0000] {taskinstance.py:1159} INFO - Dependencies all met for dep_context=requeueable deps ti=<TaskInstance: coingecko_ingestion_dag.store_raw_data_in_hdfs scheduled__2025-01-04T00:00:00+00:00 [queued]>
[2025-02-24T17:20:12.636+0000] {taskinstance.py:1361} INFO - Starting attempt 2 of 2
[2025-02-24T17:20:12.700+0000] {taskinstance.py:1382} INFO - Executing <Task(PythonOperator): store_raw_data_in_hdfs> on 2025-01-04 00:00:00+00:00
[2025-02-24T17:20:12.712+0000] {standard_task_runner.py:57} INFO - Started process 648 to run task
[2025-02-24T17:20:12.721+0000] {standard_task_runner.py:84} INFO - Running: ['***', 'tasks', 'run', 'coingecko_ingestion_dag', 'store_raw_data_in_hdfs', 'scheduled__2025-01-04T00:00:00+00:00', '--job-id', '45', '--raw', '--subdir', 'DAGS_FOLDER/test.py', '--cfg-path', '/tmp/tmpcyu5x23s']
[2025-02-24T17:20:12.734+0000] {standard_task_runner.py:85} INFO - Job 45: Subtask store_raw_data_in_hdfs
[2025-02-24T17:20:12.822+0000] {task_command.py:415} INFO - Running <TaskInstance: coingecko_ingestion_dag.store_raw_data_in_hdfs scheduled__2025-01-04T00:00:00+00:00 [running]> on host 85b967fd3989
[2025-02-24T17:20:12.974+0000] {taskinstance.py:1660} INFO - Exporting env vars: AIRFLOW_CTX_DAG_OWNER='etudiant' AIRFLOW_CTX_DAG_ID='coingecko_ingestion_dag' AIRFLOW_CTX_TASK_ID='store_raw_data_in_hdfs' AIRFLOW_CTX_EXECUTION_DATE='2025-01-04T00:00:00+00:00' AIRFLOW_CTX_TRY_NUMBER='2' AIRFLOW_CTX_DAG_RUN_ID='scheduled__2025-01-04T00:00:00+00:00'
[2025-02-24T17:20:12.995+0000] {taskinstance.py:1943} ERROR - Task failed with exception
Traceback (most recent call last):
  File "/home/airflow/.local/lib/python3.8/site-packages/airflow/operators/python.py", line 192, in execute
    return_value = self.execute_callable()
  File "/home/airflow/.local/lib/python3.8/site-packages/airflow/operators/python.py", line 209, in execute_callable
    return self.python_callable(*self.op_args, **self.op_kwargs)
  File "/opt/airflow/dags/test.py", line 38, in store_raw_data_in_hdfs
    with open(local_file, 'w') as f:
PermissionError: [Errno 13] Permission denied: '/mnt/hadoop_data/coingecko_raw.json'
[2025-02-24T17:20:13.015+0000] {taskinstance.py:1400} INFO - Marking task as FAILED. dag_id=coingecko_ingestion_dag, task_id=store_raw_data_in_hdfs, execution_date=20250104T000000, start_date=20250224T172012, end_date=20250224T172013
[2025-02-24T17:20:13.035+0000] {standard_task_runner.py:104} ERROR - Failed to execute job 45 for task store_raw_data_in_hdfs ([Errno 13] Permission denied: '/mnt/hadoop_data/coingecko_raw.json'; 648)
[2025-02-24T17:20:13.064+0000] {local_task_job_runner.py:228} INFO - Task exited with return code 1
[2025-02-24T17:20:13.152+0000] {taskinstance.py:2784} INFO - 0 downstream tasks scheduled from follow-on schedule check
[2025-02-25T15:52:52.127+0000] {taskinstance.py:1159} INFO - Dependencies all met for dep_context=non-requeueable deps ti=<TaskInstance: coingecko_ingestion_dag.store_raw_data_in_hdfs scheduled__2025-01-04T00:00:00+00:00 [queued]>
[2025-02-25T15:52:52.157+0000] {taskinstance.py:1159} INFO - Dependencies all met for dep_context=requeueable deps ti=<TaskInstance: coingecko_ingestion_dag.store_raw_data_in_hdfs scheduled__2025-01-04T00:00:00+00:00 [queued]>
[2025-02-25T15:52:52.159+0000] {taskinstance.py:1361} INFO - Starting attempt 2 of 2
[2025-02-25T15:52:52.201+0000] {taskinstance.py:1382} INFO - Executing <Task(PythonOperator): store_raw_data_in_hdfs> on 2025-01-04 00:00:00+00:00
[2025-02-25T15:52:52.214+0000] {standard_task_runner.py:57} INFO - Started process 313 to run task
[2025-02-25T15:52:52.226+0000] {standard_task_runner.py:84} INFO - Running: ['***', 'tasks', 'run', 'coingecko_ingestion_dag', 'store_raw_data_in_hdfs', 'scheduled__2025-01-04T00:00:00+00:00', '--job-id', '36', '--raw', '--subdir', 'DAGS_FOLDER/pipeline.py', '--cfg-path', '/tmp/tmpjk2i3k87']
[2025-02-25T15:52:52.238+0000] {standard_task_runner.py:85} INFO - Job 36: Subtask store_raw_data_in_hdfs
[2025-02-25T15:52:52.361+0000] {task_command.py:415} INFO - Running <TaskInstance: coingecko_ingestion_dag.store_raw_data_in_hdfs scheduled__2025-01-04T00:00:00+00:00 [running]> on host af9744bbb9eb
[2025-02-25T15:52:52.575+0000] {taskinstance.py:1660} INFO - Exporting env vars: AIRFLOW_CTX_DAG_OWNER='etudiant' AIRFLOW_CTX_DAG_ID='coingecko_ingestion_dag' AIRFLOW_CTX_TASK_ID='store_raw_data_in_hdfs' AIRFLOW_CTX_EXECUTION_DATE='2025-01-04T00:00:00+00:00' AIRFLOW_CTX_TRY_NUMBER='2' AIRFLOW_CTX_DAG_RUN_ID='scheduled__2025-01-04T00:00:00+00:00'
[2025-02-25T15:52:52.613+0000] {taskinstance.py:1943} ERROR - Task failed with exception
Traceback (most recent call last):
  File "/home/airflow/.local/lib/python3.8/site-packages/airflow/operators/python.py", line 192, in execute
    return_value = self.execute_callable()
  File "/home/airflow/.local/lib/python3.8/site-packages/airflow/operators/python.py", line 209, in execute_callable
    return self.python_callable(*self.op_args, **self.op_kwargs)
  File "/opt/airflow/dags/pipeline.py", line 39, in store_raw_data_in_hdfs
    with open(local_file, 'w') as f:
PermissionError: [Errno 13] Permission denied: '/mnt/hadoop_data/coingecko_raw.json'
[2025-02-25T15:52:52.641+0000] {taskinstance.py:1400} INFO - Marking task as FAILED. dag_id=coingecko_ingestion_dag, task_id=store_raw_data_in_hdfs, execution_date=20250104T000000, start_date=20250225T155252, end_date=20250225T155252
[2025-02-25T15:52:52.673+0000] {standard_task_runner.py:104} ERROR - Failed to execute job 36 for task store_raw_data_in_hdfs ([Errno 13] Permission denied: '/mnt/hadoop_data/coingecko_raw.json'; 313)
[2025-02-25T15:52:52.738+0000] {local_task_job_runner.py:228} INFO - Task exited with return code 1
[2025-02-25T15:52:53.086+0000] {taskinstance.py:2784} INFO - 0 downstream tasks scheduled from follow-on schedule check
