[2025-02-24T17:15:09.390+0000] {taskinstance.py:1159} INFO - Dependencies all met for dep_context=non-requeueable deps ti=<TaskInstance: coingecko_ingestion_dag.store_raw_data_in_hdfs scheduled__2025-01-08T00:00:00+00:00 [queued]>
[2025-02-24T17:15:09.465+0000] {taskinstance.py:1159} INFO - Dependencies all met for dep_context=requeueable deps ti=<TaskInstance: coingecko_ingestion_dag.store_raw_data_in_hdfs scheduled__2025-01-08T00:00:00+00:00 [queued]>
[2025-02-24T17:15:09.468+0000] {taskinstance.py:1361} INFO - Starting attempt 1 of 2
[2025-02-24T17:15:09.554+0000] {taskinstance.py:1382} INFO - Executing <Task(PythonOperator): store_raw_data_in_hdfs> on 2025-01-08 00:00:00+00:00
[2025-02-24T17:15:09.589+0000] {standard_task_runner.py:57} INFO - Started process 509 to run task
[2025-02-24T17:15:09.602+0000] {standard_task_runner.py:84} INFO - Running: ['***', 'tasks', 'run', 'coingecko_ingestion_dag', 'store_raw_data_in_hdfs', 'scheduled__2025-01-08T00:00:00+00:00', '--job-id', '25', '--raw', '--subdir', 'DAGS_FOLDER/pipeline.py', '--cfg-path', '/tmp/tmpmkioj63y']
[2025-02-24T17:15:09.617+0000] {standard_task_runner.py:85} INFO - Job 25: Subtask store_raw_data_in_hdfs
[2025-02-24T17:15:09.929+0000] {task_command.py:415} INFO - Running <TaskInstance: coingecko_ingestion_dag.store_raw_data_in_hdfs scheduled__2025-01-08T00:00:00+00:00 [running]> on host 85b967fd3989
[2025-02-24T17:15:10.459+0000] {taskinstance.py:1660} INFO - Exporting env vars: AIRFLOW_CTX_DAG_OWNER='etudiant' AIRFLOW_CTX_DAG_ID='coingecko_ingestion_dag' AIRFLOW_CTX_TASK_ID='store_raw_data_in_hdfs' AIRFLOW_CTX_EXECUTION_DATE='2025-01-08T00:00:00+00:00' AIRFLOW_CTX_TRY_NUMBER='1' AIRFLOW_CTX_DAG_RUN_ID='scheduled__2025-01-08T00:00:00+00:00'
[2025-02-24T17:15:10.538+0000] {taskinstance.py:1943} ERROR - Task failed with exception
Traceback (most recent call last):
  File "/home/airflow/.local/lib/python3.8/site-packages/airflow/operators/python.py", line 192, in execute
    return_value = self.execute_callable()
  File "/home/airflow/.local/lib/python3.8/site-packages/airflow/operators/python.py", line 209, in execute_callable
    return self.python_callable(*self.op_args, **self.op_kwargs)
  File "/opt/airflow/dags/pipeline.py", line 38, in store_raw_data_in_hdfs
    with open(local_file, 'w') as f:
PermissionError: [Errno 13] Permission denied: '/mnt/hadoop_data/coingecko_raw.json'
[2025-02-24T17:15:10.575+0000] {taskinstance.py:1400} INFO - Marking task as UP_FOR_RETRY. dag_id=coingecko_ingestion_dag, task_id=store_raw_data_in_hdfs, execution_date=20250108T000000, start_date=20250224T171509, end_date=20250224T171510
[2025-02-24T17:15:10.731+0000] {standard_task_runner.py:104} ERROR - Failed to execute job 25 for task store_raw_data_in_hdfs ([Errno 13] Permission denied: '/mnt/hadoop_data/coingecko_raw.json'; 509)
[2025-02-24T17:15:10.772+0000] {local_task_job_runner.py:228} INFO - Task exited with return code 1
[2025-02-24T17:15:10.828+0000] {taskinstance.py:2784} INFO - 0 downstream tasks scheduled from follow-on schedule check
[2025-02-25T15:47:49.014+0000] {taskinstance.py:1159} INFO - Dependencies all met for dep_context=non-requeueable deps ti=<TaskInstance: coingecko_ingestion_dag.store_raw_data_in_hdfs scheduled__2025-01-08T00:00:00+00:00 [queued]>
[2025-02-25T15:47:49.145+0000] {taskinstance.py:1159} INFO - Dependencies all met for dep_context=requeueable deps ti=<TaskInstance: coingecko_ingestion_dag.store_raw_data_in_hdfs scheduled__2025-01-08T00:00:00+00:00 [queued]>
[2025-02-25T15:47:49.152+0000] {taskinstance.py:1361} INFO - Starting attempt 1 of 2
[2025-02-25T15:47:49.322+0000] {taskinstance.py:1382} INFO - Executing <Task(PythonOperator): store_raw_data_in_hdfs> on 2025-01-08 00:00:00+00:00
[2025-02-25T15:47:49.354+0000] {standard_task_runner.py:57} INFO - Started process 241 to run task
[2025-02-25T15:47:49.359+0000] {standard_task_runner.py:84} INFO - Running: ['***', 'tasks', 'run', 'coingecko_ingestion_dag', 'store_raw_data_in_hdfs', 'scheduled__2025-01-08T00:00:00+00:00', '--job-id', '21', '--raw', '--subdir', 'DAGS_FOLDER/pipeline.py', '--cfg-path', '/tmp/tmp6cfxuq0h']
[2025-02-25T15:47:49.380+0000] {standard_task_runner.py:85} INFO - Job 21: Subtask store_raw_data_in_hdfs
[2025-02-25T15:47:49.855+0000] {task_command.py:415} INFO - Running <TaskInstance: coingecko_ingestion_dag.store_raw_data_in_hdfs scheduled__2025-01-08T00:00:00+00:00 [running]> on host af9744bbb9eb
[2025-02-25T15:47:50.772+0000] {taskinstance.py:1660} INFO - Exporting env vars: AIRFLOW_CTX_DAG_OWNER='etudiant' AIRFLOW_CTX_DAG_ID='coingecko_ingestion_dag' AIRFLOW_CTX_TASK_ID='store_raw_data_in_hdfs' AIRFLOW_CTX_EXECUTION_DATE='2025-01-08T00:00:00+00:00' AIRFLOW_CTX_TRY_NUMBER='1' AIRFLOW_CTX_DAG_RUN_ID='scheduled__2025-01-08T00:00:00+00:00'
[2025-02-25T15:47:50.886+0000] {taskinstance.py:1943} ERROR - Task failed with exception
Traceback (most recent call last):
  File "/home/airflow/.local/lib/python3.8/site-packages/airflow/operators/python.py", line 192, in execute
    return_value = self.execute_callable()
  File "/home/airflow/.local/lib/python3.8/site-packages/airflow/operators/python.py", line 209, in execute_callable
    return self.python_callable(*self.op_args, **self.op_kwargs)
  File "/opt/airflow/dags/pipeline.py", line 39, in store_raw_data_in_hdfs
    with open(local_file, 'w') as f:
PermissionError: [Errno 13] Permission denied: '/mnt/hadoop_data/coingecko_raw.json'
[2025-02-25T15:47:50.945+0000] {taskinstance.py:1400} INFO - Marking task as UP_FOR_RETRY. dag_id=coingecko_ingestion_dag, task_id=store_raw_data_in_hdfs, execution_date=20250108T000000, start_date=20250225T154749, end_date=20250225T154750
[2025-02-25T15:47:51.064+0000] {standard_task_runner.py:104} ERROR - Failed to execute job 21 for task store_raw_data_in_hdfs ([Errno 13] Permission denied: '/mnt/hadoop_data/coingecko_raw.json'; 241)
[2025-02-25T15:47:51.153+0000] {local_task_job_runner.py:228} INFO - Task exited with return code 1
[2025-02-25T15:47:51.802+0000] {taskinstance.py:2784} INFO - 0 downstream tasks scheduled from follow-on schedule check
