[2025-02-24T17:25:30.553+0000] {taskinstance.py:1159} INFO - Dependencies all met for dep_context=non-requeueable deps ti=<TaskInstance: coingecko_ingestion_dag.store_raw_data_in_hdfs scheduled__2025-01-19T00:00:00+00:00 [queued]>
[2025-02-24T17:25:30.629+0000] {taskinstance.py:1159} INFO - Dependencies all met for dep_context=requeueable deps ti=<TaskInstance: coingecko_ingestion_dag.store_raw_data_in_hdfs scheduled__2025-01-19T00:00:00+00:00 [queued]>
[2025-02-24T17:25:30.635+0000] {taskinstance.py:1361} INFO - Starting attempt 2 of 2
[2025-02-24T17:25:30.799+0000] {taskinstance.py:1382} INFO - Executing <Task(PythonOperator): store_raw_data_in_hdfs> on 2025-01-19 00:00:00+00:00
[2025-02-24T17:25:30.848+0000] {standard_task_runner.py:57} INFO - Started process 834 to run task
[2025-02-24T17:25:30.879+0000] {standard_task_runner.py:84} INFO - Running: ['***', 'tasks', 'run', 'coingecko_ingestion_dag', 'store_raw_data_in_hdfs', 'scheduled__2025-01-19T00:00:00+00:00', '--job-id', '86', '--raw', '--subdir', 'DAGS_FOLDER/test.py', '--cfg-path', '/tmp/tmpyp4sczpz']
[2025-02-24T17:25:30.885+0000] {standard_task_runner.py:85} INFO - Job 86: Subtask store_raw_data_in_hdfs
[2025-02-24T17:25:31.141+0000] {task_command.py:415} INFO - Running <TaskInstance: coingecko_ingestion_dag.store_raw_data_in_hdfs scheduled__2025-01-19T00:00:00+00:00 [running]> on host 85b967fd3989
[2025-02-24T17:25:31.416+0000] {taskinstance.py:1660} INFO - Exporting env vars: AIRFLOW_CTX_DAG_OWNER='etudiant' AIRFLOW_CTX_DAG_ID='coingecko_ingestion_dag' AIRFLOW_CTX_TASK_ID='store_raw_data_in_hdfs' AIRFLOW_CTX_EXECUTION_DATE='2025-01-19T00:00:00+00:00' AIRFLOW_CTX_TRY_NUMBER='2' AIRFLOW_CTX_DAG_RUN_ID='scheduled__2025-01-19T00:00:00+00:00'
[2025-02-24T17:25:31.480+0000] {taskinstance.py:1943} ERROR - Task failed with exception
Traceback (most recent call last):
  File "/home/airflow/.local/lib/python3.8/site-packages/airflow/operators/python.py", line 192, in execute
    return_value = self.execute_callable()
  File "/home/airflow/.local/lib/python3.8/site-packages/airflow/operators/python.py", line 209, in execute_callable
    return self.python_callable(*self.op_args, **self.op_kwargs)
  File "/opt/airflow/dags/test.py", line 38, in store_raw_data_in_hdfs
    with open(local_file, 'w') as f:
PermissionError: [Errno 13] Permission denied: '/mnt/hadoop_data/coingecko_raw.json'
[2025-02-24T17:25:31.508+0000] {taskinstance.py:1400} INFO - Marking task as FAILED. dag_id=coingecko_ingestion_dag, task_id=store_raw_data_in_hdfs, execution_date=20250119T000000, start_date=20250224T172530, end_date=20250224T172531
[2025-02-24T17:25:31.574+0000] {standard_task_runner.py:104} ERROR - Failed to execute job 86 for task store_raw_data_in_hdfs ([Errno 13] Permission denied: '/mnt/hadoop_data/coingecko_raw.json'; 834)
[2025-02-24T17:25:31.599+0000] {local_task_job_runner.py:228} INFO - Task exited with return code 1
[2025-02-24T17:25:31.689+0000] {taskinstance.py:2784} INFO - 0 downstream tasks scheduled from follow-on schedule check
[2025-02-25T15:58:47.094+0000] {taskinstance.py:1159} INFO - Dependencies all met for dep_context=non-requeueable deps ti=<TaskInstance: coingecko_ingestion_dag.store_raw_data_in_hdfs scheduled__2025-01-19T00:00:00+00:00 [queued]>
[2025-02-25T15:58:47.105+0000] {taskinstance.py:1159} INFO - Dependencies all met for dep_context=requeueable deps ti=<TaskInstance: coingecko_ingestion_dag.store_raw_data_in_hdfs scheduled__2025-01-19T00:00:00+00:00 [queued]>
[2025-02-25T15:58:47.105+0000] {taskinstance.py:1361} INFO - Starting attempt 2 of 2
[2025-02-25T15:58:47.117+0000] {taskinstance.py:1382} INFO - Executing <Task(PythonOperator): store_raw_data_in_hdfs> on 2025-01-19 00:00:00+00:00
[2025-02-25T15:58:47.121+0000] {standard_task_runner.py:57} INFO - Started process 459 to run task
[2025-02-25T15:58:47.124+0000] {standard_task_runner.py:84} INFO - Running: ['***', 'tasks', 'run', 'coingecko_ingestion_dag', 'store_raw_data_in_hdfs', 'scheduled__2025-01-19T00:00:00+00:00', '--job-id', '85', '--raw', '--subdir', 'DAGS_FOLDER/pipeline.py', '--cfg-path', '/tmp/tmp29kkihx_']
[2025-02-25T15:58:47.127+0000] {standard_task_runner.py:85} INFO - Job 85: Subtask store_raw_data_in_hdfs
[2025-02-25T15:58:47.174+0000] {task_command.py:415} INFO - Running <TaskInstance: coingecko_ingestion_dag.store_raw_data_in_hdfs scheduled__2025-01-19T00:00:00+00:00 [running]> on host af9744bbb9eb
[2025-02-25T15:58:47.243+0000] {taskinstance.py:1660} INFO - Exporting env vars: AIRFLOW_CTX_DAG_OWNER='etudiant' AIRFLOW_CTX_DAG_ID='coingecko_ingestion_dag' AIRFLOW_CTX_TASK_ID='store_raw_data_in_hdfs' AIRFLOW_CTX_EXECUTION_DATE='2025-01-19T00:00:00+00:00' AIRFLOW_CTX_TRY_NUMBER='2' AIRFLOW_CTX_DAG_RUN_ID='scheduled__2025-01-19T00:00:00+00:00'
[2025-02-25T15:58:47.258+0000] {taskinstance.py:1943} ERROR - Task failed with exception
Traceback (most recent call last):
  File "/home/airflow/.local/lib/python3.8/site-packages/airflow/operators/python.py", line 192, in execute
    return_value = self.execute_callable()
  File "/home/airflow/.local/lib/python3.8/site-packages/airflow/operators/python.py", line 209, in execute_callable
    return self.python_callable(*self.op_args, **self.op_kwargs)
  File "/opt/airflow/dags/pipeline.py", line 39, in store_raw_data_in_hdfs
    with open(local_file, 'w') as f:
PermissionError: [Errno 13] Permission denied: '/mnt/hadoop_data/coingecko_raw.json'
[2025-02-25T15:58:47.265+0000] {taskinstance.py:1400} INFO - Marking task as FAILED. dag_id=coingecko_ingestion_dag, task_id=store_raw_data_in_hdfs, execution_date=20250119T000000, start_date=20250225T155847, end_date=20250225T155847
[2025-02-25T15:58:47.275+0000] {standard_task_runner.py:104} ERROR - Failed to execute job 85 for task store_raw_data_in_hdfs ([Errno 13] Permission denied: '/mnt/hadoop_data/coingecko_raw.json'; 459)
[2025-02-25T15:58:47.303+0000] {local_task_job_runner.py:228} INFO - Task exited with return code 1
[2025-02-25T15:58:47.315+0000] {taskinstance.py:2784} INFO - 0 downstream tasks scheduled from follow-on schedule check
