[2025-02-24T17:20:11.671+0000] {taskinstance.py:1159} INFO - Dependencies all met for dep_context=non-requeueable deps ti=<TaskInstance: coingecko_ingestion_dag.store_raw_data_in_hdfs scheduled__2025-01-15T00:00:00+00:00 [queued]>
[2025-02-24T17:20:11.713+0000] {taskinstance.py:1159} INFO - Dependencies all met for dep_context=requeueable deps ti=<TaskInstance: coingecko_ingestion_dag.store_raw_data_in_hdfs scheduled__2025-01-15T00:00:00+00:00 [queued]>
[2025-02-24T17:20:11.717+0000] {taskinstance.py:1361} INFO - Starting attempt 2 of 2
[2025-02-24T17:20:11.801+0000] {taskinstance.py:1382} INFO - Executing <Task(PythonOperator): store_raw_data_in_hdfs> on 2025-01-15 00:00:00+00:00
[2025-02-24T17:20:11.815+0000] {standard_task_runner.py:57} INFO - Started process 640 to run task
[2025-02-24T17:20:11.825+0000] {standard_task_runner.py:84} INFO - Running: ['***', 'tasks', 'run', 'coingecko_ingestion_dag', 'store_raw_data_in_hdfs', 'scheduled__2025-01-15T00:00:00+00:00', '--job-id', '37', '--raw', '--subdir', 'DAGS_FOLDER/test.py', '--cfg-path', '/tmp/tmp2k61sxx3']
[2025-02-24T17:20:11.832+0000] {standard_task_runner.py:85} INFO - Job 37: Subtask store_raw_data_in_hdfs
[2025-02-24T17:20:12.086+0000] {task_command.py:415} INFO - Running <TaskInstance: coingecko_ingestion_dag.store_raw_data_in_hdfs scheduled__2025-01-15T00:00:00+00:00 [running]> on host 85b967fd3989
[2025-02-24T17:20:12.278+0000] {taskinstance.py:1660} INFO - Exporting env vars: AIRFLOW_CTX_DAG_OWNER='etudiant' AIRFLOW_CTX_DAG_ID='coingecko_ingestion_dag' AIRFLOW_CTX_TASK_ID='store_raw_data_in_hdfs' AIRFLOW_CTX_EXECUTION_DATE='2025-01-15T00:00:00+00:00' AIRFLOW_CTX_TRY_NUMBER='2' AIRFLOW_CTX_DAG_RUN_ID='scheduled__2025-01-15T00:00:00+00:00'
[2025-02-24T17:20:12.332+0000] {taskinstance.py:1943} ERROR - Task failed with exception
Traceback (most recent call last):
  File "/home/airflow/.local/lib/python3.8/site-packages/airflow/operators/python.py", line 192, in execute
    return_value = self.execute_callable()
  File "/home/airflow/.local/lib/python3.8/site-packages/airflow/operators/python.py", line 209, in execute_callable
    return self.python_callable(*self.op_args, **self.op_kwargs)
  File "/opt/airflow/dags/test.py", line 38, in store_raw_data_in_hdfs
    with open(local_file, 'w') as f:
PermissionError: [Errno 13] Permission denied: '/mnt/hadoop_data/coingecko_raw.json'
[2025-02-24T17:20:12.389+0000] {taskinstance.py:1400} INFO - Marking task as FAILED. dag_id=coingecko_ingestion_dag, task_id=store_raw_data_in_hdfs, execution_date=20250115T000000, start_date=20250224T172011, end_date=20250224T172012
[2025-02-24T17:20:12.424+0000] {standard_task_runner.py:104} ERROR - Failed to execute job 37 for task store_raw_data_in_hdfs ([Errno 13] Permission denied: '/mnt/hadoop_data/coingecko_raw.json'; 640)
[2025-02-24T17:20:12.464+0000] {local_task_job_runner.py:228} INFO - Task exited with return code 1
[2025-02-24T17:20:12.518+0000] {taskinstance.py:2784} INFO - 0 downstream tasks scheduled from follow-on schedule check
[2025-02-25T15:52:56.042+0000] {taskinstance.py:1159} INFO - Dependencies all met for dep_context=non-requeueable deps ti=<TaskInstance: coingecko_ingestion_dag.store_raw_data_in_hdfs scheduled__2025-01-15T00:00:00+00:00 [queued]>
[2025-02-25T15:52:56.092+0000] {taskinstance.py:1159} INFO - Dependencies all met for dep_context=requeueable deps ti=<TaskInstance: coingecko_ingestion_dag.store_raw_data_in_hdfs scheduled__2025-01-15T00:00:00+00:00 [queued]>
[2025-02-25T15:52:56.095+0000] {taskinstance.py:1361} INFO - Starting attempt 2 of 2
[2025-02-25T15:52:56.149+0000] {taskinstance.py:1382} INFO - Executing <Task(PythonOperator): store_raw_data_in_hdfs> on 2025-01-15 00:00:00+00:00
[2025-02-25T15:52:56.166+0000] {standard_task_runner.py:57} INFO - Started process 330 to run task
[2025-02-25T15:52:56.182+0000] {standard_task_runner.py:84} INFO - Running: ['***', 'tasks', 'run', 'coingecko_ingestion_dag', 'store_raw_data_in_hdfs', 'scheduled__2025-01-15T00:00:00+00:00', '--job-id', '43', '--raw', '--subdir', 'DAGS_FOLDER/pipeline.py', '--cfg-path', '/tmp/tmpuuts5d5q']
[2025-02-25T15:52:56.190+0000] {standard_task_runner.py:85} INFO - Job 43: Subtask store_raw_data_in_hdfs
[2025-02-25T15:52:56.459+0000] {task_command.py:415} INFO - Running <TaskInstance: coingecko_ingestion_dag.store_raw_data_in_hdfs scheduled__2025-01-15T00:00:00+00:00 [running]> on host af9744bbb9eb
[2025-02-25T15:52:56.887+0000] {taskinstance.py:1660} INFO - Exporting env vars: AIRFLOW_CTX_DAG_OWNER='etudiant' AIRFLOW_CTX_DAG_ID='coingecko_ingestion_dag' AIRFLOW_CTX_TASK_ID='store_raw_data_in_hdfs' AIRFLOW_CTX_EXECUTION_DATE='2025-01-15T00:00:00+00:00' AIRFLOW_CTX_TRY_NUMBER='2' AIRFLOW_CTX_DAG_RUN_ID='scheduled__2025-01-15T00:00:00+00:00'
[2025-02-25T15:52:56.930+0000] {taskinstance.py:1943} ERROR - Task failed with exception
Traceback (most recent call last):
  File "/home/airflow/.local/lib/python3.8/site-packages/airflow/operators/python.py", line 192, in execute
    return_value = self.execute_callable()
  File "/home/airflow/.local/lib/python3.8/site-packages/airflow/operators/python.py", line 209, in execute_callable
    return self.python_callable(*self.op_args, **self.op_kwargs)
  File "/opt/airflow/dags/pipeline.py", line 39, in store_raw_data_in_hdfs
    with open(local_file, 'w') as f:
PermissionError: [Errno 13] Permission denied: '/mnt/hadoop_data/coingecko_raw.json'
[2025-02-25T15:52:56.993+0000] {taskinstance.py:1400} INFO - Marking task as FAILED. dag_id=coingecko_ingestion_dag, task_id=store_raw_data_in_hdfs, execution_date=20250115T000000, start_date=20250225T155256, end_date=20250225T155256
[2025-02-25T15:52:57.055+0000] {standard_task_runner.py:104} ERROR - Failed to execute job 43 for task store_raw_data_in_hdfs ([Errno 13] Permission denied: '/mnt/hadoop_data/coingecko_raw.json'; 330)
[2025-02-25T15:52:57.124+0000] {local_task_job_runner.py:228} INFO - Task exited with return code 1
[2025-02-25T15:52:57.222+0000] {taskinstance.py:2784} INFO - 0 downstream tasks scheduled from follow-on schedule check
