[2025-02-27T20:38:10.163+0000] {taskinstance.py:1159} INFO - Dependencies all met for dep_context=non-requeueable deps ti=<TaskInstance: coingecko_ingestion_dag.load_to_hbase manual__2025-02-27T20:20:55.025119+00:00 [queued]>
[2025-02-27T20:38:10.172+0000] {taskinstance.py:1159} INFO - Dependencies all met for dep_context=requeueable deps ti=<TaskInstance: coingecko_ingestion_dag.load_to_hbase manual__2025-02-27T20:20:55.025119+00:00 [queued]>
[2025-02-27T20:38:10.173+0000] {taskinstance.py:1361} INFO - Starting attempt 4 of 4
[2025-02-27T20:38:10.184+0000] {taskinstance.py:1382} INFO - Executing <Task(PythonOperator): load_to_hbase> on 2025-02-27 20:20:55.025119+00:00
[2025-02-27T20:38:10.187+0000] {standard_task_runner.py:57} INFO - Started process 478 to run task
[2025-02-27T20:38:10.190+0000] {standard_task_runner.py:84} INFO - Running: ['***', 'tasks', 'run', 'coingecko_ingestion_dag', 'load_to_hbase', 'manual__2025-02-27T20:20:55.025119+00:00', '--job-id', '416', '--raw', '--subdir', 'DAGS_FOLDER/pipeline.py', '--cfg-path', '/tmp/tmp4oew5gh1']
[2025-02-27T20:38:10.193+0000] {standard_task_runner.py:85} INFO - Job 416: Subtask load_to_hbase
[2025-02-27T20:38:10.235+0000] {task_command.py:415} INFO - Running <TaskInstance: coingecko_ingestion_dag.load_to_hbase manual__2025-02-27T20:20:55.025119+00:00 [running]> on host 268c3735a020
[2025-02-27T20:38:10.302+0000] {taskinstance.py:1660} INFO - Exporting env vars: AIRFLOW_CTX_DAG_OWNER='etudiant' AIRFLOW_CTX_DAG_ID='coingecko_ingestion_dag' AIRFLOW_CTX_TASK_ID='load_to_hbase' AIRFLOW_CTX_EXECUTION_DATE='2025-02-27T20:20:55.025119+00:00' AIRFLOW_CTX_TRY_NUMBER='4' AIRFLOW_CTX_DAG_RUN_ID='manual__2025-02-27T20:20:55.025119+00:00'
[2025-02-27T20:38:11.788+0000] {taskinstance.py:1943} ERROR - Task failed with exception
Traceback (most recent call last):
  File "/home/airflow/.local/lib/python3.8/site-packages/airflow/operators/python.py", line 192, in execute
    return_value = self.execute_callable()
  File "/home/airflow/.local/lib/python3.8/site-packages/airflow/operators/python.py", line 209, in execute_callable
    return self.python_callable(*self.op_args, **self.op_kwargs)
  File "/opt/airflow/dags/pipeline.py", line 59, in load_to_hbase
    raise Exception(f"Failed to get file from HDFS: {result.stderr}")
Exception: Failed to get file from HDFS: get: `/tmp/crypto_agg.csv': File exists

[2025-02-27T20:38:11.797+0000] {taskinstance.py:1400} INFO - Marking task as FAILED. dag_id=coingecko_ingestion_dag, task_id=load_to_hbase, execution_date=20250227T202055, start_date=20250227T203810, end_date=20250227T203811
[2025-02-27T20:38:11.809+0000] {standard_task_runner.py:104} ERROR - Failed to execute job 416 for task load_to_hbase (Failed to get file from HDFS: get: `/tmp/crypto_agg.csv': File exists
; 478)
[2025-02-27T20:38:11.848+0000] {local_task_job_runner.py:228} INFO - Task exited with return code 1
[2025-02-27T20:38:11.861+0000] {taskinstance.py:2784} INFO - 0 downstream tasks scheduled from follow-on schedule check
