[2025-02-25T12:21:38.638+0000] {taskinstance.py:1159} INFO - Dependencies all met for dep_context=non-requeueable deps ti=<TaskInstance: coingecko_ingestion_dag.store_raw_data_in_hdfs manual__2025-02-25T12:16:33.619633+00:00 [queued]>
[2025-02-25T12:21:38.646+0000] {taskinstance.py:1159} INFO - Dependencies all met for dep_context=requeueable deps ti=<TaskInstance: coingecko_ingestion_dag.store_raw_data_in_hdfs manual__2025-02-25T12:16:33.619633+00:00 [queued]>
[2025-02-25T12:21:38.647+0000] {taskinstance.py:1361} INFO - Starting attempt 2 of 2
[2025-02-25T12:21:38.659+0000] {taskinstance.py:1382} INFO - Executing <Task(PythonOperator): store_raw_data_in_hdfs> on 2025-02-25 12:16:33.619633+00:00
[2025-02-25T12:21:38.663+0000] {standard_task_runner.py:57} INFO - Started process 1380 to run task
[2025-02-25T12:21:38.666+0000] {standard_task_runner.py:84} INFO - Running: ['***', 'tasks', 'run', 'coingecko_ingestion_dag', 'store_raw_data_in_hdfs', 'manual__2025-02-25T12:16:33.619633+00:00', '--job-id', '197', '--raw', '--subdir', 'DAGS_FOLDER/test.py', '--cfg-path', '/tmp/tmprrmyyg33']
[2025-02-25T12:21:38.668+0000] {standard_task_runner.py:85} INFO - Job 197: Subtask store_raw_data_in_hdfs
[2025-02-25T12:21:38.703+0000] {task_command.py:415} INFO - Running <TaskInstance: coingecko_ingestion_dag.store_raw_data_in_hdfs manual__2025-02-25T12:16:33.619633+00:00 [running]> on host 85b967fd3989
[2025-02-25T12:21:38.761+0000] {taskinstance.py:1660} INFO - Exporting env vars: AIRFLOW_CTX_DAG_OWNER='etudiant' AIRFLOW_CTX_DAG_ID='coingecko_ingestion_dag' AIRFLOW_CTX_TASK_ID='store_raw_data_in_hdfs' AIRFLOW_CTX_EXECUTION_DATE='2025-02-25T12:16:33.619633+00:00' AIRFLOW_CTX_TRY_NUMBER='2' AIRFLOW_CTX_DAG_RUN_ID='manual__2025-02-25T12:16:33.619633+00:00'
[2025-02-25T12:21:38.774+0000] {taskinstance.py:1943} ERROR - Task failed with exception
Traceback (most recent call last):
  File "/home/airflow/.local/lib/python3.8/site-packages/airflow/operators/python.py", line 192, in execute
    return_value = self.execute_callable()
  File "/home/airflow/.local/lib/python3.8/site-packages/airflow/operators/python.py", line 209, in execute_callable
    return self.python_callable(*self.op_args, **self.op_kwargs)
  File "/opt/airflow/dags/test.py", line 38, in store_raw_data_in_hdfs
    with open(local_file, 'w') as f:
PermissionError: [Errno 13] Permission denied: '/mnt/hadoop_data/coingecko_raw.json'
[2025-02-25T12:21:38.780+0000] {taskinstance.py:1400} INFO - Marking task as FAILED. dag_id=coingecko_ingestion_dag, task_id=store_raw_data_in_hdfs, execution_date=20250225T121633, start_date=20250225T122138, end_date=20250225T122138
[2025-02-25T12:21:38.790+0000] {standard_task_runner.py:104} ERROR - Failed to execute job 197 for task store_raw_data_in_hdfs ([Errno 13] Permission denied: '/mnt/hadoop_data/coingecko_raw.json'; 1380)
[2025-02-25T12:21:38.804+0000] {local_task_job_runner.py:228} INFO - Task exited with return code 1
[2025-02-25T12:21:38.817+0000] {taskinstance.py:2784} INFO - 0 downstream tasks scheduled from follow-on schedule check
