[2025-02-27T22:19:02.788+0000] {taskinstance.py:1159} INFO - Dependencies all met for dep_context=non-requeueable deps ti=<TaskInstance: coingecko_ingestion_dag.load_to_hbase manual__2025-02-27T21:00:31.609020+00:00 [queued]>
[2025-02-27T22:19:02.814+0000] {taskinstance.py:1159} INFO - Dependencies all met for dep_context=requeueable deps ti=<TaskInstance: coingecko_ingestion_dag.load_to_hbase manual__2025-02-27T21:00:31.609020+00:00 [queued]>
[2025-02-27T22:19:02.822+0000] {taskinstance.py:1361} INFO - Starting attempt 4 of 4
[2025-02-27T22:19:02.872+0000] {taskinstance.py:1382} INFO - Executing <Task(PythonOperator): load_to_hbase> on 2025-02-27 21:00:31.609020+00:00
[2025-02-27T22:19:02.884+0000] {standard_task_runner.py:57} INFO - Started process 1483 to run task
[2025-02-27T22:19:02.894+0000] {standard_task_runner.py:84} INFO - Running: ['***', 'tasks', 'run', 'coingecko_ingestion_dag', 'load_to_hbase', 'manual__2025-02-27T21:00:31.609020+00:00', '--job-id', '505', '--raw', '--subdir', 'DAGS_FOLDER/pipeline.py', '--cfg-path', '/tmp/tmpl49f8b3m']
[2025-02-27T22:19:02.900+0000] {standard_task_runner.py:85} INFO - Job 505: Subtask load_to_hbase
[2025-02-27T22:19:03.019+0000] {task_command.py:415} INFO - Running <TaskInstance: coingecko_ingestion_dag.load_to_hbase manual__2025-02-27T21:00:31.609020+00:00 [running]> on host b86b19d2f863
[2025-02-27T22:19:03.241+0000] {taskinstance.py:1660} INFO - Exporting env vars: AIRFLOW_CTX_DAG_OWNER='etudiant' AIRFLOW_CTX_DAG_ID='coingecko_ingestion_dag' AIRFLOW_CTX_TASK_ID='load_to_hbase' AIRFLOW_CTX_EXECUTION_DATE='2025-02-27T21:00:31.609020+00:00' AIRFLOW_CTX_TRY_NUMBER='4' AIRFLOW_CTX_DAG_RUN_ID='manual__2025-02-27T21:00:31.609020+00:00'
[2025-02-27T22:19:10.061+0000] {taskinstance.py:1943} ERROR - Task failed with exception
Traceback (most recent call last):
  File "/home/airflow/.local/lib/python3.8/site-packages/airflow/operators/python.py", line 192, in execute
    return_value = self.execute_callable()
  File "/home/airflow/.local/lib/python3.8/site-packages/airflow/operators/python.py", line 209, in execute_callable
    return self.python_callable(*self.op_args, **self.op_kwargs)
  File "/opt/airflow/dags/pipeline.py", line 59, in load_to_hbase
    raise Exception(f"Failed to get file from HDFS: {result.stderr}")
Exception: Failed to get file from HDFS: 
[2025-02-27T22:19:10.176+0000] {taskinstance.py:1400} INFO - Marking task as FAILED. dag_id=coingecko_ingestion_dag, task_id=load_to_hbase, execution_date=20250227T210031, start_date=20250227T221902, end_date=20250227T221910
[2025-02-27T22:19:10.258+0000] {standard_task_runner.py:104} ERROR - Failed to execute job 505 for task load_to_hbase (Failed to get file from HDFS: ; 1483)
[2025-02-27T22:19:10.317+0000] {local_task_job_runner.py:228} INFO - Task exited with return code 1
[2025-02-27T22:19:10.373+0000] {taskinstance.py:2784} INFO - 0 downstream tasks scheduled from follow-on schedule check
