[2025-02-24T18:14:16.574+0000] {taskinstance.py:1159} INFO - Dependencies all met for dep_context=non-requeueable deps ti=<TaskInstance: coingecko_ingestion_dag.store_raw_data_in_hdfs scheduled__2025-02-19T00:00:00+00:00 [queued]>
[2025-02-24T18:14:16.595+0000] {taskinstance.py:1159} INFO - Dependencies all met for dep_context=requeueable deps ti=<TaskInstance: coingecko_ingestion_dag.store_raw_data_in_hdfs scheduled__2025-02-19T00:00:00+00:00 [queued]>
[2025-02-24T18:14:16.596+0000] {taskinstance.py:1361} INFO - Starting attempt 2 of 2
[2025-02-24T18:14:16.619+0000] {taskinstance.py:1382} INFO - Executing <Task(PythonOperator): store_raw_data_in_hdfs> on 2025-02-19 00:00:00+00:00
[2025-02-24T18:14:16.626+0000] {standard_task_runner.py:57} INFO - Started process 1149 to run task
[2025-02-24T18:14:16.637+0000] {standard_task_runner.py:84} INFO - Running: ['***', 'tasks', 'run', 'coingecko_ingestion_dag', 'store_raw_data_in_hdfs', 'scheduled__2025-02-19T00:00:00+00:00', '--job-id', '162', '--raw', '--subdir', 'DAGS_FOLDER/test.py', '--cfg-path', '/tmp/tmpmvrow1he']
[2025-02-24T18:14:16.647+0000] {standard_task_runner.py:85} INFO - Job 162: Subtask store_raw_data_in_hdfs
[2025-02-24T18:14:16.761+0000] {task_command.py:415} INFO - Running <TaskInstance: coingecko_ingestion_dag.store_raw_data_in_hdfs scheduled__2025-02-19T00:00:00+00:00 [running]> on host 85b967fd3989
[2025-02-24T18:14:16.927+0000] {taskinstance.py:1660} INFO - Exporting env vars: AIRFLOW_CTX_DAG_OWNER='etudiant' AIRFLOW_CTX_DAG_ID='coingecko_ingestion_dag' AIRFLOW_CTX_TASK_ID='store_raw_data_in_hdfs' AIRFLOW_CTX_EXECUTION_DATE='2025-02-19T00:00:00+00:00' AIRFLOW_CTX_TRY_NUMBER='2' AIRFLOW_CTX_DAG_RUN_ID='scheduled__2025-02-19T00:00:00+00:00'
[2025-02-24T18:14:16.958+0000] {taskinstance.py:1943} ERROR - Task failed with exception
Traceback (most recent call last):
  File "/home/airflow/.local/lib/python3.8/site-packages/airflow/operators/python.py", line 192, in execute
    return_value = self.execute_callable()
  File "/home/airflow/.local/lib/python3.8/site-packages/airflow/operators/python.py", line 209, in execute_callable
    return self.python_callable(*self.op_args, **self.op_kwargs)
  File "/opt/airflow/dags/test.py", line 38, in store_raw_data_in_hdfs
    with open(local_file, 'w') as f:
PermissionError: [Errno 13] Permission denied: '/mnt/hadoop_data/coingecko_raw.json'
[2025-02-24T18:14:16.976+0000] {taskinstance.py:1400} INFO - Marking task as FAILED. dag_id=coingecko_ingestion_dag, task_id=store_raw_data_in_hdfs, execution_date=20250219T000000, start_date=20250224T181416, end_date=20250224T181416
[2025-02-24T18:14:16.994+0000] {standard_task_runner.py:104} ERROR - Failed to execute job 162 for task store_raw_data_in_hdfs ([Errno 13] Permission denied: '/mnt/hadoop_data/coingecko_raw.json'; 1149)
[2025-02-24T18:14:17.024+0000] {local_task_job_runner.py:228} INFO - Task exited with return code 1
[2025-02-24T18:14:17.053+0000] {taskinstance.py:2784} INFO - 0 downstream tasks scheduled from follow-on schedule check
[2025-02-25T16:09:31.581+0000] {taskinstance.py:1159} INFO - Dependencies all met for dep_context=non-requeueable deps ti=<TaskInstance: coingecko_ingestion_dag.store_raw_data_in_hdfs scheduled__2025-02-19T00:00:00+00:00 [queued]>
[2025-02-25T16:09:31.589+0000] {taskinstance.py:1159} INFO - Dependencies all met for dep_context=requeueable deps ti=<TaskInstance: coingecko_ingestion_dag.store_raw_data_in_hdfs scheduled__2025-02-19T00:00:00+00:00 [queued]>
[2025-02-25T16:09:31.589+0000] {taskinstance.py:1361} INFO - Starting attempt 2 of 2
[2025-02-25T16:09:31.600+0000] {taskinstance.py:1382} INFO - Executing <Task(PythonOperator): store_raw_data_in_hdfs> on 2025-02-19 00:00:00+00:00
[2025-02-25T16:09:31.604+0000] {standard_task_runner.py:57} INFO - Started process 728 to run task
[2025-02-25T16:09:31.607+0000] {standard_task_runner.py:84} INFO - Running: ['***', 'tasks', 'run', 'coingecko_ingestion_dag', 'store_raw_data_in_hdfs', 'scheduled__2025-02-19T00:00:00+00:00', '--job-id', '165', '--raw', '--subdir', 'DAGS_FOLDER/pipeline.py', '--cfg-path', '/tmp/tmpqocf5a1s']
[2025-02-25T16:09:31.609+0000] {standard_task_runner.py:85} INFO - Job 165: Subtask store_raw_data_in_hdfs
[2025-02-25T16:09:31.648+0000] {task_command.py:415} INFO - Running <TaskInstance: coingecko_ingestion_dag.store_raw_data_in_hdfs scheduled__2025-02-19T00:00:00+00:00 [running]> on host af9744bbb9eb
[2025-02-25T16:09:31.710+0000] {taskinstance.py:1660} INFO - Exporting env vars: AIRFLOW_CTX_DAG_OWNER='etudiant' AIRFLOW_CTX_DAG_ID='coingecko_ingestion_dag' AIRFLOW_CTX_TASK_ID='store_raw_data_in_hdfs' AIRFLOW_CTX_EXECUTION_DATE='2025-02-19T00:00:00+00:00' AIRFLOW_CTX_TRY_NUMBER='2' AIRFLOW_CTX_DAG_RUN_ID='scheduled__2025-02-19T00:00:00+00:00'
[2025-02-25T16:09:31.724+0000] {taskinstance.py:1943} ERROR - Task failed with exception
Traceback (most recent call last):
  File "/home/airflow/.local/lib/python3.8/site-packages/airflow/operators/python.py", line 192, in execute
    return_value = self.execute_callable()
  File "/home/airflow/.local/lib/python3.8/site-packages/airflow/operators/python.py", line 209, in execute_callable
    return self.python_callable(*self.op_args, **self.op_kwargs)
  File "/opt/airflow/dags/pipeline.py", line 39, in store_raw_data_in_hdfs
    with open(local_file, 'w') as f:
PermissionError: [Errno 13] Permission denied: '/mnt/hadoop_data/coingecko_raw.json'
[2025-02-25T16:09:31.731+0000] {taskinstance.py:1400} INFO - Marking task as FAILED. dag_id=coingecko_ingestion_dag, task_id=store_raw_data_in_hdfs, execution_date=20250219T000000, start_date=20250225T160931, end_date=20250225T160931
[2025-02-25T16:09:31.742+0000] {standard_task_runner.py:104} ERROR - Failed to execute job 165 for task store_raw_data_in_hdfs ([Errno 13] Permission denied: '/mnt/hadoop_data/coingecko_raw.json'; 728)
[2025-02-25T16:09:31.787+0000] {local_task_job_runner.py:228} INFO - Task exited with return code 1
[2025-02-25T16:09:31.802+0000] {taskinstance.py:2784} INFO - 0 downstream tasks scheduled from follow-on schedule check
