[2025-02-24T17:20:12.446+0000] {taskinstance.py:1159} INFO - Dependencies all met for dep_context=non-requeueable deps ti=<TaskInstance: coingecko_ingestion_dag.store_raw_data_in_hdfs scheduled__2025-01-12T00:00:00+00:00 [queued]>
[2025-02-24T17:20:12.473+0000] {taskinstance.py:1159} INFO - Dependencies all met for dep_context=requeueable deps ti=<TaskInstance: coingecko_ingestion_dag.store_raw_data_in_hdfs scheduled__2025-01-12T00:00:00+00:00 [queued]>
[2025-02-24T17:20:12.473+0000] {taskinstance.py:1361} INFO - Starting attempt 2 of 2
[2025-02-24T17:20:12.519+0000] {taskinstance.py:1382} INFO - Executing <Task(PythonOperator): store_raw_data_in_hdfs> on 2025-01-12 00:00:00+00:00
[2025-02-24T17:20:12.541+0000] {standard_task_runner.py:57} INFO - Started process 646 to run task
[2025-02-24T17:20:12.548+0000] {standard_task_runner.py:84} INFO - Running: ['***', 'tasks', 'run', 'coingecko_ingestion_dag', 'store_raw_data_in_hdfs', 'scheduled__2025-01-12T00:00:00+00:00', '--job-id', '42', '--raw', '--subdir', 'DAGS_FOLDER/test.py', '--cfg-path', '/tmp/tmpzpm054z2']
[2025-02-24T17:20:12.555+0000] {standard_task_runner.py:85} INFO - Job 42: Subtask store_raw_data_in_hdfs
[2025-02-24T17:20:12.703+0000] {task_command.py:415} INFO - Running <TaskInstance: coingecko_ingestion_dag.store_raw_data_in_hdfs scheduled__2025-01-12T00:00:00+00:00 [running]> on host 85b967fd3989
[2025-02-24T17:20:12.882+0000] {taskinstance.py:1660} INFO - Exporting env vars: AIRFLOW_CTX_DAG_OWNER='etudiant' AIRFLOW_CTX_DAG_ID='coingecko_ingestion_dag' AIRFLOW_CTX_TASK_ID='store_raw_data_in_hdfs' AIRFLOW_CTX_EXECUTION_DATE='2025-01-12T00:00:00+00:00' AIRFLOW_CTX_TRY_NUMBER='2' AIRFLOW_CTX_DAG_RUN_ID='scheduled__2025-01-12T00:00:00+00:00'
[2025-02-24T17:20:12.920+0000] {taskinstance.py:1943} ERROR - Task failed with exception
Traceback (most recent call last):
  File "/home/airflow/.local/lib/python3.8/site-packages/airflow/operators/python.py", line 192, in execute
    return_value = self.execute_callable()
  File "/home/airflow/.local/lib/python3.8/site-packages/airflow/operators/python.py", line 209, in execute_callable
    return self.python_callable(*self.op_args, **self.op_kwargs)
  File "/opt/airflow/dags/test.py", line 38, in store_raw_data_in_hdfs
    with open(local_file, 'w') as f:
PermissionError: [Errno 13] Permission denied: '/mnt/hadoop_data/coingecko_raw.json'
[2025-02-24T17:20:12.949+0000] {taskinstance.py:1400} INFO - Marking task as FAILED. dag_id=coingecko_ingestion_dag, task_id=store_raw_data_in_hdfs, execution_date=20250112T000000, start_date=20250224T172012, end_date=20250224T172012
[2025-02-24T17:20:12.980+0000] {standard_task_runner.py:104} ERROR - Failed to execute job 42 for task store_raw_data_in_hdfs ([Errno 13] Permission denied: '/mnt/hadoop_data/coingecko_raw.json'; 646)
[2025-02-24T17:20:13.027+0000] {local_task_job_runner.py:228} INFO - Task exited with return code 1
[2025-02-24T17:20:13.167+0000] {taskinstance.py:2784} INFO - 0 downstream tasks scheduled from follow-on schedule check
[2025-02-25T15:52:55.556+0000] {taskinstance.py:1159} INFO - Dependencies all met for dep_context=non-requeueable deps ti=<TaskInstance: coingecko_ingestion_dag.store_raw_data_in_hdfs scheduled__2025-01-12T00:00:00+00:00 [queued]>
[2025-02-25T15:52:55.629+0000] {taskinstance.py:1159} INFO - Dependencies all met for dep_context=requeueable deps ti=<TaskInstance: coingecko_ingestion_dag.store_raw_data_in_hdfs scheduled__2025-01-12T00:00:00+00:00 [queued]>
[2025-02-25T15:52:55.635+0000] {taskinstance.py:1361} INFO - Starting attempt 2 of 2
[2025-02-25T15:52:55.736+0000] {taskinstance.py:1382} INFO - Executing <Task(PythonOperator): store_raw_data_in_hdfs> on 2025-01-12 00:00:00+00:00
[2025-02-25T15:52:55.790+0000] {standard_task_runner.py:57} INFO - Started process 327 to run task
[2025-02-25T15:52:55.810+0000] {standard_task_runner.py:84} INFO - Running: ['***', 'tasks', 'run', 'coingecko_ingestion_dag', 'store_raw_data_in_hdfs', 'scheduled__2025-01-12T00:00:00+00:00', '--job-id', '41', '--raw', '--subdir', 'DAGS_FOLDER/pipeline.py', '--cfg-path', '/tmp/tmpavzd70eb']
[2025-02-25T15:52:55.822+0000] {standard_task_runner.py:85} INFO - Job 41: Subtask store_raw_data_in_hdfs
[2025-02-25T15:52:56.136+0000] {task_command.py:415} INFO - Running <TaskInstance: coingecko_ingestion_dag.store_raw_data_in_hdfs scheduled__2025-01-12T00:00:00+00:00 [running]> on host af9744bbb9eb
[2025-02-25T15:52:56.519+0000] {taskinstance.py:1660} INFO - Exporting env vars: AIRFLOW_CTX_DAG_OWNER='etudiant' AIRFLOW_CTX_DAG_ID='coingecko_ingestion_dag' AIRFLOW_CTX_TASK_ID='store_raw_data_in_hdfs' AIRFLOW_CTX_EXECUTION_DATE='2025-01-12T00:00:00+00:00' AIRFLOW_CTX_TRY_NUMBER='2' AIRFLOW_CTX_DAG_RUN_ID='scheduled__2025-01-12T00:00:00+00:00'
[2025-02-25T15:52:56.589+0000] {taskinstance.py:1943} ERROR - Task failed with exception
Traceback (most recent call last):
  File "/home/airflow/.local/lib/python3.8/site-packages/airflow/operators/python.py", line 192, in execute
    return_value = self.execute_callable()
  File "/home/airflow/.local/lib/python3.8/site-packages/airflow/operators/python.py", line 209, in execute_callable
    return self.python_callable(*self.op_args, **self.op_kwargs)
  File "/opt/airflow/dags/pipeline.py", line 39, in store_raw_data_in_hdfs
    with open(local_file, 'w') as f:
PermissionError: [Errno 13] Permission denied: '/mnt/hadoop_data/coingecko_raw.json'
[2025-02-25T15:52:56.685+0000] {taskinstance.py:1400} INFO - Marking task as FAILED. dag_id=coingecko_ingestion_dag, task_id=store_raw_data_in_hdfs, execution_date=20250112T000000, start_date=20250225T155255, end_date=20250225T155256
[2025-02-25T15:52:56.761+0000] {standard_task_runner.py:104} ERROR - Failed to execute job 41 for task store_raw_data_in_hdfs ([Errno 13] Permission denied: '/mnt/hadoop_data/coingecko_raw.json'; 327)
[2025-02-25T15:52:56.835+0000] {local_task_job_runner.py:228} INFO - Task exited with return code 1
[2025-02-25T15:52:57.119+0000] {taskinstance.py:2784} INFO - 0 downstream tasks scheduled from follow-on schedule check
