[2025-02-24T17:20:29.793+0000] {taskinstance.py:1159} INFO - Dependencies all met for dep_context=non-requeueable deps ti=<TaskInstance: coingecko_ingestion_dag.store_raw_data_in_hdfs scheduled__2025-01-29T00:00:00+00:00 [queued]>
[2025-02-24T17:20:29.805+0000] {taskinstance.py:1159} INFO - Dependencies all met for dep_context=requeueable deps ti=<TaskInstance: coingecko_ingestion_dag.store_raw_data_in_hdfs scheduled__2025-01-29T00:00:00+00:00 [queued]>
[2025-02-24T17:20:29.806+0000] {taskinstance.py:1361} INFO - Starting attempt 1 of 2
[2025-02-24T17:20:29.823+0000] {taskinstance.py:1382} INFO - Executing <Task(PythonOperator): store_raw_data_in_hdfs> on 2025-01-29 00:00:00+00:00
[2025-02-24T17:20:29.832+0000] {standard_task_runner.py:57} INFO - Started process 711 to run task
[2025-02-24T17:20:29.836+0000] {standard_task_runner.py:84} INFO - Running: ['***', 'tasks', 'run', 'coingecko_ingestion_dag', 'store_raw_data_in_hdfs', 'scheduled__2025-01-29T00:00:00+00:00', '--job-id', '78', '--raw', '--subdir', 'DAGS_FOLDER/test.py', '--cfg-path', '/tmp/tmp7m6t_m8r']
[2025-02-24T17:20:29.840+0000] {standard_task_runner.py:85} INFO - Job 78: Subtask store_raw_data_in_hdfs
[2025-02-24T17:20:29.890+0000] {task_command.py:415} INFO - Running <TaskInstance: coingecko_ingestion_dag.store_raw_data_in_hdfs scheduled__2025-01-29T00:00:00+00:00 [running]> on host 85b967fd3989
[2025-02-24T17:20:29.967+0000] {taskinstance.py:1660} INFO - Exporting env vars: AIRFLOW_CTX_DAG_OWNER='etudiant' AIRFLOW_CTX_DAG_ID='coingecko_ingestion_dag' AIRFLOW_CTX_TASK_ID='store_raw_data_in_hdfs' AIRFLOW_CTX_EXECUTION_DATE='2025-01-29T00:00:00+00:00' AIRFLOW_CTX_TRY_NUMBER='1' AIRFLOW_CTX_DAG_RUN_ID='scheduled__2025-01-29T00:00:00+00:00'
[2025-02-24T17:20:29.979+0000] {taskinstance.py:1943} ERROR - Task failed with exception
Traceback (most recent call last):
  File "/home/airflow/.local/lib/python3.8/site-packages/airflow/operators/python.py", line 192, in execute
    return_value = self.execute_callable()
  File "/home/airflow/.local/lib/python3.8/site-packages/airflow/operators/python.py", line 209, in execute_callable
    return self.python_callable(*self.op_args, **self.op_kwargs)
  File "/opt/airflow/dags/test.py", line 38, in store_raw_data_in_hdfs
    with open(local_file, 'w') as f:
PermissionError: [Errno 13] Permission denied: '/mnt/hadoop_data/coingecko_raw.json'
[2025-02-24T17:20:29.988+0000] {taskinstance.py:1400} INFO - Marking task as UP_FOR_RETRY. dag_id=coingecko_ingestion_dag, task_id=store_raw_data_in_hdfs, execution_date=20250129T000000, start_date=20250224T172029, end_date=20250224T172029
[2025-02-24T17:20:29.999+0000] {standard_task_runner.py:104} ERROR - Failed to execute job 78 for task store_raw_data_in_hdfs ([Errno 13] Permission denied: '/mnt/hadoop_data/coingecko_raw.json'; 711)
[2025-02-24T17:20:30.017+0000] {local_task_job_runner.py:228} INFO - Task exited with return code 1
[2025-02-24T17:20:30.032+0000] {taskinstance.py:2784} INFO - 0 downstream tasks scheduled from follow-on schedule check
[2025-02-25T15:53:50.434+0000] {taskinstance.py:1159} INFO - Dependencies all met for dep_context=non-requeueable deps ti=<TaskInstance: coingecko_ingestion_dag.store_raw_data_in_hdfs scheduled__2025-01-29T00:00:00+00:00 [queued]>
[2025-02-25T15:53:50.468+0000] {taskinstance.py:1159} INFO - Dependencies all met for dep_context=requeueable deps ti=<TaskInstance: coingecko_ingestion_dag.store_raw_data_in_hdfs scheduled__2025-01-29T00:00:00+00:00 [queued]>
[2025-02-25T15:53:50.470+0000] {taskinstance.py:1361} INFO - Starting attempt 1 of 2
[2025-02-25T15:53:50.504+0000] {taskinstance.py:1382} INFO - Executing <Task(PythonOperator): store_raw_data_in_hdfs> on 2025-01-29 00:00:00+00:00
[2025-02-25T15:53:50.519+0000] {standard_task_runner.py:57} INFO - Started process 400 to run task
[2025-02-25T15:53:50.526+0000] {standard_task_runner.py:84} INFO - Running: ['***', 'tasks', 'run', 'coingecko_ingestion_dag', 'store_raw_data_in_hdfs', 'scheduled__2025-01-29T00:00:00+00:00', '--job-id', '78', '--raw', '--subdir', 'DAGS_FOLDER/pipeline.py', '--cfg-path', '/tmp/tmpzddz5gew']
[2025-02-25T15:53:50.534+0000] {standard_task_runner.py:85} INFO - Job 78: Subtask store_raw_data_in_hdfs
[2025-02-25T15:53:50.671+0000] {task_command.py:415} INFO - Running <TaskInstance: coingecko_ingestion_dag.store_raw_data_in_hdfs scheduled__2025-01-29T00:00:00+00:00 [running]> on host af9744bbb9eb
[2025-02-25T15:53:50.844+0000] {taskinstance.py:1660} INFO - Exporting env vars: AIRFLOW_CTX_DAG_OWNER='etudiant' AIRFLOW_CTX_DAG_ID='coingecko_ingestion_dag' AIRFLOW_CTX_TASK_ID='store_raw_data_in_hdfs' AIRFLOW_CTX_EXECUTION_DATE='2025-01-29T00:00:00+00:00' AIRFLOW_CTX_TRY_NUMBER='1' AIRFLOW_CTX_DAG_RUN_ID='scheduled__2025-01-29T00:00:00+00:00'
[2025-02-25T15:53:50.870+0000] {taskinstance.py:1943} ERROR - Task failed with exception
Traceback (most recent call last):
  File "/home/airflow/.local/lib/python3.8/site-packages/airflow/operators/python.py", line 192, in execute
    return_value = self.execute_callable()
  File "/home/airflow/.local/lib/python3.8/site-packages/airflow/operators/python.py", line 209, in execute_callable
    return self.python_callable(*self.op_args, **self.op_kwargs)
  File "/opt/airflow/dags/pipeline.py", line 39, in store_raw_data_in_hdfs
    with open(local_file, 'w') as f:
PermissionError: [Errno 13] Permission denied: '/mnt/hadoop_data/coingecko_raw.json'
[2025-02-25T15:53:50.893+0000] {taskinstance.py:1400} INFO - Marking task as UP_FOR_RETRY. dag_id=coingecko_ingestion_dag, task_id=store_raw_data_in_hdfs, execution_date=20250129T000000, start_date=20250225T155350, end_date=20250225T155350
[2025-02-25T15:53:50.919+0000] {standard_task_runner.py:104} ERROR - Failed to execute job 78 for task store_raw_data_in_hdfs ([Errno 13] Permission denied: '/mnt/hadoop_data/coingecko_raw.json'; 400)
[2025-02-25T15:53:50.965+0000] {local_task_job_runner.py:228} INFO - Task exited with return code 1
[2025-02-25T15:53:51.228+0000] {taskinstance.py:2784} INFO - 0 downstream tasks scheduled from follow-on schedule check
