[2025-02-25T09:28:44.088+0000] {taskinstance.py:1159} INFO - Dependencies all met for dep_context=non-requeueable deps ti=<TaskInstance: coingecko_ingestion_dag.store_raw_data_in_hdfs scheduled__2025-02-24T00:00:00+00:00 [queued]>
[2025-02-25T09:28:44.104+0000] {taskinstance.py:1159} INFO - Dependencies all met for dep_context=requeueable deps ti=<TaskInstance: coingecko_ingestion_dag.store_raw_data_in_hdfs scheduled__2025-02-24T00:00:00+00:00 [queued]>
[2025-02-25T09:28:44.105+0000] {taskinstance.py:1361} INFO - Starting attempt 2 of 2
[2025-02-25T09:28:44.129+0000] {taskinstance.py:1382} INFO - Executing <Task(PythonOperator): store_raw_data_in_hdfs> on 2025-02-24 00:00:00+00:00
[2025-02-25T09:28:44.140+0000] {standard_task_runner.py:57} INFO - Started process 282 to run task
[2025-02-25T09:28:44.146+0000] {standard_task_runner.py:84} INFO - Running: ['***', 'tasks', 'run', 'coingecko_ingestion_dag', 'store_raw_data_in_hdfs', 'scheduled__2025-02-24T00:00:00+00:00', '--job-id', '173', '--raw', '--subdir', 'DAGS_FOLDER/pipeline.py', '--cfg-path', '/tmp/tmpnwcuy3lb']
[2025-02-25T09:28:44.158+0000] {standard_task_runner.py:85} INFO - Job 173: Subtask store_raw_data_in_hdfs
[2025-02-25T09:28:44.275+0000] {task_command.py:415} INFO - Running <TaskInstance: coingecko_ingestion_dag.store_raw_data_in_hdfs scheduled__2025-02-24T00:00:00+00:00 [running]> on host 85b967fd3989
[2025-02-25T09:28:44.439+0000] {taskinstance.py:1660} INFO - Exporting env vars: AIRFLOW_CTX_DAG_OWNER='etudiant' AIRFLOW_CTX_DAG_ID='coingecko_ingestion_dag' AIRFLOW_CTX_TASK_ID='store_raw_data_in_hdfs' AIRFLOW_CTX_EXECUTION_DATE='2025-02-24T00:00:00+00:00' AIRFLOW_CTX_TRY_NUMBER='2' AIRFLOW_CTX_DAG_RUN_ID='scheduled__2025-02-24T00:00:00+00:00'
[2025-02-25T09:28:44.470+0000] {taskinstance.py:1943} ERROR - Task failed with exception
Traceback (most recent call last):
  File "/home/airflow/.local/lib/python3.8/site-packages/airflow/operators/python.py", line 192, in execute
    return_value = self.execute_callable()
  File "/home/airflow/.local/lib/python3.8/site-packages/airflow/operators/python.py", line 209, in execute_callable
    return self.python_callable(*self.op_args, **self.op_kwargs)
  File "/opt/airflow/dags/pipeline.py", line 38, in store_raw_data_in_hdfs
    with open(local_file, 'w') as f:
PermissionError: [Errno 13] Permission denied: '/mnt/hadoop_data/coingecko_raw.json'
[2025-02-25T09:28:44.482+0000] {taskinstance.py:1400} INFO - Marking task as FAILED. dag_id=coingecko_ingestion_dag, task_id=store_raw_data_in_hdfs, execution_date=20250224T000000, start_date=20250225T092844, end_date=20250225T092844
[2025-02-25T09:28:44.501+0000] {standard_task_runner.py:104} ERROR - Failed to execute job 173 for task store_raw_data_in_hdfs ([Errno 13] Permission denied: '/mnt/hadoop_data/coingecko_raw.json'; 282)
[2025-02-25T09:28:44.531+0000] {local_task_job_runner.py:228} INFO - Task exited with return code 1
[2025-02-25T09:28:44.559+0000] {taskinstance.py:2784} INFO - 0 downstream tasks scheduled from follow-on schedule check
[2025-02-25T16:09:39.186+0000] {taskinstance.py:1159} INFO - Dependencies all met for dep_context=non-requeueable deps ti=<TaskInstance: coingecko_ingestion_dag.store_raw_data_in_hdfs scheduled__2025-02-24T00:00:00+00:00 [queued]>
[2025-02-25T16:09:39.198+0000] {taskinstance.py:1159} INFO - Dependencies all met for dep_context=requeueable deps ti=<TaskInstance: coingecko_ingestion_dag.store_raw_data_in_hdfs scheduled__2025-02-24T00:00:00+00:00 [queued]>
[2025-02-25T16:09:39.199+0000] {taskinstance.py:1361} INFO - Starting attempt 2 of 2
[2025-02-25T16:09:39.214+0000] {taskinstance.py:1382} INFO - Executing <Task(PythonOperator): store_raw_data_in_hdfs> on 2025-02-24 00:00:00+00:00
[2025-02-25T16:09:39.221+0000] {standard_task_runner.py:57} INFO - Started process 737 to run task
[2025-02-25T16:09:39.225+0000] {standard_task_runner.py:84} INFO - Running: ['***', 'tasks', 'run', 'coingecko_ingestion_dag', 'store_raw_data_in_hdfs', 'scheduled__2025-02-24T00:00:00+00:00', '--job-id', '169', '--raw', '--subdir', 'DAGS_FOLDER/pipeline.py', '--cfg-path', '/tmp/tmplq4obn1e']
[2025-02-25T16:09:39.228+0000] {standard_task_runner.py:85} INFO - Job 169: Subtask store_raw_data_in_hdfs
[2025-02-25T16:09:39.289+0000] {task_command.py:415} INFO - Running <TaskInstance: coingecko_ingestion_dag.store_raw_data_in_hdfs scheduled__2025-02-24T00:00:00+00:00 [running]> on host af9744bbb9eb
[2025-02-25T16:09:39.397+0000] {taskinstance.py:1660} INFO - Exporting env vars: AIRFLOW_CTX_DAG_OWNER='etudiant' AIRFLOW_CTX_DAG_ID='coingecko_ingestion_dag' AIRFLOW_CTX_TASK_ID='store_raw_data_in_hdfs' AIRFLOW_CTX_EXECUTION_DATE='2025-02-24T00:00:00+00:00' AIRFLOW_CTX_TRY_NUMBER='2' AIRFLOW_CTX_DAG_RUN_ID='scheduled__2025-02-24T00:00:00+00:00'
[2025-02-25T16:09:39.416+0000] {taskinstance.py:1943} ERROR - Task failed with exception
Traceback (most recent call last):
  File "/home/airflow/.local/lib/python3.8/site-packages/airflow/operators/python.py", line 192, in execute
    return_value = self.execute_callable()
  File "/home/airflow/.local/lib/python3.8/site-packages/airflow/operators/python.py", line 209, in execute_callable
    return self.python_callable(*self.op_args, **self.op_kwargs)
  File "/opt/airflow/dags/pipeline.py", line 39, in store_raw_data_in_hdfs
    with open(local_file, 'w') as f:
PermissionError: [Errno 13] Permission denied: '/mnt/hadoop_data/coingecko_raw.json'
[2025-02-25T16:09:39.429+0000] {taskinstance.py:1400} INFO - Marking task as FAILED. dag_id=coingecko_ingestion_dag, task_id=store_raw_data_in_hdfs, execution_date=20250224T000000, start_date=20250225T160939, end_date=20250225T160939
[2025-02-25T16:09:39.448+0000] {standard_task_runner.py:104} ERROR - Failed to execute job 169 for task store_raw_data_in_hdfs ([Errno 13] Permission denied: '/mnt/hadoop_data/coingecko_raw.json'; 737)
[2025-02-25T16:09:39.490+0000] {local_task_job_runner.py:228} INFO - Task exited with return code 1
[2025-02-25T16:09:39.503+0000] {taskinstance.py:2784} INFO - 0 downstream tasks scheduled from follow-on schedule check
