[2025-02-24T12:28:54.782+0000] {taskinstance.py:1159} INFO - Dependencies all met for dep_context=non-requeueable deps ti=<TaskInstance: coingecko_ingestion_dag.store_raw_data_in_hdfs scheduled__2025-02-23T00:00:00+00:00 [queued]>
[2025-02-24T12:28:54.794+0000] {taskinstance.py:1159} INFO - Dependencies all met for dep_context=requeueable deps ti=<TaskInstance: coingecko_ingestion_dag.store_raw_data_in_hdfs scheduled__2025-02-23T00:00:00+00:00 [queued]>
[2025-02-24T12:28:54.795+0000] {taskinstance.py:1361} INFO - Starting attempt 2 of 2
[2025-02-24T12:28:54.816+0000] {taskinstance.py:1382} INFO - Executing <Task(PythonOperator): store_raw_data_in_hdfs> on 2025-02-23 00:00:00+00:00
[2025-02-24T12:28:54.823+0000] {standard_task_runner.py:57} INFO - Started process 393 to run task
[2025-02-24T12:28:54.828+0000] {standard_task_runner.py:84} INFO - Running: ['***', 'tasks', 'run', 'coingecko_ingestion_dag', 'store_raw_data_in_hdfs', 'scheduled__2025-02-23T00:00:00+00:00', '--job-id', '11', '--raw', '--subdir', 'DAGS_FOLDER/pipeline.py', '--cfg-path', '/tmp/tmpu5aiagc5']
[2025-02-24T12:28:54.833+0000] {standard_task_runner.py:85} INFO - Job 11: Subtask store_raw_data_in_hdfs
[2025-02-24T12:28:54.901+0000] {task_command.py:415} INFO - Running <TaskInstance: coingecko_ingestion_dag.store_raw_data_in_hdfs scheduled__2025-02-23T00:00:00+00:00 [running]> on host 94f70d9be3b1
[2025-02-24T12:28:55.000+0000] {taskinstance.py:1660} INFO - Exporting env vars: AIRFLOW_CTX_DAG_OWNER='etudiant' AIRFLOW_CTX_DAG_ID='coingecko_ingestion_dag' AIRFLOW_CTX_TASK_ID='store_raw_data_in_hdfs' AIRFLOW_CTX_EXECUTION_DATE='2025-02-23T00:00:00+00:00' AIRFLOW_CTX_TRY_NUMBER='2' AIRFLOW_CTX_DAG_RUN_ID='scheduled__2025-02-23T00:00:00+00:00'
[2025-02-24T12:29:02.037+0000] {python.py:194} INFO - Done. Returned value was: None
[2025-02-24T12:29:02.059+0000] {taskinstance.py:1400} INFO - Marking task as SUCCESS. dag_id=coingecko_ingestion_dag, task_id=store_raw_data_in_hdfs, execution_date=20250223T000000, start_date=20250224T122854, end_date=20250224T122902
[2025-02-24T12:29:02.135+0000] {local_task_job_runner.py:228} INFO - Task exited with return code 0
[2025-02-24T12:29:02.173+0000] {taskinstance.py:2784} INFO - 0 downstream tasks scheduled from follow-on schedule check
[2025-02-24T18:14:16.402+0000] {taskinstance.py:1159} INFO - Dependencies all met for dep_context=non-requeueable deps ti=<TaskInstance: coingecko_ingestion_dag.store_raw_data_in_hdfs scheduled__2025-02-23T00:00:00+00:00 [queued]>
[2025-02-24T18:14:16.431+0000] {taskinstance.py:1159} INFO - Dependencies all met for dep_context=requeueable deps ti=<TaskInstance: coingecko_ingestion_dag.store_raw_data_in_hdfs scheduled__2025-02-23T00:00:00+00:00 [queued]>
[2025-02-24T18:14:16.434+0000] {taskinstance.py:1361} INFO - Starting attempt 2 of 2
[2025-02-24T18:14:16.461+0000] {taskinstance.py:1382} INFO - Executing <Task(PythonOperator): store_raw_data_in_hdfs> on 2025-02-23 00:00:00+00:00
[2025-02-24T18:14:16.472+0000] {standard_task_runner.py:57} INFO - Started process 1147 to run task
[2025-02-24T18:14:16.479+0000] {standard_task_runner.py:84} INFO - Running: ['***', 'tasks', 'run', 'coingecko_ingestion_dag', 'store_raw_data_in_hdfs', 'scheduled__2025-02-23T00:00:00+00:00', '--job-id', '159', '--raw', '--subdir', 'DAGS_FOLDER/test.py', '--cfg-path', '/tmp/tmpnctdihyv']
[2025-02-24T18:14:16.485+0000] {standard_task_runner.py:85} INFO - Job 159: Subtask store_raw_data_in_hdfs
[2025-02-24T18:14:16.587+0000] {task_command.py:415} INFO - Running <TaskInstance: coingecko_ingestion_dag.store_raw_data_in_hdfs scheduled__2025-02-23T00:00:00+00:00 [running]> on host 85b967fd3989
[2025-02-24T18:14:16.788+0000] {taskinstance.py:1660} INFO - Exporting env vars: AIRFLOW_CTX_DAG_OWNER='etudiant' AIRFLOW_CTX_DAG_ID='coingecko_ingestion_dag' AIRFLOW_CTX_TASK_ID='store_raw_data_in_hdfs' AIRFLOW_CTX_EXECUTION_DATE='2025-02-23T00:00:00+00:00' AIRFLOW_CTX_TRY_NUMBER='2' AIRFLOW_CTX_DAG_RUN_ID='scheduled__2025-02-23T00:00:00+00:00'
[2025-02-24T18:14:16.823+0000] {taskinstance.py:1943} ERROR - Task failed with exception
Traceback (most recent call last):
  File "/home/airflow/.local/lib/python3.8/site-packages/airflow/operators/python.py", line 192, in execute
    return_value = self.execute_callable()
  File "/home/airflow/.local/lib/python3.8/site-packages/airflow/operators/python.py", line 209, in execute_callable
    return self.python_callable(*self.op_args, **self.op_kwargs)
  File "/opt/airflow/dags/test.py", line 38, in store_raw_data_in_hdfs
    with open(local_file, 'w') as f:
PermissionError: [Errno 13] Permission denied: '/mnt/hadoop_data/coingecko_raw.json'
[2025-02-24T18:14:16.845+0000] {taskinstance.py:1400} INFO - Marking task as FAILED. dag_id=coingecko_ingestion_dag, task_id=store_raw_data_in_hdfs, execution_date=20250223T000000, start_date=20250224T181416, end_date=20250224T181416
[2025-02-24T18:14:16.871+0000] {standard_task_runner.py:104} ERROR - Failed to execute job 159 for task store_raw_data_in_hdfs ([Errno 13] Permission denied: '/mnt/hadoop_data/coingecko_raw.json'; 1147)
[2025-02-24T18:14:16.909+0000] {local_task_job_runner.py:228} INFO - Task exited with return code 1
[2025-02-24T18:14:16.942+0000] {taskinstance.py:2784} INFO - 0 downstream tasks scheduled from follow-on schedule check
[2025-02-25T16:09:39.111+0000] {taskinstance.py:1159} INFO - Dependencies all met for dep_context=non-requeueable deps ti=<TaskInstance: coingecko_ingestion_dag.store_raw_data_in_hdfs scheduled__2025-02-23T00:00:00+00:00 [queued]>
[2025-02-25T16:09:39.123+0000] {taskinstance.py:1159} INFO - Dependencies all met for dep_context=requeueable deps ti=<TaskInstance: coingecko_ingestion_dag.store_raw_data_in_hdfs scheduled__2025-02-23T00:00:00+00:00 [queued]>
[2025-02-25T16:09:39.124+0000] {taskinstance.py:1361} INFO - Starting attempt 2 of 2
[2025-02-25T16:09:39.141+0000] {taskinstance.py:1382} INFO - Executing <Task(PythonOperator): store_raw_data_in_hdfs> on 2025-02-23 00:00:00+00:00
[2025-02-25T16:09:39.148+0000] {standard_task_runner.py:57} INFO - Started process 736 to run task
[2025-02-25T16:09:39.152+0000] {standard_task_runner.py:84} INFO - Running: ['***', 'tasks', 'run', 'coingecko_ingestion_dag', 'store_raw_data_in_hdfs', 'scheduled__2025-02-23T00:00:00+00:00', '--job-id', '168', '--raw', '--subdir', 'DAGS_FOLDER/pipeline.py', '--cfg-path', '/tmp/tmpc8y2tq8s']
[2025-02-25T16:09:39.159+0000] {standard_task_runner.py:85} INFO - Job 168: Subtask store_raw_data_in_hdfs
[2025-02-25T16:09:39.226+0000] {task_command.py:415} INFO - Running <TaskInstance: coingecko_ingestion_dag.store_raw_data_in_hdfs scheduled__2025-02-23T00:00:00+00:00 [running]> on host af9744bbb9eb
[2025-02-25T16:09:39.322+0000] {taskinstance.py:1660} INFO - Exporting env vars: AIRFLOW_CTX_DAG_OWNER='etudiant' AIRFLOW_CTX_DAG_ID='coingecko_ingestion_dag' AIRFLOW_CTX_TASK_ID='store_raw_data_in_hdfs' AIRFLOW_CTX_EXECUTION_DATE='2025-02-23T00:00:00+00:00' AIRFLOW_CTX_TRY_NUMBER='2' AIRFLOW_CTX_DAG_RUN_ID='scheduled__2025-02-23T00:00:00+00:00'
[2025-02-25T16:09:39.345+0000] {taskinstance.py:1943} ERROR - Task failed with exception
Traceback (most recent call last):
  File "/home/airflow/.local/lib/python3.8/site-packages/airflow/operators/python.py", line 192, in execute
    return_value = self.execute_callable()
  File "/home/airflow/.local/lib/python3.8/site-packages/airflow/operators/python.py", line 209, in execute_callable
    return self.python_callable(*self.op_args, **self.op_kwargs)
  File "/opt/airflow/dags/pipeline.py", line 39, in store_raw_data_in_hdfs
    with open(local_file, 'w') as f:
PermissionError: [Errno 13] Permission denied: '/mnt/hadoop_data/coingecko_raw.json'
[2025-02-25T16:09:39.368+0000] {taskinstance.py:1400} INFO - Marking task as FAILED. dag_id=coingecko_ingestion_dag, task_id=store_raw_data_in_hdfs, execution_date=20250223T000000, start_date=20250225T160939, end_date=20250225T160939
[2025-02-25T16:09:39.390+0000] {standard_task_runner.py:104} ERROR - Failed to execute job 168 for task store_raw_data_in_hdfs ([Errno 13] Permission denied: '/mnt/hadoop_data/coingecko_raw.json'; 736)
[2025-02-25T16:09:39.413+0000] {local_task_job_runner.py:228} INFO - Task exited with return code 1
[2025-02-25T16:09:39.433+0000] {taskinstance.py:2784} INFO - 0 downstream tasks scheduled from follow-on schedule check
