[2025-02-24T18:14:16.416+0000] {taskinstance.py:1159} INFO - Dependencies all met for dep_context=non-requeueable deps ti=<TaskInstance: coingecko_ingestion_dag.store_raw_data_in_hdfs scheduled__2025-02-18T00:00:00+00:00 [queued]>
[2025-02-24T18:14:16.435+0000] {taskinstance.py:1159} INFO - Dependencies all met for dep_context=requeueable deps ti=<TaskInstance: coingecko_ingestion_dag.store_raw_data_in_hdfs scheduled__2025-02-18T00:00:00+00:00 [queued]>
[2025-02-24T18:14:16.437+0000] {taskinstance.py:1361} INFO - Starting attempt 2 of 2
[2025-02-24T18:14:16.466+0000] {taskinstance.py:1382} INFO - Executing <Task(PythonOperator): store_raw_data_in_hdfs> on 2025-02-18 00:00:00+00:00
[2025-02-24T18:14:16.476+0000] {standard_task_runner.py:57} INFO - Started process 1148 to run task
[2025-02-24T18:14:16.483+0000] {standard_task_runner.py:84} INFO - Running: ['***', 'tasks', 'run', 'coingecko_ingestion_dag', 'store_raw_data_in_hdfs', 'scheduled__2025-02-18T00:00:00+00:00', '--job-id', '160', '--raw', '--subdir', 'DAGS_FOLDER/test.py', '--cfg-path', '/tmp/tmpqprw3tr_']
[2025-02-24T18:14:16.488+0000] {standard_task_runner.py:85} INFO - Job 160: Subtask store_raw_data_in_hdfs
[2025-02-24T18:14:16.581+0000] {task_command.py:415} INFO - Running <TaskInstance: coingecko_ingestion_dag.store_raw_data_in_hdfs scheduled__2025-02-18T00:00:00+00:00 [running]> on host 85b967fd3989
[2025-02-24T18:14:16.778+0000] {taskinstance.py:1660} INFO - Exporting env vars: AIRFLOW_CTX_DAG_OWNER='etudiant' AIRFLOW_CTX_DAG_ID='coingecko_ingestion_dag' AIRFLOW_CTX_TASK_ID='store_raw_data_in_hdfs' AIRFLOW_CTX_EXECUTION_DATE='2025-02-18T00:00:00+00:00' AIRFLOW_CTX_TRY_NUMBER='2' AIRFLOW_CTX_DAG_RUN_ID='scheduled__2025-02-18T00:00:00+00:00'
[2025-02-24T18:14:16.815+0000] {taskinstance.py:1943} ERROR - Task failed with exception
Traceback (most recent call last):
  File "/home/airflow/.local/lib/python3.8/site-packages/airflow/operators/python.py", line 192, in execute
    return_value = self.execute_callable()
  File "/home/airflow/.local/lib/python3.8/site-packages/airflow/operators/python.py", line 209, in execute_callable
    return self.python_callable(*self.op_args, **self.op_kwargs)
  File "/opt/airflow/dags/test.py", line 38, in store_raw_data_in_hdfs
    with open(local_file, 'w') as f:
PermissionError: [Errno 13] Permission denied: '/mnt/hadoop_data/coingecko_raw.json'
[2025-02-24T18:14:16.831+0000] {taskinstance.py:1400} INFO - Marking task as FAILED. dag_id=coingecko_ingestion_dag, task_id=store_raw_data_in_hdfs, execution_date=20250218T000000, start_date=20250224T181416, end_date=20250224T181416
[2025-02-24T18:14:16.861+0000] {standard_task_runner.py:104} ERROR - Failed to execute job 160 for task store_raw_data_in_hdfs ([Errno 13] Permission denied: '/mnt/hadoop_data/coingecko_raw.json'; 1148)
[2025-02-24T18:14:16.909+0000] {local_task_job_runner.py:228} INFO - Task exited with return code 1
[2025-02-24T18:14:16.934+0000] {taskinstance.py:2784} INFO - 0 downstream tasks scheduled from follow-on schedule check
[2025-02-25T16:09:21.602+0000] {taskinstance.py:1159} INFO - Dependencies all met for dep_context=non-requeueable deps ti=<TaskInstance: coingecko_ingestion_dag.store_raw_data_in_hdfs scheduled__2025-02-18T00:00:00+00:00 [queued]>
[2025-02-25T16:09:21.610+0000] {taskinstance.py:1159} INFO - Dependencies all met for dep_context=requeueable deps ti=<TaskInstance: coingecko_ingestion_dag.store_raw_data_in_hdfs scheduled__2025-02-18T00:00:00+00:00 [queued]>
[2025-02-25T16:09:21.610+0000] {taskinstance.py:1361} INFO - Starting attempt 2 of 2
[2025-02-25T16:09:21.625+0000] {taskinstance.py:1382} INFO - Executing <Task(PythonOperator): store_raw_data_in_hdfs> on 2025-02-18 00:00:00+00:00
[2025-02-25T16:09:21.629+0000] {standard_task_runner.py:57} INFO - Started process 721 to run task
[2025-02-25T16:09:21.632+0000] {standard_task_runner.py:84} INFO - Running: ['***', 'tasks', 'run', 'coingecko_ingestion_dag', 'store_raw_data_in_hdfs', 'scheduled__2025-02-18T00:00:00+00:00', '--job-id', '164', '--raw', '--subdir', 'DAGS_FOLDER/pipeline.py', '--cfg-path', '/tmp/tmpekbyxf6_']
[2025-02-25T16:09:21.634+0000] {standard_task_runner.py:85} INFO - Job 164: Subtask store_raw_data_in_hdfs
[2025-02-25T16:09:21.675+0000] {task_command.py:415} INFO - Running <TaskInstance: coingecko_ingestion_dag.store_raw_data_in_hdfs scheduled__2025-02-18T00:00:00+00:00 [running]> on host af9744bbb9eb
[2025-02-25T16:09:21.741+0000] {taskinstance.py:1660} INFO - Exporting env vars: AIRFLOW_CTX_DAG_OWNER='etudiant' AIRFLOW_CTX_DAG_ID='coingecko_ingestion_dag' AIRFLOW_CTX_TASK_ID='store_raw_data_in_hdfs' AIRFLOW_CTX_EXECUTION_DATE='2025-02-18T00:00:00+00:00' AIRFLOW_CTX_TRY_NUMBER='2' AIRFLOW_CTX_DAG_RUN_ID='scheduled__2025-02-18T00:00:00+00:00'
[2025-02-25T16:09:21.756+0000] {taskinstance.py:1943} ERROR - Task failed with exception
Traceback (most recent call last):
  File "/home/airflow/.local/lib/python3.8/site-packages/airflow/operators/python.py", line 192, in execute
    return_value = self.execute_callable()
  File "/home/airflow/.local/lib/python3.8/site-packages/airflow/operators/python.py", line 209, in execute_callable
    return self.python_callable(*self.op_args, **self.op_kwargs)
  File "/opt/airflow/dags/pipeline.py", line 39, in store_raw_data_in_hdfs
    with open(local_file, 'w') as f:
PermissionError: [Errno 13] Permission denied: '/mnt/hadoop_data/coingecko_raw.json'
[2025-02-25T16:09:21.763+0000] {taskinstance.py:1400} INFO - Marking task as FAILED. dag_id=coingecko_ingestion_dag, task_id=store_raw_data_in_hdfs, execution_date=20250218T000000, start_date=20250225T160921, end_date=20250225T160921
[2025-02-25T16:09:21.772+0000] {standard_task_runner.py:104} ERROR - Failed to execute job 164 for task store_raw_data_in_hdfs ([Errno 13] Permission denied: '/mnt/hadoop_data/coingecko_raw.json'; 721)
[2025-02-25T16:09:21.814+0000] {local_task_job_runner.py:228} INFO - Task exited with return code 1
[2025-02-25T16:09:21.831+0000] {taskinstance.py:2784} INFO - 0 downstream tasks scheduled from follow-on schedule check
