[2025-02-24T17:20:11.784+0000] {taskinstance.py:1159} INFO - Dependencies all met for dep_context=non-requeueable deps ti=<TaskInstance: coingecko_ingestion_dag.store_raw_data_in_hdfs scheduled__2025-01-11T00:00:00+00:00 [queued]>
[2025-02-24T17:20:11.821+0000] {taskinstance.py:1159} INFO - Dependencies all met for dep_context=requeueable deps ti=<TaskInstance: coingecko_ingestion_dag.store_raw_data_in_hdfs scheduled__2025-01-11T00:00:00+00:00 [queued]>
[2025-02-24T17:20:11.824+0000] {taskinstance.py:1361} INFO - Starting attempt 2 of 2
[2025-02-24T17:20:11.934+0000] {taskinstance.py:1382} INFO - Executing <Task(PythonOperator): store_raw_data_in_hdfs> on 2025-01-11 00:00:00+00:00
[2025-02-24T17:20:11.947+0000] {standard_task_runner.py:57} INFO - Started process 641 to run task
[2025-02-24T17:20:11.958+0000] {standard_task_runner.py:84} INFO - Running: ['***', 'tasks', 'run', 'coingecko_ingestion_dag', 'store_raw_data_in_hdfs', 'scheduled__2025-01-11T00:00:00+00:00', '--job-id', '38', '--raw', '--subdir', 'DAGS_FOLDER/test.py', '--cfg-path', '/tmp/tmpyqn8j03z']
[2025-02-24T17:20:11.985+0000] {standard_task_runner.py:85} INFO - Job 38: Subtask store_raw_data_in_hdfs
[2025-02-24T17:20:12.160+0000] {task_command.py:415} INFO - Running <TaskInstance: coingecko_ingestion_dag.store_raw_data_in_hdfs scheduled__2025-01-11T00:00:00+00:00 [running]> on host 85b967fd3989
[2025-02-24T17:20:12.416+0000] {taskinstance.py:1660} INFO - Exporting env vars: AIRFLOW_CTX_DAG_OWNER='etudiant' AIRFLOW_CTX_DAG_ID='coingecko_ingestion_dag' AIRFLOW_CTX_TASK_ID='store_raw_data_in_hdfs' AIRFLOW_CTX_EXECUTION_DATE='2025-01-11T00:00:00+00:00' AIRFLOW_CTX_TRY_NUMBER='2' AIRFLOW_CTX_DAG_RUN_ID='scheduled__2025-01-11T00:00:00+00:00'
[2025-02-24T17:20:12.456+0000] {taskinstance.py:1943} ERROR - Task failed with exception
Traceback (most recent call last):
  File "/home/airflow/.local/lib/python3.8/site-packages/airflow/operators/python.py", line 192, in execute
    return_value = self.execute_callable()
  File "/home/airflow/.local/lib/python3.8/site-packages/airflow/operators/python.py", line 209, in execute_callable
    return self.python_callable(*self.op_args, **self.op_kwargs)
  File "/opt/airflow/dags/test.py", line 38, in store_raw_data_in_hdfs
    with open(local_file, 'w') as f:
PermissionError: [Errno 13] Permission denied: '/mnt/hadoop_data/coingecko_raw.json'
[2025-02-24T17:20:12.478+0000] {taskinstance.py:1400} INFO - Marking task as FAILED. dag_id=coingecko_ingestion_dag, task_id=store_raw_data_in_hdfs, execution_date=20250111T000000, start_date=20250224T172011, end_date=20250224T172012
[2025-02-24T17:20:12.523+0000] {standard_task_runner.py:104} ERROR - Failed to execute job 38 for task store_raw_data_in_hdfs ([Errno 13] Permission denied: '/mnt/hadoop_data/coingecko_raw.json'; 641)
[2025-02-24T17:20:12.593+0000] {local_task_job_runner.py:228} INFO - Task exited with return code 1
[2025-02-24T17:20:12.636+0000] {taskinstance.py:2784} INFO - 0 downstream tasks scheduled from follow-on schedule check
[2025-02-25T15:52:55.862+0000] {taskinstance.py:1159} INFO - Dependencies all met for dep_context=non-requeueable deps ti=<TaskInstance: coingecko_ingestion_dag.store_raw_data_in_hdfs scheduled__2025-01-11T00:00:00+00:00 [queued]>
[2025-02-25T15:52:55.890+0000] {taskinstance.py:1159} INFO - Dependencies all met for dep_context=requeueable deps ti=<TaskInstance: coingecko_ingestion_dag.store_raw_data_in_hdfs scheduled__2025-01-11T00:00:00+00:00 [queued]>
[2025-02-25T15:52:55.891+0000] {taskinstance.py:1361} INFO - Starting attempt 2 of 2
[2025-02-25T15:52:55.951+0000] {taskinstance.py:1382} INFO - Executing <Task(PythonOperator): store_raw_data_in_hdfs> on 2025-01-11 00:00:00+00:00
[2025-02-25T15:52:55.967+0000] {standard_task_runner.py:57} INFO - Started process 329 to run task
[2025-02-25T15:52:55.990+0000] {standard_task_runner.py:84} INFO - Running: ['***', 'tasks', 'run', 'coingecko_ingestion_dag', 'store_raw_data_in_hdfs', 'scheduled__2025-01-11T00:00:00+00:00', '--job-id', '42', '--raw', '--subdir', 'DAGS_FOLDER/pipeline.py', '--cfg-path', '/tmp/tmpcgnjv64i']
[2025-02-25T15:52:56.010+0000] {standard_task_runner.py:85} INFO - Job 42: Subtask store_raw_data_in_hdfs
[2025-02-25T15:52:56.293+0000] {task_command.py:415} INFO - Running <TaskInstance: coingecko_ingestion_dag.store_raw_data_in_hdfs scheduled__2025-01-11T00:00:00+00:00 [running]> on host af9744bbb9eb
[2025-02-25T15:52:56.717+0000] {taskinstance.py:1660} INFO - Exporting env vars: AIRFLOW_CTX_DAG_OWNER='etudiant' AIRFLOW_CTX_DAG_ID='coingecko_ingestion_dag' AIRFLOW_CTX_TASK_ID='store_raw_data_in_hdfs' AIRFLOW_CTX_EXECUTION_DATE='2025-01-11T00:00:00+00:00' AIRFLOW_CTX_TRY_NUMBER='2' AIRFLOW_CTX_DAG_RUN_ID='scheduled__2025-01-11T00:00:00+00:00'
[2025-02-25T15:52:56.775+0000] {taskinstance.py:1943} ERROR - Task failed with exception
Traceback (most recent call last):
  File "/home/airflow/.local/lib/python3.8/site-packages/airflow/operators/python.py", line 192, in execute
    return_value = self.execute_callable()
  File "/home/airflow/.local/lib/python3.8/site-packages/airflow/operators/python.py", line 209, in execute_callable
    return self.python_callable(*self.op_args, **self.op_kwargs)
  File "/opt/airflow/dags/pipeline.py", line 39, in store_raw_data_in_hdfs
    with open(local_file, 'w') as f:
PermissionError: [Errno 13] Permission denied: '/mnt/hadoop_data/coingecko_raw.json'
[2025-02-25T15:52:56.859+0000] {taskinstance.py:1400} INFO - Marking task as FAILED. dag_id=coingecko_ingestion_dag, task_id=store_raw_data_in_hdfs, execution_date=20250111T000000, start_date=20250225T155255, end_date=20250225T155256
[2025-02-25T15:52:56.930+0000] {standard_task_runner.py:104} ERROR - Failed to execute job 42 for task store_raw_data_in_hdfs ([Errno 13] Permission denied: '/mnt/hadoop_data/coingecko_raw.json'; 329)
[2025-02-25T15:52:57.023+0000] {local_task_job_runner.py:228} INFO - Task exited with return code 1
[2025-02-25T15:52:57.121+0000] {taskinstance.py:2784} INFO - 0 downstream tasks scheduled from follow-on schedule check
