[2025-02-24T17:15:09.458+0000] {taskinstance.py:1159} INFO - Dependencies all met for dep_context=non-requeueable deps ti=<TaskInstance: coingecko_ingestion_dag.store_raw_data_in_hdfs scheduled__2025-01-11T00:00:00+00:00 [queued]>
[2025-02-24T17:15:09.509+0000] {taskinstance.py:1159} INFO - Dependencies all met for dep_context=requeueable deps ti=<TaskInstance: coingecko_ingestion_dag.store_raw_data_in_hdfs scheduled__2025-01-11T00:00:00+00:00 [queued]>
[2025-02-24T17:15:09.514+0000] {taskinstance.py:1361} INFO - Starting attempt 1 of 2
[2025-02-24T17:15:09.573+0000] {taskinstance.py:1382} INFO - Executing <Task(PythonOperator): store_raw_data_in_hdfs> on 2025-01-11 00:00:00+00:00
[2025-02-24T17:15:09.602+0000] {standard_task_runner.py:57} INFO - Started process 510 to run task
[2025-02-24T17:15:09.621+0000] {standard_task_runner.py:84} INFO - Running: ['***', 'tasks', 'run', 'coingecko_ingestion_dag', 'store_raw_data_in_hdfs', 'scheduled__2025-01-11T00:00:00+00:00', '--job-id', '21', '--raw', '--subdir', 'DAGS_FOLDER/pipeline.py', '--cfg-path', '/tmp/tmpb21ba8nz']
[2025-02-24T17:15:09.630+0000] {standard_task_runner.py:85} INFO - Job 21: Subtask store_raw_data_in_hdfs
[2025-02-24T17:15:09.947+0000] {task_command.py:415} INFO - Running <TaskInstance: coingecko_ingestion_dag.store_raw_data_in_hdfs scheduled__2025-01-11T00:00:00+00:00 [running]> on host 85b967fd3989
[2025-02-24T17:15:10.323+0000] {taskinstance.py:1660} INFO - Exporting env vars: AIRFLOW_CTX_DAG_OWNER='etudiant' AIRFLOW_CTX_DAG_ID='coingecko_ingestion_dag' AIRFLOW_CTX_TASK_ID='store_raw_data_in_hdfs' AIRFLOW_CTX_EXECUTION_DATE='2025-01-11T00:00:00+00:00' AIRFLOW_CTX_TRY_NUMBER='1' AIRFLOW_CTX_DAG_RUN_ID='scheduled__2025-01-11T00:00:00+00:00'
[2025-02-24T17:15:10.483+0000] {taskinstance.py:1943} ERROR - Task failed with exception
Traceback (most recent call last):
  File "/home/airflow/.local/lib/python3.8/site-packages/airflow/operators/python.py", line 192, in execute
    return_value = self.execute_callable()
  File "/home/airflow/.local/lib/python3.8/site-packages/airflow/operators/python.py", line 209, in execute_callable
    return self.python_callable(*self.op_args, **self.op_kwargs)
  File "/opt/airflow/dags/pipeline.py", line 38, in store_raw_data_in_hdfs
    with open(local_file, 'w') as f:
PermissionError: [Errno 13] Permission denied: '/mnt/hadoop_data/coingecko_raw.json'
[2025-02-24T17:15:10.531+0000] {taskinstance.py:1400} INFO - Marking task as UP_FOR_RETRY. dag_id=coingecko_ingestion_dag, task_id=store_raw_data_in_hdfs, execution_date=20250111T000000, start_date=20250224T171509, end_date=20250224T171510
[2025-02-24T17:15:10.561+0000] {standard_task_runner.py:104} ERROR - Failed to execute job 21 for task store_raw_data_in_hdfs ([Errno 13] Permission denied: '/mnt/hadoop_data/coingecko_raw.json'; 510)
[2025-02-24T17:15:10.602+0000] {local_task_job_runner.py:228} INFO - Task exited with return code 1
[2025-02-24T17:15:10.647+0000] {taskinstance.py:2784} INFO - 0 downstream tasks scheduled from follow-on schedule check
[2025-02-25T15:47:51.418+0000] {taskinstance.py:1159} INFO - Dependencies all met for dep_context=non-requeueable deps ti=<TaskInstance: coingecko_ingestion_dag.store_raw_data_in_hdfs scheduled__2025-01-11T00:00:00+00:00 [queued]>
[2025-02-25T15:47:51.465+0000] {taskinstance.py:1159} INFO - Dependencies all met for dep_context=requeueable deps ti=<TaskInstance: coingecko_ingestion_dag.store_raw_data_in_hdfs scheduled__2025-01-11T00:00:00+00:00 [queued]>
[2025-02-25T15:47:51.469+0000] {taskinstance.py:1361} INFO - Starting attempt 1 of 2
[2025-02-25T15:47:51.818+0000] {taskinstance.py:1382} INFO - Executing <Task(PythonOperator): store_raw_data_in_hdfs> on 2025-01-11 00:00:00+00:00
[2025-02-25T15:47:51.864+0000] {standard_task_runner.py:57} INFO - Started process 251 to run task
[2025-02-25T15:47:51.896+0000] {standard_task_runner.py:84} INFO - Running: ['***', 'tasks', 'run', 'coingecko_ingestion_dag', 'store_raw_data_in_hdfs', 'scheduled__2025-01-11T00:00:00+00:00', '--job-id', '32', '--raw', '--subdir', 'DAGS_FOLDER/pipeline.py', '--cfg-path', '/tmp/tmpkjex5m3b']
[2025-02-25T15:47:51.955+0000] {standard_task_runner.py:85} INFO - Job 32: Subtask store_raw_data_in_hdfs
[2025-02-25T15:47:52.306+0000] {task_command.py:415} INFO - Running <TaskInstance: coingecko_ingestion_dag.store_raw_data_in_hdfs scheduled__2025-01-11T00:00:00+00:00 [running]> on host af9744bbb9eb
[2025-02-25T15:47:52.568+0000] {taskinstance.py:1660} INFO - Exporting env vars: AIRFLOW_CTX_DAG_OWNER='etudiant' AIRFLOW_CTX_DAG_ID='coingecko_ingestion_dag' AIRFLOW_CTX_TASK_ID='store_raw_data_in_hdfs' AIRFLOW_CTX_EXECUTION_DATE='2025-01-11T00:00:00+00:00' AIRFLOW_CTX_TRY_NUMBER='1' AIRFLOW_CTX_DAG_RUN_ID='scheduled__2025-01-11T00:00:00+00:00'
[2025-02-25T15:47:52.598+0000] {taskinstance.py:1943} ERROR - Task failed with exception
Traceback (most recent call last):
  File "/home/airflow/.local/lib/python3.8/site-packages/airflow/operators/python.py", line 192, in execute
    return_value = self.execute_callable()
  File "/home/airflow/.local/lib/python3.8/site-packages/airflow/operators/python.py", line 209, in execute_callable
    return self.python_callable(*self.op_args, **self.op_kwargs)
  File "/opt/airflow/dags/pipeline.py", line 39, in store_raw_data_in_hdfs
    with open(local_file, 'w') as f:
PermissionError: [Errno 13] Permission denied: '/mnt/hadoop_data/coingecko_raw.json'
[2025-02-25T15:47:52.616+0000] {taskinstance.py:1400} INFO - Marking task as UP_FOR_RETRY. dag_id=coingecko_ingestion_dag, task_id=store_raw_data_in_hdfs, execution_date=20250111T000000, start_date=20250225T154751, end_date=20250225T154752
[2025-02-25T15:47:52.645+0000] {standard_task_runner.py:104} ERROR - Failed to execute job 32 for task store_raw_data_in_hdfs ([Errno 13] Permission denied: '/mnt/hadoop_data/coingecko_raw.json'; 251)
[2025-02-25T15:47:52.669+0000] {local_task_job_runner.py:228} INFO - Task exited with return code 1
[2025-02-25T15:47:52.718+0000] {taskinstance.py:2784} INFO - 0 downstream tasks scheduled from follow-on schedule check
